Workbook

Sheet Puntajes
A1: Número | B1: Posición | C1: Nombre | D1: Marcadores | E1: Posiciones | F1: Total | I1: =NOW() -> 46200.607 | M1: 46199 | N1: _Nombre | O1: _Numero | P1: _Puntaje | Q1: _Key | R1: _Rank
A2: =[1]Puntajes!A2 -> 30 | B2: =[1]Puntajes!B2 -> 1 | C2: =[1]Puntajes!C2 -> Luis Peña | D2: =[1]Puntajes!D2 -> 63 | E2: =[1]Puntajes!E2 -> 155 | F2: =[1]Puntajes!F2 -> 218 | N2: =Grupo!A3 -> Alberto | O2: =Participantes!A2 -> 1 | P2: =Grupo!HJ3 -> 48 | Q2: =P2*100-ROW() -> 4798 | R2: =SUMPRODUCT(($Q$2:$Q$50>Q2)*1)+1 -> 26
A3: =[1]Puntajes!A3 -> 34 | B3: =[1]Puntajes!B3 -> 2 | C3: =[1]Puntajes!C3 -> Medica | D3: =[1]Puntajes!D3 -> 59 | E3: =[1]Puntajes!E3 -> 155 | F3: =[1]Puntajes!F3 -> 214 | N3: =Grupo!A4 -> Alexander | O3: =Participantes!A3 -> 2 | P3: =Grupo!HJ4 -> 55 | Q3: =P3*100-ROW() -> 5497 | R3: =SUMPRODUCT(($Q$2:$Q$50>Q3)*1)+1 -> 6
A4: =[1]Puntajes!A4 -> 31 | B4: =[1]Puntajes!B4 -> 3 | C4: =[1]Puntajes!C4 -> Marco R. | D4: =[1]Puntajes!D4 -> 53 | E4: =[1]Puntajes!E4 -> 158 | F4: =[1]Puntajes!F4 -> 211 | I4: =IF(M1=TODAY()-1,"Finalizado",IF(NOW()<M1+L5,"Por iniciar",IF(NOW()<=M1+L5+2/24,"Iniciado","Finalizado"))) -> Finalizado | N4: =Grupo!A5 -> Alfredo 1 | O4: =Participantes!A4 -> 3 | P4: =Grupo!HJ5 -> 52 | Q4: =P4*100-ROW() -> 5196 | R4: =SUMPRODUCT(($Q$2:$Q$50>Q4)*1)+1 -> 12
A5: =[1]Puntajes!A5 -> 3 | B5: =[1]Puntajes!B5 -> 4 | C5: =[1]Puntajes!C5 -> Alfredo 1 | D5: =[1]Puntajes!D5 -> 52 | E5: =[1]Puntajes!E5 -> 157 | F5: =[1]Puntajes!F5 -> 209 | I5: =Partidos!F68 -> Panamá | J5: =Partidos!G68 -> Inglaterra | L5: =Partidos!C68 -> 0.66666667 | N5: =Grupo!A6 -> Alfredo 2 | O5: =Participantes!A5 -> 4 | P5: =Grupo!HJ6 -> 50 | Q5: =P5*100-ROW() -> 4995 | R5: =SUMPRODUCT(($Q$2:$Q$50>Q5)*1)+1 -> 18
A6: =[1]Puntajes!A6 -> 44 | B6: =[1]Puntajes!B6 -> 5 | C6: =[1]Puntajes!C6 -> Quinnie | D6: =[1]Puntajes!D6 -> 57 | E6: =[1]Puntajes!E6 -> 151 | F6: =[1]Puntajes!F6 -> 208 | I6: =IF(Partidos!H68="","",Partidos!H68) | J6: =IF(Partidos!I68="","",Partidos!I68) | N6: =Grupo!A7 -> Aneth | O6: =Participantes!A6 -> 5 | P6: =Grupo!HJ7 -> 52 | Q6: =P6*100-ROW() -> 5194 | R6: =SUMPRODUCT(($Q$2:$Q$50>Q6)*1)+1 -> 13
A7: =[1]Puntajes!A7 -> 38 | B7: =[1]Puntajes!B7 -> 6 | C7: =[1]Puntajes!C7 -> Mily Oliver | D7: =[1]Puntajes!D7 -> 47 | E7: =[1]Puntajes!E7 -> 158 | F7: =[1]Puntajes!F7 -> 205 | N7: =Grupo!A8 -> Antonio | O7: =Participantes!A7 -> 6 | P7: =Grupo!HJ8 -> 39 | Q7: =P7*100-ROW() -> 3893 | R7: =SUMPRODUCT(($Q$2:$Q$50>Q7)*1)+1 -> 45
A8: =[1]Puntajes!A8 -> 2 | B8: =[1]Puntajes!B8 -> 7 | C8: =[1]Puntajes!C8 -> Alexander | D8: =[1]Puntajes!D8 -> 55 | E8: =[1]Puntajes!E8 -> 149 | F8: =[1]Puntajes!F8 -> 204 | I8: =IF(M1=TODAY()-1,"Finalizado",IF(NOW()<M1+L9,"Por iniciar",IF(NOW()<=M1+L9+2/24,"Iniciado","Finalizado"))) -> Finalizado | N8: =Grupo!A9 -> Carlos | O8: =Participantes!A8 -> 7 | P8: =Grupo!HJ9 -> 46 | Q8: =P8*100-ROW() -> 4592 | R8: =SUMPRODUCT(($Q$2:$Q$50>Q8)*1)+1 -> 32
A9: =[1]Puntajes!A9 -> 16 | B9: =[1]Puntajes!B9 -> 7 | C9: =[1]Puntajes!C9 -> Isabel 2 | D9: =[1]Puntajes!D9 -> 53 | E9: =[1]Puntajes!E9 -> 151 | F9: =[1]Puntajes!F9 -> 204 | I9: =Partidos!F69 -> Croacia | J9: =Partidos!G69 -> Ghana | L9: =Partidos!C69 -> 0.66666667 | N9: =Grupo!A10 -> Castillo L. | O9: =Participantes!A9 -> 8 | P9: =Grupo!HJ10 -> 50 | Q9: =P9*100-ROW() -> 4991 | R9: =SUMPRODUCT(($Q$2:$Q$50>Q9)*1)+1 -> 19
A10: =[1]Puntajes!A10 -> 27 | B10: =[1]Puntajes!B10 -> 8 | C10: =[1]Puntajes!C10 -> Kattia 2 | D10: =[1]Puntajes!D10 -> 58 | E10: =[1]Puntajes!E10 -> 145 | F10: =[1]Puntajes!F10 -> 203 | I10: =IF(Partidos!H69="","",Partidos!H69) | J10: =IF(Partidos!I69="","",Partidos!I69) | N10: =Grupo!A11 -> Christofer | O10: =Participantes!A10 -> 9 | P10: =Grupo!HJ11 -> 32 | Q10: =P10*100-ROW() -> 3190 | R10: =SUMPRODUCT(($Q$2:$Q$50>Q10)*1)+1 -> 49
A11: =[1]Puntajes!A11 -> 46 | B11: =[1]Puntajes!B11 -> 8 | C11: =[1]Puntajes!C11 -> Saul | D11: =[1]Puntajes!D11 -> 46 | E11: =[1]Puntajes!E11 -> 157 | F11: =[1]Puntajes!F11 -> 203 | N11: =Grupo!A12 -> Cynthia | O11: =Participantes!A11 -> 10 | P11: =Grupo!HJ12 -> 48 | Q11: =P11*100-ROW() -> 4789 | R11: =SUMPRODUCT(($Q$2:$Q$50>Q11)*1)+1 -> 27
A12: =[1]Puntajes!A12 -> 20 | B12: =[1]Puntajes!B12 -> 9 | C12: =[1]Puntajes!C12 -> Jose C Ahiza | D12: =[1]Puntajes!D12 -> 55 | E12: =[1]Puntajes!E12 -> 144 | F12: =[1]Puntajes!F12 -> 199 | I12: =IF(M1=TODAY()-1,"Finalizado",IF(NOW()<M1+L13,"Por iniciar",IF(NOW()<=M1+L13+2/24,"Iniciado","Finalizado"))) -> Finalizado | N12: =Grupo!A13 -> Edward | O12: =Participantes!A12 -> 11 | P12: =Grupo!HJ13 -> 57 | Q12: =P12*100-ROW() -> 5688 | R12: =SUMPRODUCT(($Q$2:$Q$50>Q12)*1)+1 -> 4
A13: =[1]Puntajes!A13 -> 35 | B13: =[1]Puntajes!B13 -> 9 | C13: =[1]Puntajes!C13 -> Milagros | D13: =[1]Puntajes!D13 -> 55 | E13: =[1]Puntajes!E13 -> 144 | F13: =[1]Puntajes!F13 -> 199 | I13: =Partidos!F72 -> Colombia | J13: =Partidos!G72 -> Portugal | L13: =Partidos!C72 -> 0.77083333 | N13: =Grupo!A14 -> Espinosa L. | O13: =Participantes!A13 -> 12 | P13: =Grupo!HJ14 -> 36 | Q13: =P13*100-ROW() -> 3587 | R13: =SUMPRODUCT(($Q$2:$Q$50>Q13)*1)+1 -> 47
A14: =[1]Puntajes!A14 -> 45 | B14: =[1]Puntajes!B14 -> 9 | C14: =[1]Puntajes!C14 -> Radames | D14: =[1]Puntajes!D14 -> 44 | E14: =[1]Puntajes!E14 -> 155 | F14: =[1]Puntajes!F14 -> 199 | I14: =IF(Partidos!H72="","",Partidos!H72) | J14: =IF(Partidos!I72="","",Partidos!I72) | N14: =Grupo!A15 -> Freddy | O14: =Participantes!A14 -> 13 | P14: =Grupo!HJ15 -> 42 | Q14: =P14*100-ROW() -> 4186 | R14: =SUMPRODUCT(($Q$2:$Q$50>Q14)*1)+1 -> 41
A15: =[1]Puntajes!A15 -> 4 | B15: =[1]Puntajes!B15 -> 10 | C15: =[1]Puntajes!C15 -> Alfredo 2 | D15: =[1]Puntajes!D15 -> 50 | E15: =[1]Puntajes!E15 -> 148 | F15: =[1]Puntajes!F15 -> 198 | N15: =Grupo!A16 -> Isabel 1 | O15: =Participantes!A15 -> 15 | P15: =Grupo!HJ16 -> 43 | Q15: =P15*100-ROW() -> 4285 | R15: =SUMPRODUCT(($Q$2:$Q$50>Q15)*1)+1 -> 39
A16: =[1]Puntajes!A16 -> 1 | B16: =[1]Puntajes!B16 -> 11 | C16: =[1]Puntajes!C16 -> Alberto | D16: =[1]Puntajes!D16 -> 48 | E16: =[1]Puntajes!E16 -> 149 | F16: =[1]Puntajes!F16 -> 197 | I16: =IF(M1=TODAY()-1,"Finalizado",IF(NOW()<M1+L17,"Por iniciar",IF(NOW()<=M1+L17+2/24,"Iniciado","Finalizado"))) -> Finalizado | N16: =Grupo!A17 -> Isabel 2 | O16: =Participantes!A16 -> 16 | P16: =Grupo!HJ17 -> 53 | Q16: =P16*100-ROW() -> 5284 | R16: =SUMPRODUCT(($Q$2:$Q$50>Q16)*1)+1 -> 9
A17: =[1]Puntajes!A17 -> 49 | B17: =[1]Puntajes!B17 -> 12 | C17: =[1]Puntajes!C17 -> Waldo | D17: =[1]Puntajes!D17 -> 43 | E17: =[1]Puntajes!E17 -> 153 | F17: =[1]Puntajes!F17 -> 196 | I17: =Partidos!F73 -> RD Congo | J17: =Partidos!G73 -> Uzbekistán | L17: =Partidos!C73 -> 0.77083333 | N17: =Grupo!A18 -> Javier | O17: =Participantes!A17 -> 17 | P17: =Grupo!HJ18 -> 48 | Q17: =P17*100-ROW() -> 4783 | R17: =SUMPRODUCT(($Q$2:$Q$50>Q17)*1)+1 -> 28
A18: =[1]Puntajes!A18 -> 18 | B18: =[1]Puntajes!B18 -> 13 | C18: =[1]Puntajes!C18 -> Jose C 1 | D18: =[1]Puntajes!D18 -> 46 | E18: =[1]Puntajes!E18 -> 149 | F18: =[1]Puntajes!F18 -> 195 | I18: =IF(Partidos!H73="","",Partidos!H73) | J18: =IF(Partidos!I73="","",Partidos!I73) | N18: =Grupo!A19 -> Jose C 1 | O18: =Participantes!A18 -> 18 | P18: =Grupo!HJ19 -> 46 | Q18: =P18*100-ROW() -> 4582 | R18: =SUMPRODUCT(($Q$2:$Q$50>Q18)*1)+1 -> 33
A19: =[1]Puntajes!A19 -> 26 | B19: =[1]Puntajes!B19 -> 14 | C19: =[1]Puntajes!C19 -> Kattia 1 | D19: =[1]Puntajes!D19 -> 49 | E19: =[1]Puntajes!E19 -> 145 | F19: =[1]Puntajes!F19 -> 194 | N19: =Grupo!A20 -> Jose C 2 | O19: =Participantes!A19 -> 19 | P19: =Grupo!HJ20 -> 52 | Q19: =P19*100-ROW() -> 5181 | R19: =SUMPRODUCT(($Q$2:$Q$50>Q19)*1)+1 -> 14
A20: =[1]Puntajes!A20 -> 39 | B20: =[1]Puntajes!B20 -> 15 | C20: =[1]Puntajes!C20 -> Mily Zeynneth | D20: =[1]Puntajes!D20 -> 50 | E20: =[1]Puntajes!E20 -> 143 | F20: =[1]Puntajes!F20 -> 193 | I20: =IF(M1=TODAY()-1,"Finalizado",IF(NOW()<M1+L21,"Por iniciar",IF(NOW()<=M1+L21+2/24,"Iniciado","Finalizado"))) -> Finalizado | N20: =Grupo!A21 -> Jose C Ahiza | O20: =Participantes!A20 -> 20 | P20: =Grupo!HJ21 -> 55 | Q20: =P20*100-ROW() -> 5480 | R20: =SUMPRODUCT(($Q$2:$Q$50>Q20)*1)+1 -> 7
A21: =[1]Puntajes!A21 -> 8 | B21: =[1]Puntajes!B21 -> 16 | C21: =[1]Puntajes!C21 -> Castillo L. | D21: =[1]Puntajes!D21 -> 50 | E21: =[1]Puntajes!E21 -> 140 | F21: =[1]Puntajes!F21 -> 190 | I21: =Partidos!F70 -> Argelia | J21: =Partidos!G70 -> Austria | L21: =Partidos!C70 -> 0.875 | N21: =Grupo!A22 -> Jose C Ana | O21: =Participantes!A21 -> 21 | P21: =Grupo!HJ22 -> 47 | Q21: =P21*100-ROW() -> 4679 | R21: =SUMPRODUCT(($Q$2:$Q$50>Q21)*1)+1 -> 29
A22: =[1]Puntajes!A22 -> 37 | B22: =[1]Puntajes!B22 -> 17 | C22: =[1]Puntajes!C22 -> Mily CF 2 | D22: =[1]Puntajes!D22 -> 41 | E22: =[1]Puntajes!E22 -> 147 | F22: =[1]Puntajes!F22 -> 188 | I22: =IF(Partidos!H70="","",Partidos!H70) | J22: =IF(Partidos!I70="","",Partidos!I70) | N22: =Grupo!A23 -> Jose C Judith | O22: =Participantes!A22 -> 22 | P22: =Grupo!HJ23 -> 53 | Q22: =P22*100-ROW() -> 5278 | R22: =SUMPRODUCT(($Q$2:$Q$50>Q22)*1)+1 -> 10
A23: =[1]Puntajes!A23 -> 47 | B23: =[1]Puntajes!B23 -> 17 | C23: =[1]Puntajes!C23 -> Silvia | D23: =[1]Puntajes!D23 -> 49 | E23: =[1]Puntajes!E23 -> 139 | F23: =[1]Puntajes!F23 -> 188 | N23: =Grupo!A24 -> José de León | O23: =Participantes!A23 -> 23 | P23: =Grupo!HJ24 -> 45 | Q23: =P23*100-ROW() -> 4477 | R23: =SUMPRODUCT(($Q$2:$Q$50>Q23)*1)+1 -> 35
A24: =[1]Puntajes!A24 -> 19 | B24: =[1]Puntajes!B24 -> 18 | C24: =[1]Puntajes!C24 -> Jose C 2 | D24: =[1]Puntajes!D24 -> 52 | E24: =[1]Puntajes!E24 -> 135 | F24: =[1]Puntajes!F24 -> 187 | I24: =IF(M1=TODAY()-1,"Finalizado",IF(NOW()<M1+L25,"Por iniciar",IF(NOW()<=M1+L25+2/24,"Iniciado","Finalizado"))) -> Finalizado | N24: =Grupo!A25 -> Jovanna | O24: =Participantes!A24 -> 24 | P24: =Grupo!HJ25 -> 44 | Q24: =P24*100-ROW() -> 4376 | R24: =SUMPRODUCT(($Q$2:$Q$50>Q24)*1)+1 -> 37
A25: =[1]Puntajes!A25 -> 24 | B25: =[1]Puntajes!B25 -> 18 | C25: =[1]Puntajes!C25 -> Jovanna | D25: =[1]Puntajes!D25 -> 44 | E25: =[1]Puntajes!E25 -> 143 | F25: =[1]Puntajes!F25 -> 187 | I25: =Partidos!F71 -> Jordania | J25: =Partidos!G71 -> Argentina | L25: =Partidos!C71 -> 0.875 | N25: =Grupo!A26 -> Karina | O25: =Participantes!A25 -> 25 | P25: =Grupo!HJ26 -> 47 | Q25: =P25*100-ROW() -> 4675 | R25: =SUMPRODUCT(($Q$2:$Q$50>Q25)*1)+1 -> 30
A26: =[1]Puntajes!A26 -> 7 | B26: =[1]Puntajes!B26 -> 19 | C26: =[1]Puntajes!C26 -> Carlos | D26: =[1]Puntajes!D26 -> 46 | E26: =[1]Puntajes!E26 -> 140 | F26: =[1]Puntajes!F26 -> 186 | I26: =IF(Partidos!H71="","",Partidos!H71) | J26: =IF(Partidos!I71="","",Partidos!I71) | N26: =Grupo!A27 -> Kattia 1 | O26: =Participantes!A26 -> 26 | P26: =Grupo!HJ27 -> 49 | Q26: =P26*100-ROW() -> 4874 | R26: =SUMPRODUCT(($Q$2:$Q$50>Q26)*1)+1 -> 23
A27: =[1]Puntajes!A27 -> 11 | B27: =[1]Puntajes!B27 -> 20 | C27: =[1]Puntajes!C27 -> Edward | D27: =[1]Puntajes!D27 -> 57 | E27: =[1]Puntajes!E27 -> 128 | F27: =[1]Puntajes!F27 -> 185 | N27: =Grupo!A28 -> Kattia 2 | O27: =Participantes!A27 -> 27 | P27: =Grupo!HJ28 -> 58 | Q27: =P27*100-ROW() -> 5773 | R27: =SUMPRODUCT(($Q$2:$Q$50>Q27)*1)+1 -> 3
A28: =[1]Puntajes!A28 -> 43 | B28: =[1]Puntajes!B28 -> 20 | C28: =[1]Puntajes!C28 -> Peter | D28: =[1]Puntajes!D28 -> 52 | E28: =[1]Puntajes!E28 -> 133 | F28: =[1]Puntajes!F28 -> 185 | N28: =Grupo!A29 -> Kevin | O28: =Participantes!A28 -> 28 | P28: =Grupo!HJ29 -> 50 | Q28: =P28*100-ROW() -> 4972 | R28: =SUMPRODUCT(($Q$2:$Q$50>Q28)*1)+1 -> 20
A29: =[1]Puntajes!A29 -> 10 | B29: =[1]Puntajes!B29 -> 21 | C29: =[1]Puntajes!C29 -> Cynthia | D29: =[1]Puntajes!D29 -> 48 | E29: =[1]Puntajes!E29 -> 135 | F29: =[1]Puntajes!F29 -> 183 | N29: =Grupo!A30 -> Lizka | O29: =Participantes!A29 -> 29 | P29: =Grupo!HJ30 -> 35 | Q29: =P29*100-ROW() -> 3471 | R29: =SUMPRODUCT(($Q$2:$Q$50>Q29)*1)+1 -> 48
A30: =[1]Puntajes!A30 -> 22 | B30: =[1]Puntajes!B30 -> 21 | C30: =[1]Puntajes!C30 -> Jose C Judith | D30: =[1]Puntajes!D30 -> 53 | E30: =[1]Puntajes!E30 -> 130 | F30: =[1]Puntajes!F30 -> 183 | N30: =Grupo!A31 -> Luis Peña | O30: =Participantes!A30 -> 30 | P30: =Grupo!HJ31 -> 63 | Q30: =P30*100-ROW() -> 6270 | R30: =SUMPRODUCT(($Q$2:$Q$50>Q30)*1)+1 -> 1
A31: =[1]Puntajes!A31 -> 28 | B31: =[1]Puntajes!B31 -> 22 | C31: =[1]Puntajes!C31 -> Kevin | D31: =[1]Puntajes!D31 -> 50 | E31: =[1]Puntajes!E31 -> 132 | F31: =[1]Puntajes!F31 -> 182 | N31: =Grupo!A32 -> Marco R. | O31: =Participantes!A31 -> 31 | P31: =Grupo!HJ32 -> 53 | Q31: =P31*100-ROW() -> 5269 | R31: =SUMPRODUCT(($Q$2:$Q$50>Q31)*1)+1 -> 11
A32: =[1]Puntajes!A32 -> 41 | B32: =[1]Puntajes!B32 -> 23 | C32: =[1]Puntajes!C32 -> Ninoshka | D32: =[1]Puntajes!D32 -> 42 | E32: =[1]Puntajes!E32 -> 139 | F32: =[1]Puntajes!F32 -> 181 | N32: =Grupo!A33 -> Maricela | O32: =Participantes!A32 -> 32 | P32: =Grupo!HJ33 -> 39 | Q32: =P32*100-ROW() -> 3868 | R32: =SUMPRODUCT(($Q$2:$Q$50>Q32)*1)+1 -> 46
A33: =[1]Puntajes!A33 -> 42 | B33: =[1]Puntajes!B33 -> 23 | C33: =[1]Puntajes!C33 -> Osvaldo | D33: =[1]Puntajes!D33 -> 51 | E33: =[1]Puntajes!E33 -> 130 | F33: =[1]Puntajes!F33 -> 181 | N33: =Grupo!A34 -> Marilyn | O33: =Participantes!A33 -> 33 | P33: =Grupo!HJ34 -> 49 | Q33: =P33*100-ROW() -> 4867 | R33: =SUMPRODUCT(($Q$2:$Q$50>Q33)*1)+1 -> 24
A34: =[1]Puntajes!A34 -> 5 | B34: =[1]Puntajes!B34 -> 24 | C34: =[1]Puntajes!C34 -> Aneth | D34: =[1]Puntajes!D34 -> 52 | E34: =[1]Puntajes!E34 -> 127 | F34: =[1]Puntajes!F34 -> 179 | N34: =Grupo!A35 -> Medica | O34: =Participantes!A34 -> 34 | P34: =Grupo!HJ35 -> 59 | Q34: =P34*100-ROW() -> 5866 | R34: =SUMPRODUCT(($Q$2:$Q$50>Q34)*1)+1 -> 2
A35: =[1]Puntajes!A35 -> 25 | B35: =[1]Puntajes!B35 -> 24 | C35: =[1]Puntajes!C35 -> Karina | D35: =[1]Puntajes!D35 -> 47 | E35: =[1]Puntajes!E35 -> 132 | F35: =[1]Puntajes!F35 -> 179 | N35: =Grupo!A36 -> Milagros | O35: =Participantes!A35 -> 35 | P35: =Grupo!HJ36 -> 55 | Q35: =P35*100-ROW() -> 5465 | R35: =SUMPRODUCT(($Q$2:$Q$50>Q35)*1)+1 -> 8
A36: =[1]Puntajes!A36 -> 14 | B36: =[1]Puntajes!B36 -> 25 | C36: =[1]Puntajes!C36 -> Mily Frida | D36: =[1]Puntajes!D36 -> 52 | E36: =[1]Puntajes!E36 -> 126 | F36: =[1]Puntajes!F36 -> 178 | N36: =Grupo!A37 -> Mily CF 1 | O36: =Participantes!A36 -> 36 | P36: =Grupo!HJ37 -> 50 | Q36: =P36*100-ROW() -> 4964 | R36: =SUMPRODUCT(($Q$2:$Q$50>Q36)*1)+1 -> 21
A37: =[1]Puntajes!A37 -> 23 | B37: =[1]Puntajes!B37 -> 26 | C37: =[1]Puntajes!C37 -> José de León | D37: =[1]Puntajes!D37 -> 45 | E37: =[1]Puntajes!E37 -> 132 | F37: =[1]Puntajes!F37 -> 177 | N37: =Grupo!A38 -> Mily CF 2 | O37: =Participantes!A37 -> 37 | P37: =Grupo!HJ38 -> 41 | Q37: =P37*100-ROW() -> 4063 | R37: =SUMPRODUCT(($Q$2:$Q$50>Q37)*1)+1 -> 43
A38: =[1]Puntajes!A38 -> 48 | B38: =[1]Puntajes!B38 -> 26 | C38: =[1]Puntajes!C38 -> Walder | D38: =[1]Puntajes!D38 -> 45 | E38: =[1]Puntajes!E38 -> 132 | F38: =[1]Puntajes!F38 -> 177 | N38: =Grupo!A39 -> Mily Frida | O38: =Participantes!A38 -> 14 | P38: =Grupo!HJ39 -> 52 | Q38: =P38*100-ROW() -> 5162 | R38: =SUMPRODUCT(($Q$2:$Q$50>Q38)*1)+1 -> 15
... A50: =[1]Puntajes!A50 -> 9 | B50: =[1]Puntajes!B50 -> 34 | C50: =[1]Puntajes!C50 -> Christofer | D50: =[1]Puntajes!D50 -> 32 | E50: =[1]Puntajes!E50 -> 112 | F50: =[1]Puntajes!F50 -> 144 | N50: =Grupo!A51 -> Waldo | O50: =Participantes!A50 -> 49 | P50: =Grupo!HJ51 -> 43 | Q50: =P50*100-ROW() -> 4250 | R50: =SUMPRODUCT(($Q$2:$Q$50>Q50)*1)+1 -> 40

Sheet Puntaje Anterior
A1: Número | B1: Posición | C1: Nombre | D1: Marcadores | E1: Posiciones | F1: Total | I1: 46200.008 | M1: 46199
A2: 30 | B2: 1 | C2: Luis Peña | D2: 63 | E2: 155 | F2: 218
A3: 34 | B3: 2 | C3: Medica | D3: 59 | E3: 155 | F3: 214
A4: 31 | B4: 3 | C4: Marco R. | D4: 53 | E4: 158 | F4: 211 | I4: Finalizado
A5: 3 | B5: 4 | C5: Alfredo 1 | D5: 52 | E5: 157 | F5: 209 | I5: Noruega | J5: Francia | L5: 0.58333333
A6: 44 | B6: 5 | C6: Quinnie | D6: 57 | E6: 151 | F6: 208 | I6: 1 | J6: 4
A7: 38 | B7: 6 | C7: Mily Oliver | D7: 47 | E7: 158 | F7: 205
A8: 2 | B8: 7 | C8: Alexander | D8: 55 | E8: 149 | F8: 204 | I8: Finalizado
A9: 16 | B9: 7 | C9: Isabel 2 | D9: 53 | E9: 151 | F9: 204 | I9: Senegal | J9: Irak | L9: 0.58333333
A10: 27 | B10: 8 | C10: Kattia 2 | D10: 58 | E10: 145 | F10: 203 | I10: 5 | J10: 0
A11: 46 | B11: 8 | C11: Saul | D11: 46 | E11: 157 | F11: 203
A12: 20 | B12: 9 | C12: Jose C Ahiza | D12: 55 | E12: 144 | F12: 199 | I12: Finalizado
A13: 35 | B13: 9 | C13: Milagros | D13: 55 | E13: 144 | F13: 199 | I13: Cabo Verde | J13: Arabia | L13: 0.79166667
A14: 45 | B14: 9 | C14: Radames | D14: 44 | E14: 155 | F14: 199 | I14: 0 | J14: 0
A15: 4 | B15: 10 | C15: Alfredo 2 | D15: 50 | E15: 148 | F15: 198
A16: 1 | B16: 11 | C16: Alberto | D16: 48 | E16: 149 | F16: 197 | I16: Finalizado
A17: 49 | B17: 12 | C17: Waldo | D17: 43 | E17: 153 | F17: 196 | I17: Uruguay | J17: España | L17: 0.79166667
A18: 18 | B18: 13 | C18: Jose C 1 | D18: 46 | E18: 149 | F18: 195 | I18: 0 | J18: 1
A19: 26 | B19: 14 | C19: Kattia 1 | D19: 49 | E19: 145 | F19: 194
A20: 39 | B20: 15 | C20: Mily Zeynneth | D20: 50 | E20: 143 | F20: 193 | I20: Finalizado
A21: 8 | B21: 16 | C21: Castillo L. | D21: 50 | E21: 140 | F21: 190 | I21: Egipto | J21: Irán | L21: 0.91666667
A22: 37 | B22: 17 | C22: Mily CF 2 | D22: 41 | E22: 147 | F22: 188 | I22: 1 | J22: 1
A23: 47 | B23: 17 | C23: Silvia | D23: 49 | E23: 139 | F23: 188
A24: 19 | B24: 18 | C24: Jose C 2 | D24: 52 | E24: 135 | F24: 187 | I24: Finalizado
A25: 24 | B25: 18 | C25: Jovanna | D25: 44 | E25: 143 | F25: 187 | I25: Nueva Zelanda | J25: Bélgica | L25: 0.91666667
A26: 7 | B26: 19 | C26: Carlos | D26: 46 | E26: 140 | F26: 186 | I26: 1 | J26: 5
A27: 11 | B27: 20 | C27: Edward | D27: 57 | E27: 128 | F27: 185
A28: 43 | B28: 20 | C28: Peter | D28: 52 | E28: 133 | F28: 185
A29: 10 | B29: 21 | C29: Cynthia | D29: 48 | E29: 135 | F29: 183
A30: 22 | B30: 21 | C30: Jose C Judith | D30: 53 | E30: 130 | F30: 183
A31: 28 | B31: 22 | C31: Kevin | D31: 50 | E31: 132 | F31: 182
A32: 41 | B32: 23 | C32: Ninoshka | D32: 42 | E32: 139 | F32: 181
A33: 42 | B33: 23 | C33: Osvaldo | D33: 51 | E33: 130 | F33: 181
A34: 5 | B34: 24 | C34: Aneth | D34: 52 | E34: 127 | F34: 179
A35: 25 | B35: 24 | C35: Karina | D35: 47 | E35: 132 | F35: 179
A36: 14 | B36: 25 | C36: Mily Frida | D36: 52 | E36: 126 | F36: 178
A37: 23 | B37: 26 | C37: José de León | D37: 45 | E37: 132 | F37: 177
A38: 48 | B38: 26 | C38: Walder | D38: 45 | E38: 132 | F38: 177
... A50: 9 | B50: 34 | C50: Christofer | D50: 32 | E50: 112 | F50: 144

Sheet ClaGrupo
A1: Grupos | B1: A | I1: B | P1: C | W1: D | AD1: E | AK1: F | AR1: G | AY1: H | BF1: I | BM1: J | BT1: K | CA1: L
A2: Posición | B2: 1° | C2: P | D2: 2° | E2: P | F2: 3° | G2: P | H2: T | I2: 1° | J2: P | K2: 2° | L2: P | M2: 3° | N2: P | O2: T | P2: 1° | Q2: P | R2: 2° | S2: P | T2: 3° | U2: P | V2: T | W2: 1° | X2: P | Y2: 2° | Z2: P | AA2: 3° | AB2: P | AC2: T | AD2: 1° | AE2: P | AF2: 2° | AG2: P | AH2: 3° | AI2: P | AJ2: T | AK2: 1° | AL2: P | AM2: 2° | AN2: P | AO2: 3° | AP2: P | AQ2: T | AR2: 1° | AS2: P | AT2: 2° | AU2: P | AV2: 3° | AW2: P | AX2: T | AY2: 1° | AZ2: P | BA2: 2° | BB2: P | BC2: 3° | BD2: P | BE2: T | BF2: 1° | BG2: P | BH2: 2° | BI2: P | BJ2: 3° | BK2: P | BL2: T | BM2: 1° | BN2: P | BO2: 2° | BP2: P | BQ2: 3° | BR2: P | BS2: T | BT2: 1° | BU2: P | BV2: 2° | BW2: P | BX2: 3° | BY2: P | BZ2: T | CA2: 1° | CB2: P | CC2: 2° | CD2: P | CE2: 3° | CF2: P | CG2: T | CH2: Total
A3: Equipos | B3: =[1]Posiciones!$D2 -> México | D3: =[1]Posiciones!$D3 -> Sudáfrica | F3: =IF(AND([1]Posiciones!$D4=[1]Mejores_Terceros!$C2,[1]Mejores_Terceros!$I2="Sí"),[1]Mejores_Terceros!$C2,"") -> Corea República | I3: =[1]Posiciones!$D6 -> Suiza | K3: =[1]Posiciones!$D7 -> Canadá | M3: =IF(AND([1]Posiciones!$D8=[1]Mejores_Terceros!$C3,[1]Mejores_Terceros!$I3="Sí"),[1]Mejores_Terceros!$C3,"") -> Bosnia y Herzegovina | P3: =[1]Posiciones!$D10 -> Brasil | R3: =[1]Posiciones!$D11 -> Marruecos | T3: =IF(AND([1]Posiciones!$D12=[1]Mejores_Terceros!$C4,[1]Mejores_Terceros!$I4="Sí"),[1]Mejores_Terceros!$C4,"") | W3: =[1]Posiciones!$D14 -> Estados Unidos | Y3: =[1]Posiciones!$D15 -> Australia | AA3: =IF(AND([1]Posiciones!$D16=[1]Mejores_Terceros!$C5,[1]Mejores_Terceros!$I5="Sí"),[1]Mejores_Terceros!$C5,"") -> Paraguay | AD3: =[1]Posiciones!$D18 -> Alemania | AF3: =[1]Posiciones!$D19 -> Costa de Marfil | AH3: =IF(AND([1]Posiciones!$D20=[1]Mejores_Terceros!$C6,[1]Mejores_Terceros!$I6="Sí"),[1]Mejores_Terceros!$C6,"") -> Ecuador | AK3: =[1]Posiciones!$D22 -> Países Bajos | AM3: =[1]Posiciones!$D23 -> Japón | AO3: =IF(AND([1]Posiciones!$D24=[1]Mejores_Terceros!$C7,[1]Mejores_Terceros!$I7="Sí"),[1]Mejores_Terceros!$C7,"") -> Suecia | AR3: =[1]Posiciones!$D26 -> Bélgica | AT3: =[1]Posiciones!$D27 -> Egipto | AV3: =IF(AND([1]Posiciones!$D28=[1]Mejores_Terceros!$C8,[1]Mejores_Terceros!$I8="Sí"),[1]Mejores_Terceros!$C8,"") -> Irán | AY3: =[1]Posiciones!$D30 -> España | BA3: =[1]Posiciones!$D31 -> Cabo Verde | BC3: =IF(AND([1]Posiciones!$D32=[1]Mejores_Terceros!$C9,[1]Mejores_Terceros!$I9="Sí"),[1]Mejores_Terceros!$C9,"") | BF3: =[1]Posiciones!$D34 -> Francia | BH3: =[1]Posiciones!$D35 -> Noruega | BJ3: =IF(AND([1]Posiciones!$D36=[1]Mejores_Terceros!$C10,[1]Mejores_Terceros!$I10="Sí"),[1]Mejores_Terceros!$C10,"") -> Senegal | BM3: =[1]Posiciones!$D38 -> Argentina | BO3: =[1]Posiciones!$D39 -> Austria | BQ3: =IF(AND([1]Posiciones!$D40=[1]Mejores_Terceros!$C11,[1]Mejores_Terceros!$I11="Sí"),[1]Mejores_Terceros!$C11,"") | BT3: =[1]Posiciones!$D42 -> Colombia | BV3: =[1]Posiciones!$D43 -> Portugal | BX3: =IF(AND([1]Posiciones!$D44=[1]Mejores_Terceros!$C12,[1]Mejores_Terceros!$I12="Sí"),[1]Mejores_Terceros!$C12,"") | CA3: =[1]Posiciones!$D46 -> Inglaterra | CC3: =[1]Posiciones!$D47 -> Ghana | CE3: =IF(AND([1]Posiciones!$D48=[1]Mejores_Terceros!$C13,[1]Mejores_Terceros!$I13="Sí"),[1]Mejores_Terceros!$C13,"") -> Croacia
A4: =[1]Participantes!B2 -> Alberto | B4: =IF($A4="","",INDEX([1]Clasif_Pron!$E:$E,((ROW()-4)*12+2))) -> México | C4: =IF($A4="","",INDEX([1]Clasif_Pron!$K:$K,((ROW()-4)*12+2))) -> 7 | D4: =IF($A4="","",INDEX([1]Clasif_Pron!$G:$G,((ROW()-4)*12+2))) -> Corea República | E4: =IF($A4="","",INDEX([1]Clasif_Pron!$L:$L,((ROW()-4)*12+2))) -> 3 | F4: =IF($A4="","",INDEX([1]Clasif_Pron!$I:$I,((ROW()-4)*12+2))) -> Sudáfrica | G4: =IF($A4="","",INDEX([1]Clasif_Pron!$M:$M,((ROW()-4)*12+2))) -> 3 | H4: =IF($A4="","",INDEX([1]Clasif_Pron!$N:$N,((ROW()-4)*12+2))) -> 13 | I4: =IF($A4="","",INDEX([1]Clasif_Pron!$E:$E,((ROW()-4)*12+3))) -> Suiza | J4: =IF($A4="","",INDEX([1]Clasif_Pron!$K:$K,((ROW()-4)*12+3))) -> 7 | K4: =IF($A4="","",INDEX([1]Clasif_Pron!$G:$G,((ROW()-4)*12+3))) -> Canadá | L4: =IF($A4="","",INDEX([1]Clasif_Pron!$L:$L,((ROW()-4)*12+3))) -> 6 | M4: =IF($A4="","",INDEX([1]Clasif_Pron!$I:$I,((ROW()-4)*12+3))) -> Bosnia y Herzegovina | N4: =IF($A4="","",INDEX([1]Clasif_Pron!$M:$M,((ROW()-4)*12+3))) -> 5 | O4: =IF($A4="","",INDEX([1]Clasif_Pron!$N:$N,((ROW()-4)*12+3))) -> 18 | P4: =IF($A4="","",INDEX([1]Clasif_Pron!$E:$E,((ROW()-4)*12+4))) -> Marruecos | Q4: =IF($A4="","",INDEX([1]Clasif_Pron!$K:$K,((ROW()-4)*12+4))) -> 3 | R4: =IF($A4="","",INDEX([1]Clasif_Pron!$G:$G,((ROW()-4)*12+4))) -> Brasil | S4: =IF($A4="","",INDEX([1]Clasif_Pron!$L:$L,((ROW()-4)*12+4))) -> 3 | T4: =IF($A4="","",INDEX([1]Clasif_Pron!$I:$I,((ROW()-4)*12+4))) -> Escocia | U4: =IF($A4="","",INDEX([1]Clasif_Pron!$M:$M,((ROW()-4)*12+4))) -> 0 | V4: =IF($A4="","",INDEX([1]Clasif_Pron!$N:$N,((ROW()-4)*12+4))) -> 6 | W4: =IF($A4="","",INDEX([1]Clasif_Pron!$E:$E,((ROW()-4)*12+5))) -> Paraguay | X4: =IF($A4="","",INDEX([1]Clasif_Pron!$K:$K,((ROW()-4)*12+5))) -> 3 | Y4: =IF($A4="","",INDEX([1]Clasif_Pron!$G:$G,((ROW()-4)*12+5))) -> Türkiye | Z4: =IF($A4="","",INDEX([1]Clasif_Pron!$L:$L,((ROW()-4)*12+5))) -> 0 | AA4: =IF($A4="","",INDEX([1]Clasif_Pron!$I:$I,((ROW()-4)*12+5))) -> Estados Unidos | AB4: =IF($A4="","",INDEX([1]Clasif_Pron!$M:$M,((ROW()-4)*12+5))) -> 3 | AC4: =IF($A4="","",INDEX([1]Clasif_Pron!$N:$N,((ROW()-4)*12+5))) -> 6 | AD4: =IF($A4="","",INDEX([1]Clasif_Pron!$E:$E,((ROW()-4)*12+6))) -> Alemania | AE4: =IF($A4="","",INDEX([1]Clasif_Pron!$K:$K,((ROW()-4)*12+6))) -> 7 | AF4: =IF($A4="","",INDEX([1]Clasif_Pron!$G:$G,((ROW()-4)*12+6))) -> Ecuador | AG4: =IF($A4="","",INDEX([1]Clasif_Pron!$L:$L,((ROW()-4)*12+6))) -> 3 | AH4: =IF($A4="","",INDEX([1]Clasif_Pron!$I:$I,((ROW()-4)*12+6))) -> Costa de Marfil | AI4: =IF($A4="","",INDEX([1]Clasif_Pron!$M:$M,((ROW()-4)*12+6))) -> 3 | AJ4: =IF($A4="","",INDEX([1]Clasif_Pron!$N:$N,((ROW()-4)*12+6))) -> 13 | AK4: =IF($A4="","",INDEX([1]Clasif_Pron!$E:$E,((ROW()-4)*12+7))) -> Países Bajos | AL4: =IF($A4="","",INDEX([1]Clasif_Pron!$K:$K,((ROW()-4)*12+7))) -> 7 | AM4: =IF($A4="","",INDEX([1]Clasif_Pron!$G:$G,((ROW()-4)*12+7))) -> Japón | AN4: =IF($A4="","",INDEX([1]Clasif_Pron!$L:$L,((ROW()-4)*12+7))) -> 6 | AO4: =IF($A4="","",INDEX([1]Clasif_Pron!$I:$I,((ROW()-4)*12+7))) -> Suecia | AP4: =IF($A4="","",INDEX([1]Clasif_Pron!$M:$M,((ROW()-4)*12+7))) -> 5 | AQ4: =IF($A4="","",INDEX([1]Clasif_Pron!$N:$N,((ROW()-4)*12+7))) -> 18 | AR4: =IF($A4="","",INDEX([1]Clasif_Pron!$E:$E,((ROW()-4)*12+8))) -> Bélgica | AS4: =IF($A4="","",INDEX([1]Clasif_Pron!$K:$K,((ROW()-4)*12+8))) -> 7 | AT4: =IF($A4="","",INDEX([1]Clasif_Pron!$G:$G,((ROW()-4)*12+8))) -> Egipto | AU4: =IF($A4="","",INDEX([1]Clasif_Pron!$L:$L,((ROW()-4)*12+8))) -> 6 | AV4: =IF($A4="","",INDEX([1]Clasif_Pron!$I:$I,((ROW()-4)*12+8))) -> Irán | AW4: =IF($A4="","",INDEX([1]Clasif_Pron!$M:$M,((ROW()-4)*12+8))) -> 5 | AX4: =IF($A4="","",INDEX([1]Clasif_Pron!$N:$N,((ROW()-4)*12+8))) -> 18 | AY4: =IF($A4="","",INDEX([1]Clasif_Pron!$E:$E,((ROW()-4)*12+9))) -> España | AZ4: =IF($A4="","",INDEX([1]Clasif_Pron!$K:$K,((ROW()-4)*12+9))) -> 7 | BA4: =IF($A4="","",INDEX([1]Clasif_Pron!$G:$G,((ROW()-4)*12+9))) -> Uruguay | BB4: =IF($A4="","",INDEX([1]Clasif_Pron!$L:$L,((ROW()-4)*12+9))) -> 0 | BC4: =IF($A4="","",INDEX([1]Clasif_Pron!$I:$I,((ROW()-4)*12+9))) -> Arabia Saudita | BD4: =IF($A4="","",INDEX([1]Clasif_Pron!$M:$M,((ROW()-4)*12+9))) -> 0 | BE4: =IF($A4="","",INDEX([1]Clasif_Pron!$N:$N,((ROW()-4)*12+9))) -> 7 | BF4: =IF($A4="","",INDEX([1]Clasif_Pron!$E:$E,((ROW()-4)*12+10))) -> Francia | BG4: =IF($A4="","",INDEX([1]Clasif_Pron!$K:$K,((ROW()-4)*12+10))) -> 7 | BH4: =IF($A4="","",INDEX([1]Clasif_Pron!$G:$G,((ROW()-4)*12+10))) -> Noruega | BI4: =IF($A4="","",INDEX([1]Clasif_Pron!$L:$L,((ROW()-4)*12+10))) -> 6 | BJ4: =IF($A4="","",INDEX([1]Clasif_Pron!$I:$I,((ROW()-4)*12+10))) -> Senegal | BK4: =IF($A4="","",INDEX([1]Clasif_Pron!$M:$M,((ROW()-4)*12+10))) -> 5 | BL4: =IF($A4="","",INDEX([1]Clasif_Pron!$N:$N,((ROW()-4)*12+10))) -> 18 | BM4: =IF($A4="","",INDEX([1]Clasif_Pron!$E:$E,((ROW()-4)*12+11))) -> Argentina | BN4: =IF($A4="","",INDEX([1]Clasif_Pron!$K:$K,((ROW()-4)*12+11))) -> 7 | BO4: =IF($A4="","",INDEX([1]Clasif_Pron!$G:$G,((ROW()-4)*12+11))) -> Austria | BP4: =IF($A4="","",INDEX([1]Clasif_Pron!$L:$L,((ROW()-4)*12+11))) -> 6 | BQ4: =IF($A4="","",INDEX([1]Clasif_Pron!$I:$I,((ROW()-4)*12+11))) -> Argelia | BR4: =IF($A4="","",INDEX([1]Clasif_Pron!$M:$M,((ROW()-4)*12+11))) -> 0 | BS4: =IF($A4="","",INDEX([1]Clasif_Pron!$N:$N,((ROW()-4)*12+11))) -> 13 | BT4: =IF($A4="","",INDEX([1]Clasif_Pron!$E:$E,((ROW()-4)*12+12))) -> Portugal | BU4: =IF($A4="","",INDEX([1]Clasif_Pron!$K:$K,((ROW()-4)*12+12))) -> 3 | BV4: =IF($A4="","",INDEX([1]Clasif_Pron!$G:$G,((ROW()-4)*12+12))) -> Colombia | BW4: =IF($A4="","",INDEX([1]Clasif_Pron!$L:$L,((ROW()-4)*12+12))) -> 3 | BX4: =IF($A4="","",INDEX([1]Clasif_Pron!$I:$I,((ROW()-4)*12+12))) -> RD Congo | BY4: =IF($A4="","",INDEX([1]Clasif_Pron!$M:$M,((ROW()-4)*12+12))) -> 0 | BZ4: =IF($A4="","",INDEX([1]Clasif_Pron!$N:$N,((ROW()-4)*12+12))) -> 6 | CA4: =IF($A4="","",INDEX([1]Clasif_Pron!$E:$E,((ROW()-4)*12+13))) -> Inglaterra | CB4: =IF($A4="","",INDEX([1]Clasif_Pron!$K:$K,((ROW()-4)*12+13))) -> 7 | CC4: =IF($A4="","",INDEX([1]Clasif_Pron!$G:$G,((ROW()-4)*12+13))) -> Croacia | CD4: =IF($A4="","",INDEX([1]Clasif_Pron!$L:$L,((ROW()-4)*12+13))) -> 3 | CE4: =IF($A4="","",INDEX([1]Clasif_Pron!$I:$I,((ROW()-4)*12+13))) -> Ghana | CF4: =IF($A4="","",INDEX([1]Clasif_Pron!$M:$M,((ROW()-4)*12+13))) -> 3 | CG4: =IF($A4="","",INDEX([1]Clasif_Pron!$N:$N,((ROW()-4)*12+13))) -> 13 | CH4: =IF($A4="","",SUM(H4,O4,V4,AC4,AJ4,AQ4,AX4,BE4,BL4,BS4,BZ4,CG4)) -> 149
A5: =[1]Participantes!B3 -> Alexander | B5: =IF($A5="","",INDEX([1]Clasif_Pron!$E:$E,((ROW()-4)*12+2))) -> México | C5: =IF($A5="","",INDEX([1]Clasif_Pron!$K:$K,((ROW()-4)*12+2))) -> 7 | D5: =IF($A5="","",INDEX([1]Clasif_Pron!$G:$G,((ROW()-4)*12+2))) -> Corea República | E5: =IF($A5="","",INDEX([1]Clasif_Pron!$L:$L,((ROW()-4)*12+2))) -> 3 | F5: =IF($A5="","",INDEX([1]Clasif_Pron!$I:$I,((ROW()-4)*12+2))) -> Chequia | G5: =IF($A5="","",INDEX([1]Clasif_Pron!$M:$M,((ROW()-4)*12+2))) -> 0 | H5: =IF($A5="","",INDEX([1]Clasif_Pron!$N:$N,((ROW()-4)*12+2))) -> 10 | I5: =IF($A5="","",INDEX([1]Clasif_Pron!$E:$E,((ROW()-4)*12+3))) -> Canadá | J5: =IF($A5="","",INDEX([1]Clasif_Pron!$K:$K,((ROW()-4)*12+3))) -> 3 | K5: =IF($A5="","",INDEX([1]Clasif_Pron!$G:$G,((ROW()-4)*12+3))) -> Bosnia y Herzegovina | L5: =IF($A5="","",INDEX([1]Clasif_Pron!$L:$L,((ROW()-4)*12+3))) -> 3 | M5: =IF($A5="","",INDEX([1]Clasif_Pron!$I:$I,((ROW()-4)*12+3))) -> Suiza | N5: =IF($A5="","",INDEX([1]Clasif_Pron!$M:$M,((ROW()-4)*12+3))) -> 3 | O5: =IF($A5="","",INDEX([1]Clasif_Pron!$N:$N,((ROW()-4)*12+3))) -> 9 | P5: =IF($A5="","",INDEX([1]Clasif_Pron!$E:$E,((ROW()-4)*12+4))) -> Brasil | Q5: =IF($A5="","",INDEX([1]Clasif_Pron!$K:$K,((ROW()-4)*12+4))) -> 7 | R5: =IF($A5="","",INDEX([1]Clasif_Pron!$G:$G,((ROW()-4)*12+4))) -> Marruecos | S5: =IF($A5="","",INDEX([1]Clasif_Pron!$L:$L,((ROW()-4)*12+4))) -> 6 | T5: =IF($A5="","",INDEX([1]Clasif_Pron!$I:$I,((ROW()-4)*12+4))) -> Escocia | U5: =IF($A5="","",INDEX([1]Clasif_Pron!$M:$M,((ROW()-4)*12+4))) -> 0 | V5: =IF($A5="","",INDEX([1]Clasif_Pron!$N:$N,((ROW()-4)*12+4))) -> 13 | W5: =IF($A5="","",INDEX([1]Clasif_Pron!$E:$E,((ROW()-4)*12+5))) -> Estados Unidos | X5: =IF($A5="","",INDEX([1]Clasif_Pron!$K:$K,((ROW()-4)*12+5))) -> 7 | Y5: =IF($A5="","",INDEX([1]Clasif_Pron!$G:$G,((ROW()-4)*12+5))) -> Paraguay | Z5: =IF($A5="","",INDEX([1]Clasif_Pron!$L:$L,((ROW()-4)*12+5))) -> 3 | AA5: =IF($A5="","",INDEX([1]Clasif_Pron!$I:$I,((ROW()-4)*12+5))) -> Türkiye | AB5: =IF($A5="","",INDEX([1]Clasif_Pron!$M:$M,((ROW()-4)*12+5))) -> 0 | AC5: =IF($A5="","",INDEX([1]Clasif_Pron!$N:$N,((ROW()-4)*12+5))) -> 10 | AD5: =IF($A5="","",INDEX([1]Clasif_Pron!$E:$E,((ROW()-4)*12+6))) -> Alemania | AE5: =IF($A5="","",INDEX([1]Clasif_Pron!$K:$K,((ROW()-4)*12+6))) -> 7 | AF5: =IF($A5="","",INDEX([1]Clasif_Pron!$G:$G,((ROW()-4)*12+6))) -> Costa de Marfil | AG5: =IF($A5="","",INDEX([1]Clasif_Pron!$L:$L,((ROW()-4)*12+6))) -> 6 | AH5: =IF($A5="","",INDEX([1]Clasif_Pron!$I:$I,((ROW()-4)*12+6))) -> Ecuador | AI5: =IF($A5="","",INDEX([1]Clasif_Pron!$M:$M,((ROW()-4)*12+6))) -> 5 | AJ5: =IF($A5="","",INDEX([1]Clasif_Pron!$N:$N,((ROW()-4)*12+6))) -> 18 | AK5: =IF($A5="","",INDEX([1]Clasif_Pron!$E:$E,((ROW()-4)*12+7))) -> Países Bajos | AL5: =IF($A5="","",INDEX([1]Clasif_Pron!$K:$K,((ROW()-4)*12+7))) -> 7 | AM5: =IF($A5="","",INDEX([1]Clasif_Pron!$G:$G,((ROW()-4)*12+7))) -> Japón | AN5: =IF($A5="","",INDEX([1]Clasif_Pron!$L:$L,((ROW()-4)*12+7))) -> 6 | AO5: =IF($A5="","",INDEX([1]Clasif_Pron!$I:$I,((ROW()-4)*12+7))) -> Suecia | AP5: =IF($A5="","",INDEX([1]Clasif_Pron!$M:$M,((ROW()-4)*12+7))) -> 5 | AQ5: =IF($A5="","",INDEX([1]Clasif_Pron!$N:$N,((ROW()-4)*12+7))) -> 18 | AR5: =IF($A5="","",INDEX([1]Clasif_Pron!$E:$E,((ROW()-4)*12+8))) -> Bélgica | AS5: =IF($A5="","",INDEX([1]Clasif_Pron!$K:$K,((ROW()-4)*12+8))) -> 7 | AT5: =IF($A5="","",INDEX([1]Clasif_Pron!$G:$G,((ROW()-4)*12+8))) -> Egipto | AU5: =IF($A5="","",INDEX([1]Clasif_Pron!$L:$L,((ROW()-4)*12+8))) -> 6 | AV5: =IF($A5="","",INDEX([1]Clasif_Pron!$I:$I,((ROW()-4)*12+8))) -> Irán | AW5: =IF($A5="","",INDEX([1]Clasif_Pron!$M:$M,((ROW()-4)*12+8))) -> 5 | AX5: =IF($A5="","",INDEX([1]Clasif_Pron!$N:$N,((ROW()-4)*12+8))) -> 18 | AY5: =IF($A5="","",INDEX([1]Clasif_Pron!$E:$E,((ROW()-4)*12+9))) -> España | AZ5: =IF($A5="","",INDEX([1]Clasif_Pron!$K:$K,((ROW()-4)*12+9))) -> 7 | BA5: =IF($A5="","",INDEX([1]Clasif_Pron!$G:$G,((ROW()-4)*12+9))) -> Uruguay | BB5: =IF($A5="","",INDEX([1]Clasif_Pron!$L:$L,((ROW()-4)*12+9))) -> 0 | BC5: =IF($A5="","",INDEX([1]Clasif_Pron!$I:$I,((ROW()-4)*12+9))) -> Arabia Saudita | BD5: =IF($A5="","",INDEX([1]Clasif_Pron!$M:$M,((ROW()-4)*12+9))) -> 0 | BE5: =IF($A5="","",INDEX([1]Clasif_Pron!$N:$N,((ROW()-4)*12+9))) -> 7 | BF5: =IF($A5="","",INDEX([1]Clasif_Pron!$E:$E,((ROW()-4)*12+10))) -> Francia | BG5: =IF($A5="","",INDEX([1]Clasif_Pron!$K:$K,((ROW()-4)*12+10))) -> 7 | BH5: =IF($A5="","",INDEX([1]Clasif_Pron!$G:$G,((ROW()-4)*12+10))) -> Senegal | BI5: =IF($A5="","",INDEX([1]Clasif_Pron!$L:$L,((ROW()-4)*12+10))) -> 3 | BJ5: =IF($A5="","",INDEX([1]Clasif_Pron!$I:$I,((ROW()-4)*12+10))) -> Noruega | BK5: =IF($A5="","",INDEX([1]Clasif_Pron!$M:$M,((ROW()-4)*12+10))) -> 3 | BL5: =IF($A5="","",INDEX([1]Clasif_Pron!$N:$N,((ROW()-4)*12+10))) -> 13 | BM5: =IF($A5="","",INDEX([1]Clasif_Pron!$E:$E,((ROW()-4)*12+11))) -> Argentina | BN5: =IF($A5="","",INDEX([1]Clasif_Pron!$K:$K,((ROW()-4)*12+11))) -> 7 | BO5: =IF($A5="","",INDEX([1]Clasif_Pron!$G:$G,((ROW()-4)*12+11))) -> Argelia | BP5: =IF($A5="","",INDEX([1]Clasif_Pron!$L:$L,((ROW()-4)*12+11))) -> 0 | BQ5: =IF($A5="","",INDEX([1]Clasif_Pron!$I:$I,((ROW()-4)*12+11))) -> Austria | BR5: =IF($A5="","",INDEX([1]Clasif_Pron!$M:$M,((ROW()-4)*12+11))) -> 3 | BS5: =IF($A5="","",INDEX([1]Clasif_Pron!$N:$N,((ROW()-4)*12+11))) -> 10 | BT5: =IF($A5="","",INDEX([1]Clasif_Pron!$E:$E,((ROW()-4)*12+12))) -> Colombia | BU5: =IF($A5="","",INDEX([1]Clasif_Pron!$K:$K,((ROW()-4)*12+12))) -> 7 | BV5: =IF($A5="","",INDEX([1]Clasif_Pron!$G:$G,((ROW()-4)*12+12))) -> Portugal | BW5: =IF($A5="","",INDEX([1]Clasif_Pron!$L:$L,((ROW()-4)*12+12))) -> 6 | BX5: =IF($A5="","",INDEX([1]Clasif_Pron!$I:$I,((ROW()-4)*12+12))) -> RD Congo | BY5: =IF($A5="","",INDEX([1]Clasif_Pron!$M:$M,((ROW()-4)*12+12))) -> 0 | BZ5: =IF($A5="","",INDEX([1]Clasif_Pron!$N:$N,((ROW()-4)*12+12))) -> 13 | CA5: =IF($A5="","",INDEX([1]Clasif_Pron!$E:$E,((ROW()-4)*12+13))) -> Inglaterra | CB5: =IF($A5="","",INDEX([1]Clasif_Pron!$K:$K,((ROW()-4)*12+13))) -> 7 | CC5: =IF($A5="","",INDEX([1]Clasif_Pron!$G:$G,((ROW()-4)*12+13))) -> Croacia | CD5: =IF($A5="","",INDEX([1]Clasif_Pron!$L:$L,((ROW()-4)*12+13))) -> 3 | CE5: =IF($A5="","",INDEX([1]Clasif_Pron!$I:$I,((ROW()-4)*12+13))) -> Panamá | CF5: =IF($A5="","",INDEX([1]Clasif_Pron!$M:$M,((ROW()-4)*12+13))) -> 0 | CG5: =IF($A5="","",INDEX([1]Clasif_Pron!$N:$N,((ROW()-4)*12+13))) -> 10 | CH5: =IF($A5="","",SUM(H5,O5,V5,AC5,AJ5,AQ5,AX5,BE5,BL5,BS5,BZ5,CG5)) -> 149
A6: =[1]Participantes!B4 -> Alfredo 1 | B6: =IF($A6="","",INDEX([1]Clasif_Pron!$E:$E,((ROW()-4)*12+2))) -> México | C6: =IF($A6="","",INDEX([1]Clasif_Pron!$K:$K,((ROW()-4)*12+2))) -> 7 | D6: =IF($A6="","",INDEX([1]Clasif_Pron!$G:$G,((ROW()-4)*12+2))) -> Chequia | E6: =IF($A6="","",INDEX([1]Clasif_Pron!$L:$L,((ROW()-4)*12+2))) -> 0 | F6: =IF($A6="","",INDEX([1]Clasif_Pron!$I:$I,((ROW()-4)*12+2))) -> Corea República | G6: =IF($A6="","",INDEX([1]Clasif_Pron!$M:$M,((ROW()-4)*12+2))) -> 5 | H6: =IF($A6="","",INDEX([1]Clasif_Pron!$N:$N,((ROW()-4)*12+2))) -> 12 | I6: =IF($A6="","",INDEX([1]Clasif_Pron!$E:$E,((ROW()-4)*12+3))) -> Suiza | J6: =IF($A6="","",INDEX([1]Clasif_Pron!$K:$K,((ROW()-4)*12+3))) -> 7 | K6: =IF($A6="","",INDEX([1]Clasif_Pron!$G:$G,((ROW()-4)*12+3))) -> Canadá | L6: =IF($A6="","",INDEX([1]Clasif_Pron!$L:$L,((ROW()-4)*12+3))) -> 6 | M6: =IF($A6="","",INDEX([1]Clasif_Pron!$I:$I,((ROW()-4)*12+3))) -> Bosnia y Herzegovina | N6: =IF($A6="","",INDEX([1]Clasif_Pron!$M:$M,((ROW()-4)*12+3))) -> 5 | O6: =IF($A6="","",INDEX([1]Clasif_Pron!$N:$N,((ROW()-4)*12+3))) -> 18 | P6: =IF($A6="","",INDEX([1]Clasif_Pron!$E:$E,((ROW()-4)*12+4))) -> Brasil | Q6: =IF($A6="","",INDEX([1]Clasif_Pron!$K:$K,((ROW()-4)*12+4))) -> 7 | R6: =IF($A6="","",INDEX([1]Clasif_Pron!$G:$G,((ROW()-4)*12+4))) -> Marruecos | S6: =IF($A6="","",INDEX([1]Clasif_Pron!$L:$L,((ROW()-4)*12+4))) -> 6 | T6: =IF($A6="","",INDEX([1]Clasif_Pron!$I:$I,((ROW()-4)*12+4))) -> Escocia | U6: =IF($A6="","",INDEX([1]Clasif_Pron!$M:$M,((ROW()-4)*12+4))) -> 0 | V6: =IF($A6="","",INDEX([1]Clasif_Pron!$N:$N,((ROW()-4)*12+4))) -> 13 | W6: =IF($A6="","",INDEX([1]Clasif_Pron!$E:$E,((ROW()-4)*12+5))) -> Türkiye | X6: =IF($A6="","",INDEX([1]Clasif_Pron!$K:$K,((ROW()-4)*12+5))) -> 0 | Y6: =IF($A6="","",INDEX([1]Clasif_Pron!$G:$G,((ROW()-4)*12+5))) -> Estados Unidos | Z6: =IF($A6="","",INDEX([1]Clasif_Pron!$L:$L,((ROW()-4)*12+5))) -> 3 | AA6: =IF($A6="","",INDEX([1]Clasif_Pron!$I:$I,((ROW()-4)*12+5))) -> Paraguay | AB6: =IF($A6="","",INDEX([1]Clasif_Pron!$M:$M,((ROW()-4)*12+5))) -> 5 | AC6: =IF($A6="","",INDEX([1]Clasif_Pron!$N:$N,((ROW()-4)*12+5))) -> 8 | AD6: =IF($A6="","",INDEX([1]Clasif_Pron!$E:$E,((ROW()-4)*12+6))) -> Alemania | AE6: =IF($A6="","",INDEX([1]Clasif_Pron!$K:$K,((ROW()-4)*12+6))) -> 7 | AF6: =IF($A6="","",INDEX([1]Clasif_Pron!$G:$G,((ROW()-4)*12+6))) -> Ecuador | AG6: =IF($A6="","",INDEX([1]Clasif_Pron!$L:$L,((ROW()-4)*12+6))) -> 3 | AH6: =IF($A6="","",INDEX([1]Clasif_Pron!$I:$I,((ROW()-4)*12+6))) -> Costa de Marfil | AI6: =IF($A6="","",INDEX([1]Clasif_Pron!$M:$M,((ROW()-4)*12+6))) -> 3 | AJ6: =IF($A6="","",INDEX([1]Clasif_Pron!$N:$N,((ROW()-4)*12+6))) -> 13 | AK6: =IF($A6="","",INDEX([1]Clasif_Pron!$E:$E,((ROW()-4)*12+7))) -> Países Bajos | AL6: =IF($A6="","",INDEX([1]Clasif_Pron!$K:$K,((ROW()-4)*12+7))) -> 7 | AM6: =IF($A6="","",INDEX([1]Clasif_Pron!$G:$G,((ROW()-4)*12+7))) -> Japón | AN6: =IF($A6="","",INDEX([1]Clasif_Pron!$L:$L,((ROW()-4)*12+7))) -> 6 | AO6: =IF($A6="","",INDEX([1]Clasif_Pron!$I:$I,((ROW()-4)*12+7))) -> Suecia | AP6: =IF($A6="","",INDEX([1]Clasif_Pron!$M:$M,((ROW()-4)*12+7))) -> 5 | AQ6: =IF($A6="","",INDEX([1]Clasif_Pron!$N:$N,((ROW()-4)*12+7))) -> 18 | AR6: =IF($A6="","",INDEX([1]Clasif_Pron!$E:$E,((ROW()-4)*12+8))) -> Bélgica | AS6: =IF($A6="","",INDEX([1]Clasif_Pron!$K:$K,((ROW()-4)*12+8))) -> 7 | AT6: =IF($A6="","",INDEX([1]Clasif_Pron!$G:$G,((ROW()-4)*12+8))) -> Egipto | AU6: =IF($A6="","",INDEX([1]Clasif_Pron!$L:$L,((ROW()-4)*12+8))) -> 6 | AV6: =IF($A6="","",INDEX([1]Clasif_Pron!$I:$I,((ROW()-4)*12+8))) -> Irán | AW6: =IF($A6="","",INDEX([1]Clasif_Pron!$M:$M,((ROW()-4)*12+8))) -> 5 | AX6: =IF($A6="","",INDEX([1]Clasif_Pron!$N:$N,((ROW()-4)*12+8))) -> 18 | AY6: =IF($A6="","",INDEX([1]Clasif_Pron!$E:$E,((ROW()-4)*12+9))) -> España | AZ6: =IF($A6="","",INDEX([1]Clasif_Pron!$K:$K,((ROW()-4)*12+9))) -> 7 | BA6: =IF($A6="","",INDEX([1]Clasif_Pron!$G:$G,((ROW()-4)*12+9))) -> Uruguay | BB6: =IF($A6="","",INDEX([1]Clasif_Pron!$L:$L,((ROW()-4)*12+9))) -> 0 | BC6: =IF($A6="","",INDEX([1]Clasif_Pron!$I:$I,((ROW()-4)*12+9))) -> Arabia Saudita | BD6: =IF($A6="","",INDEX([1]Clasif_Pron!$M:$M,((ROW()-4)*12+9))) -> 0 | BE6: =IF($A6="","",INDEX([1]Clasif_Pron!$N:$N,((ROW()-4)*12+9))) -> 7 | BF6: =IF($A6="","",INDEX([1]Clasif_Pron!$E:$E,((ROW()-4)*12+10))) -> Francia | BG6: =IF($A6="","",INDEX([1]Clasif_Pron!$K:$K,((ROW()-4)*12+10))) -> 7 | BH6: =IF($A6="","",INDEX([1]Clasif_Pron!$G:$G,((ROW()-4)*12+10))) -> Noruega | BI6: =IF($A6="","",INDEX([1]Clasif_Pron!$L:$L,((ROW()-4)*12+10))) -> 6 | BJ6: =IF($A6="","",INDEX([1]Clasif_Pron!$I:$I,((ROW()-4)*12+10))) -> Senegal | BK6: =IF($A6="","",INDEX([1]Clasif_Pron!$M:$M,((ROW()-4)*12+10))) -> 5 | BL6: =IF($A6="","",INDEX([1]Clasif_Pron!$N:$N,((ROW()-4)*12+10))) -> 18 | BM6: =IF($A6="","",INDEX([1]Clasif_Pron!$E:$E,((ROW()-4)*12+11))) -> Argentina | BN6: =IF($A6="","",INDEX([1]Clasif_Pron!$K:$K,((ROW()-4)*12+11))) -> 7 | BO6: =IF($A6="","",INDEX([1]Clasif_Pron!$G:$G,((ROW()-4)*12+11))) -> Austria | BP6: =IF($A6="","",INDEX([1]Clasif_Pron!$L:$L,((ROW()-4)*12+11))) -> 6 | BQ6: =IF($A6="","",INDEX([1]Clasif_Pron!$I:$I,((ROW()-4)*12+11))) -> Argelia | BR6: =IF($A6="","",INDEX([1]Clasif_Pron!$M:$M,((ROW()-4)*12+11))) -> 0 | BS6: =IF($A6="","",INDEX([1]Clasif_Pron!$N:$N,((ROW()-4)*12+11))) -> 13 | BT6: =IF($A6="","",INDEX([1]Clasif_Pron!$E:$E,((ROW()-4)*12+12))) -> Portugal | BU6: =IF($A6="","",INDEX([1]Clasif_Pron!$K:$K,((ROW()-4)*12+12))) -> 3 | BV6: =IF($A6="","",INDEX([1]Clasif_Pron!$G:$G,((ROW()-4)*12+12))) -> Colombia | BW6: =IF($A6="","",INDEX([1]Clasif_Pron!$L:$L,((ROW()-4)*12+12))) -> 3 | BX6: =IF($A6="","",INDEX([1]Clasif_Pron!$I:$I,((ROW()-4)*12+12))) -> RD Congo | BY6: =IF($A6="","",INDEX([1]Clasif_Pron!$M:$M,((ROW()-4)*12+12))) -> 0 | BZ6: =IF($A6="","",INDEX([1]Clasif_Pron!$N:$N,((ROW()-4)*12+12))) -> 6 | CA6: =IF($A6="","",INDEX([1]Clasif_Pron!$E:$E,((ROW()-4)*12+13))) -> Inglaterra | CB6: =IF($A6="","",INDEX([1]Clasif_Pron!$K:$K,((ROW()-4)*12+13))) -> 7 | CC6: =IF($A6="","",INDEX([1]Clasif_Pron!$G:$G,((ROW()-4)*12+13))) -> Croacia | CD6: =IF($A6="","",INDEX([1]Clasif_Pron!$L:$L,((ROW()-4)*12+13))) -> 3 | CE6: =IF($A6="","",INDEX([1]Clasif_Pron!$I:$I,((ROW()-4)*12+13))) -> Ghana | CF6: =IF($A6="","",INDEX([1]Clasif_Pron!$M:$M,((ROW()-4)*12+13))) -> 3 | CG6: =IF($A6="","",INDEX([1]Clasif_Pron!$N:$N,((ROW()-4)*12+13))) -> 13 | CH6: =IF($A6="","",SUM(H6,O6,V6,AC6,AJ6,AQ6,AX6,BE6,BL6,BS6,BZ6,CG6)) -> 157
A7: =[1]Participantes!B5 -> Alfredo 2 | B7: =IF($A7="","",INDEX([1]Clasif_Pron!$E:$E,((ROW()-4)*12+2))) -> México | C7: =IF($A7="","",INDEX([1]Clasif_Pron!$K:$K,((ROW()-4)*12+2))) -> 7 | D7: =IF($A7="","",INDEX([1]Clasif_Pron!$G:$G,((ROW()-4)*12+2))) -> Chequia | E7: =IF($A7="","",INDEX([1]Clasif_Pron!$L:$L,((ROW()-4)*12+2))) -> 0 | F7: =IF($A7="","",INDEX([1]Clasif_Pron!$I:$I,((ROW()-4)*12+2))) -> Corea República | G7: =IF($A7="","",INDEX([1]Clasif_Pron!$M:$M,((ROW()-4)*12+2))) -> 5 | H7: =IF($A7="","",INDEX([1]Clasif_Pron!$N:$N,((ROW()-4)*12+2))) -> 12 | I7: =IF($A7="","",INDEX([1]Clasif_Pron!$E:$E,((ROW()-4)*12+3))) -> Canadá | J7: =IF($A7="","",INDEX([1]Clasif_Pron!$K:$K,((ROW()-4)*12+3))) -> 3 | K7: =IF($A7="","",INDEX([1]Clasif_Pron!$G:$G,((ROW()-4)*12+3))) -> Suiza | L7: =IF($A7="","",INDEX([1]Clasif_Pron!$L:$L,((ROW()-4)*12+3))) -> 3 | M7: =IF($A7="","",INDEX([1]Clasif_Pron!$I:$I,((ROW()-4)*12+3))) -> Bosnia y Herzegovina | N7: =IF($A7="","",INDEX([1]Clasif_Pron!$M:$M,((ROW()-4)*12+3))) -> 5 | O7: =IF($A7="","",INDEX([1]Clasif_Pron!$N:$N,((ROW()-4)*12+3))) -> 11 | P7: =IF($A7="","",INDEX([1]Clasif_Pron!$E:$E,((ROW()-4)*12+4))) -> Brasil | Q7: =IF($A7="","",INDEX([1]Clasif_Pron!$K:$K,((ROW()-4)*12+4))) -> 7 | R7: =IF($A7="","",INDEX([1]Clasif_Pron!$G:$G,((ROW()-4)*12+4))) -> Marruecos | S7: =IF($A7="","",INDEX([1]Clasif_Pron!$L:$L,((ROW()-4)*12+4))) -> 6 | T7: =IF($A7="","",INDEX([1]Clasif_Pron!$I:$I,((ROW()-4)*12+4))) -> Escocia | U7: =IF($A7="","",INDEX([1]Clasif_Pron!$M:$M,((ROW()-4)*12+4))) -> 0 | V7: =IF($A7="","",INDEX([1]Clasif_Pron!$N:$N,((ROW()-4)*12+4))) -> 13 | W7: =IF($A7="","",INDEX([1]Clasif_Pron!$E:$E,((ROW()-4)*12+5))) -> Estados Unidos | X7: =IF($A7="","",INDEX([1]Clasif_Pron!$K:$K,((ROW()-4)*12+5))) -> 7 | Y7: =IF($A7="","",INDEX([1]Clasif_Pron!$G:$G,((ROW()-4)*12+5))) -> Türkiye | Z7: =IF($A7="","",INDEX([1]Clasif_Pron!$L:$L,((ROW()-4)*12+5))) -> 0 | AA7: =IF($A7="","",INDEX([1]Clasif_Pron!$I:$I,((ROW()-4)*12+5))) -> Paraguay | AB7: =IF($A7="","",INDEX([1]Clasif_Pron!$M:$M,((ROW()-4)*12+5))) -> 5 | AC7: =IF($A7="","",INDEX([1]Clasif_Pron!$N:$N,((ROW()-4)*12+5))) -> 12 | AD7: =IF($A7="","",INDEX([1]Clasif_Pron!$E:$E,((ROW()-4)*12+6))) -> Alemania | AE7: =IF($A7="","",INDEX([1]Clasif_Pron!$K:$K,((ROW()-4)*12+6))) -> 7 | AF7: =IF($A7="","",INDEX([1]Clasif_Pron!$G:$G,((ROW()-4)*12+6))) -> Ecuador | AG7: =IF($A7="","",INDEX([1]Clasif_Pron!$L:$L,((ROW()-4)*12+6))) -> 3 | AH7: =IF($A7="","",INDEX([1]Clasif_Pron!$I:$I,((ROW()-4)*12+6))) -> Costa de Marfil | AI7: =IF($A7="","",INDEX([1]Clasif_Pron!$M:$M,((ROW()-4)*12+6))) -> 3 | AJ7: =IF($A7="","",INDEX([1]Clasif_Pron!$N:$N,((ROW()-4)*12+6))) -> 13 | AK7: =IF($A7="","",INDEX([1]Clasif_Pron!$E:$E,((ROW()-4)*12+7))) -> Japón | AL7: =IF($A7="","",INDEX([1]Clasif_Pron!$K:$K,((ROW()-4)*12+7))) -> 3 | AM7: =IF($A7="","",INDEX([1]Clasif_Pron!$G:$G,((ROW()-4)*12+7))) -> Países Bajos | AN7: =IF($A7="","",INDEX([1]Clasif_Pron!$L:$L,((ROW()-4)*12+7))) -> 3 | AO7: =IF($A7="","",INDEX([1]Clasif_Pron!$I:$I,((ROW()-4)*12+7))) -> Suecia | AP7: =IF($A7="","",INDEX([1]Clasif_Pron!$M:$M,((ROW()-4)*12+7))) -> 5 | AQ7: =IF($A7="","",INDEX([1]Clasif_Pron!$N:$N,((ROW()-4)*12+7))) -> 11 | AR7: =IF($A7="","",INDEX([1]Clasif_Pron!$E:$E,((ROW()-4)*12+8))) -> Bélgica | AS7: =IF($A7="","",INDEX([1]Clasif_Pron!$K:$K,((ROW()-4)*12+8))) -> 7 | AT7: =IF($A7="","",INDEX([1]Clasif_Pron!$G:$G,((ROW()-4)*12+8))) -> Egipto | AU7: =IF($A7="","",INDEX([1]Clasif_Pron!$L:$L,((ROW()-4)*12+8))) -> 6 | AV7: =IF($A7="","",INDEX([1]Clasif_Pron!$I:$I,((ROW()-4)*12+8))) -> Irán | AW7: =IF($A7="","",INDEX([1]Clasif_Pron!$M:$M,((ROW()-4)*12+8))) -> 5 | AX7: =IF($A7="","",INDEX([1]Clasif_Pron!$N:$N,((ROW()-4)*12+8))) -> 18 | AY7: =IF($A7="","",INDEX([1]Clasif_Pron!$E:$E,((ROW()-4)*12+9))) -> España | AZ7: =IF($A7="","",INDEX([1]Clasif_Pron!$K:$K,((ROW()-4)*12+9))) -> 7 | BA7: =IF($A7="","",INDEX([1]Clasif_Pron!$G:$G,((ROW()-4)*12+9))) -> Arabia Saudita | BB7: =IF($A7="","",INDEX([1]Clasif_Pron!$L:$L,((ROW()-4)*12+9))) -> 0 | BC7: =IF($A7="","",INDEX([1]Clasif_Pron!$I:$I,((ROW()-4)*12+9))) -> Uruguay | BD7: =IF($A7="","",INDEX([1]Clasif_Pron!$M:$M,((ROW()-4)*12+9))) -> 0 | BE7: =IF($A7="","",INDEX([1]Clasif_Pron!$N:$N,((ROW()-4)*12+9))) -> 7 | BF7: =IF($A7="","",INDEX([1]Clasif_Pron!$E:$E,((ROW()-4)*12+10))) -> Francia | BG7: =IF($A7="","",INDEX([1]Clasif_Pron!$K:$K,((ROW()-4)*12+10))) -> 7 | BH7: =IF($A7="","",INDEX([1]Clasif_Pron!$G:$G,((ROW()-4)*12+10))) -> Noruega | BI7: =IF($A7="","",INDEX([1]Clasif_Pron!$L:$L,((ROW()-4)*12+10))) -> 6 | BJ7: =IF($A7="","",INDEX([1]Clasif_Pron!$I:$I,((ROW()-4)*12+10))) -> Senegal | BK7: =IF($A7="","",INDEX([1]Clasif_Pron!$M:$M,((ROW()-4)*12+10))) -> 5 | BL7: =IF($A7="","",INDEX([1]Clasif_Pron!$N:$N,((ROW()-4)*12+10))) -> 18 | BM7: =IF($A7="","",INDEX([1]Clasif_Pron!$E:$E,((ROW()-4)*12+11))) -> Argentina | BN7: =IF($A7="","",INDEX([1]Clasif_Pron!$K:$K,((ROW()-4)*12+11))) -> 7 | BO7: =IF($A7="","",INDEX([1]Clasif_Pron!$G:$G,((ROW()-4)*12+11))) -> Argelia | BP7: =IF($A7="","",INDEX([1]Clasif_Pron!$L:$L,((ROW()-4)*12+11))) -> 0 | BQ7: =IF($A7="","",INDEX([1]Clasif_Pron!$I:$I,((ROW()-4)*12+11))) -> Austria | BR7: =IF($A7="","",INDEX([1]Clasif_Pron!$M:$M,((ROW()-4)*12+11))) -> 3 | BS7: =IF($A7="","",INDEX([1]Clasif_Pron!$N:$N,((ROW()-4)*12+11))) -> 10 | BT7: =IF($A7="","",INDEX([1]Clasif_Pron!$E:$E,((ROW()-4)*12+12))) -> Colombia | BU7: =IF($A7="","",INDEX([1]Clasif_Pron!$K:$K,((ROW()-4)*12+12))) -> 7 | BV7: =IF($A7="","",INDEX([1]Clasif_Pron!$G:$G,((ROW()-4)*12+12))) -> Portugal | BW7: =IF($A7="","",INDEX([1]Clasif_Pron!$L:$L,((ROW()-4)*12+12))) -> 6 | BX7: =IF($A7="","",INDEX([1]Clasif_Pron!$I:$I,((ROW()-4)*12+12))) -> RD Congo | BY7: =IF($A7="","",INDEX([1]Clasif_Pron!$M:$M,((ROW()-4)*12+12))) -> 0 | BZ7: =IF($A7="","",INDEX([1]Clasif_Pron!$N:$N,((ROW()-4)*12+12))) -> 13 | CA7: =IF($A7="","",INDEX([1]Clasif_Pron!$E:$E,((ROW()-4)*12+13))) -> Inglaterra | CB7: =IF($A7="","",INDEX([1]Clasif_Pron!$K:$K,((ROW()-4)*12+13))) -> 7 | CC7: =IF($A7="","",INDEX([1]Clasif_Pron!$G:$G,((ROW()-4)*12+13))) -> Croacia | CD7: =IF($A7="","",INDEX([1]Clasif_Pron!$L:$L,((ROW()-4)*12+13))) -> 3 | CE7: =IF($A7="","",INDEX([1]Clasif_Pron!$I:$I,((ROW()-4)*12+13))) -> Panamá | CF7: =IF($A7="","",INDEX([1]Clasif_Pron!$M:$M,((ROW()-4)*12+13))) -> 0 | CG7: =IF($A7="","",INDEX([1]Clasif_Pron!$N:$N,((ROW()-4)*12+13))) -> 10 | CH7: =IF($A7="","",SUM(H7,O7,V7,AC7,AJ7,AQ7,AX7,BE7,BL7,BS7,BZ7,CG7)) -> 148
A8: =[1]Participantes!B6 -> Aneth | B8: =IF($A8="","",INDEX([1]Clasif_Pron!$E:$E,((ROW()-4)*12+2))) -> México | C8: =IF($A8="","",INDEX([1]Clasif_Pron!$K:$K,((ROW()-4)*12+2))) -> 7 | D8: =IF($A8="","",INDEX([1]Clasif_Pron!$G:$G,((ROW()-4)*12+2))) -> Chequia | E8: =IF($A8="","",INDEX([1]Clasif_Pron!$L:$L,((ROW()-4)*12+2))) -> 0 | F8: =IF($A8="","",INDEX([1]Clasif_Pron!$I:$I,((ROW()-4)*12+2))) -> Sudáfrica | G8: =IF($A8="","",INDEX([1]Clasif_Pron!$M:$M,((ROW()-4)*12+2))) -> 3 | H8: =IF($A8="","",INDEX([1]Clasif_Pron!$N:$N,((ROW()-4)*12+2))) -> 10 | I8: =IF($A8="","",INDEX([1]Clasif_Pron!$E:$E,((ROW()-4)*12+3))) -> Canadá | J8: =IF($A8="","",INDEX([1]Clasif_Pron!$K:$K,((ROW()-4)*12+3))) -> 3 | K8: =IF($A8="","",INDEX([1]Clasif_Pron!$G:$G,((ROW()-4)*12+3))) -> Qatar | L8: =IF($A8="","",INDEX([1]Clasif_Pron!$L:$L,((ROW()-4)*12+3))) -> 0 | M8: =IF($A8="","",INDEX([1]Clasif_Pron!$I:$I,((ROW()-4)*12+3))) -> Suiza | N8: =IF($A8="","",INDEX([1]Clasif_Pron!$M:$M,((ROW()-4)*12+3))) -> 3 | O8: =IF($A8="","",INDEX([1]Clasif_Pron!$N:$N,((ROW()-4)*12+3))) -> 6 | P8: =IF($A8="","",INDEX([1]Clasif_Pron!$E:$E,((ROW()-4)*12+4))) -> Brasil | Q8: =IF($A8="","",INDEX([1]Clasif_Pron!$K:$K,((ROW()-4)*12+4))) -> 7 | R8: =IF($A8="","",INDEX([1]Clasif_Pron!$G:$G,((ROW()-4)*12+4))) -> Marruecos | S8: =IF($A8="","",INDEX([1]Clasif_Pron!$L:$L,((ROW()-4)*12+4))) -> 6 | T8: =IF($A8="","",INDEX([1]Clasif_Pron!$I:$I,((ROW()-4)*12+4))) -> Escocia | U8: =IF($A8="","",INDEX([1]Clasif_Pron!$M:$M,((ROW()-4)*12+4))) -> 0 | V8: =IF($A8="","",INDEX([1]Clasif_Pron!$N:$N,((ROW()-4)*12+4))) -> 13 | W8: =IF($A8="","",INDEX([1]Clasif_Pron!$E:$E,((ROW()-4)*12+5))) -> Estados Unidos | X8: =IF($A8="","",INDEX([1]Clasif_Pron!$K:$K,((ROW()-4)*12+5))) -> 7 | Y8: =IF($A8="","",INDEX([1]Clasif_Pron!$G:$G,((ROW()-4)*12+5))) -> Türkiye | Z8: =IF($A8="","",INDEX([1]Clasif_Pron!$L:$L,((ROW()-4)*12+5))) -> 0 | AA8: =IF($A8="","",INDEX([1]Clasif_Pron!$I:$I,((ROW()-4)*12+5))) -> Paraguay | AB8: =IF($A8="","",INDEX([1]Clasif_Pron!$M:$M,((ROW()-4)*12+5))) -> 5 | AC8: =IF($A8="","",INDEX([1]Clasif_Pron!$N:$N,((ROW()-4)*12+5))) -> 12 | AD8: =IF($A8="","",INDEX([1]Clasif_Pron!$E:$E,((ROW()-4)*12+6))) -> Ecuador | AE8: =IF($A8="","",INDEX([1]Clasif_Pron!$K:$K,((ROW()-4)*12+6))) -> 3 | AF8: =IF($A8="","",INDEX([1]Clasif_Pron!$G:$G,((ROW()-4)*12+6))) -> Alemania | AG8: =IF($A8="","",INDEX([1]Clasif_Pron!$L:$L,((ROW()-4)*12+6))) -> 3 | AH8: =IF($A8="","",INDEX([1]Clasif_Pron!$I:$I,((ROW()-4)*12+6))) -> Curazao | AI8: =IF($A8="","",INDEX([1]Clasif_Pron!$M:$M,((ROW()-4)*12+6))) -> 0 | AJ8: =IF($A8="","",INDEX([1]Clasif_Pron!$N:$N,((ROW()-4)*12+6))) -> 6 | AK8: =IF($A8="","",INDEX([1]Clasif_Pron!$E:$E,((ROW()-4)*12+7))) -> Países Bajos | AL8: =IF($A8="","",INDEX([1]Clasif_Pron!$K:$K,((ROW()-4)*12+7))) -> 7 | AM8: =IF($A8="","",INDEX([1]Clasif_Pron!$G:$G,((ROW()-4)*12+7))) -> Japón | AN8: =IF($A8="","",INDEX([1]Clasif_Pron!$L:$L,((ROW()-4)*12+7))) -> 6 | AO8: =IF($A8="","",INDEX([1]Clasif_Pron!$I:$I,((ROW()-4)*12+7))) -> Suecia | AP8: =IF($A8="","",INDEX([1]Clasif_Pron!$M:$M,((ROW()-4)*12+7))) -> 5 | AQ8: =IF($A8="","",INDEX([1]Clasif_Pron!$N:$N,((ROW()-4)*12+7))) -> 18 | AR8: =IF($A8="","",INDEX([1]Clasif_Pron!$E:$E,((ROW()-4)*12+8))) -> Bélgica | AS8: =IF($A8="","",INDEX([1]Clasif_Pron!$K:$K,((ROW()-4)*12+8))) -> 7 | AT8: =IF($A8="","",INDEX([1]Clasif_Pron!$G:$G,((ROW()-4)*12+8))) -> Irán | AU8: =IF($A8="","",INDEX([1]Clasif_Pron!$L:$L,((ROW()-4)*12+8))) -> 3 | AV8: =IF($A8="","",INDEX([1]Clasif_Pron!$I:$I,((ROW()-4)*12+8))) -> Egipto | AW8: =IF($A8="","",INDEX([1]Clasif_Pron!$M:$M,((ROW()-4)*12+8))) -> 3 | AX8: =IF($A8="","",INDEX([1]Clasif_Pron!$N:$N,((ROW()-4)*12+8))) -> 13 | AY8: =IF($A8="","",INDEX([1]Clasif_Pron!$E:$E,((ROW()-4)*12+9))) -> España | AZ8: =IF($A8="","",INDEX([1]Clasif_Pron!$K:$K,((ROW()-4)*12+9))) -> 7 | BA8: =IF($A8="","",INDEX([1]Clasif_Pron!$G:$G,((ROW()-4)*12+9))) -> Uruguay | BB8: =IF($A8="","",INDEX([1]Clasif_Pron!$L:$L,((ROW()-4)*12+9))) -> 0 | BC8: =IF($A8="","",INDEX([1]Clasif_Pron!$I:$I,((ROW()-4)*12+9))) -> Arabia Saudita | BD8: =IF($A8="","",INDEX([1]Clasif_Pron!$M:$M,((ROW()-4)*12+9))) -> 0 | BE8: =IF($A8="","",INDEX([1]Clasif_Pron!$N:$N,((ROW()-4)*12+9))) -> 7 | BF8: =IF($A8="","",INDEX([1]Clasif_Pron!$E:$E,((ROW()-4)*12+10))) -> Francia | BG8: =IF($A8="","",INDEX([1]Clasif_Pron!$K:$K,((ROW()-4)*12+10))) -> 7 | BH8: =IF($A8="","",INDEX([1]Clasif_Pron!$G:$G,((ROW()-4)*12+10))) -> Senegal | BI8: =IF($A8="","",INDEX([1]Clasif_Pron!$L:$L,((ROW()-4)*12+10))) -> 3 | BJ8: =IF($A8="","",INDEX([1]Clasif_Pron!$I:$I,((ROW()-4)*12+10))) -> Noruega | BK8: =IF($A8="","",INDEX([1]Clasif_Pron!$M:$M,((ROW()-4)*12+10))) -> 3 | BL8: =IF($A8="","",INDEX([1]Clasif_Pron!$N:$N,((ROW()-4)*12+10))) -> 13 | BM8: =IF($A8="","",INDEX([1]Clasif_Pron!$E:$E,((ROW()-4)*12+11))) -> Argentina | BN8: =IF($A8="","",INDEX([1]Clasif_Pron!$K:$K,((ROW()-4)*12+11))) -> 7 | BO8: =IF($A8="","",INDEX([1]Clasif_Pron!$G:$G,((ROW()-4)*12+11))) -> Austria | BP8: =IF($A8="","",INDEX([1]Clasif_Pron!$L:$L,((ROW()-4)*12+11))) -> 6 | BQ8: =IF($A8="","",INDEX([1]Clasif_Pron!$I:$I,((ROW()-4)*12+11))) -> Argelia | BR8: =IF($A8="","",INDEX([1]Clasif_Pron!$M:$M,((ROW()-4)*12+11))) -> 0 | BS8: =IF($A8="","",INDEX([1]Clasif_Pron!$N:$N,((ROW()-4)*12+11))) -> 13 | BT8: =IF($A8="","",INDEX([1]Clasif_Pron!$E:$E,((ROW()-4)*12+12))) -> Portugal | BU8: =IF($A8="","",INDEX([1]Clasif_Pron!$K:$K,((ROW()-4)*12+12))) -> 3 | BV8: =IF($A8="","",INDEX([1]Clasif_Pron!$G:$G,((ROW()-4)*12+12))) -> Colombia | BW8: =IF($A8="","",INDEX([1]Clasif_Pron!$L:$L,((ROW()-4)*12+12))) -> 3 | BX8: =IF($A8="","",INDEX([1]Clasif_Pron!$I:$I,((ROW()-4)*12+12))) -> Uzbekistán | BY8: =IF($A8="","",INDEX([1]Clasif_Pron!$M:$M,((ROW()-4)*12+12))) -> 0 | BZ8: =IF($A8="","",INDEX([1]Clasif_Pron!$N:$N,((ROW()-4)*12+12))) -> 6 | CA8: =IF($A8="","",INDEX([1]Clasif_Pron!$E:$E,((ROW()-4)*12+13))) -> Inglaterra | CB8: =IF($A8="","",INDEX([1]Clasif_Pron!$K:$K,((ROW()-4)*12+13))) -> 7 | CC8: =IF($A8="","",INDEX([1]Clasif_Pron!$G:$G,((ROW()-4)*12+13))) -> Croacia | CD8: =IF($A8="","",INDEX([1]Clasif_Pron!$L:$L,((ROW()-4)*12+13))) -> 3 | CE8: =IF($A8="","",INDEX([1]Clasif_Pron!$I:$I,((ROW()-4)*12+13))) -> Panamá | CF8: =IF($A8="","",INDEX([1]Clasif_Pron!$M:$M,((ROW()-4)*12+13))) -> 0 | CG8: =IF($A8="","",INDEX([1]Clasif_Pron!$N:$N,((ROW()-4)*12+13))) -> 10 | CH8: =IF($A8="","",SUM(H8,O8,V8,AC8,AJ8,AQ8,AX8,BE8,BL8,BS8,BZ8,CG8)) -> 127
