Workbook

Sheet Portada
A1: Mundial FIFA 2026 - Calendario y clasificación
A3: Uso
A4: 1 | B4: Escribe los goles en la hoja Partidos, columnas H e I. Las tablas se recalculan automáticamente.
A5: 2 | B5: Las posiciones de grupo están identificadas como A1, A2, A3, A4, etc.
A6: 3 | B6: Los cruces de eliminatoria usan placeholders oficiales: 1A, 2B, 3C/D/E, W74, etc.
A7: 4 | B7: La hoja Clasificacion calcula puntos, goles y posición básica; al inicio conserva el orden A1-A4 por grupo.
A8: 5 | B8: La columna Desempate manual permite resolver empates complejos de FIFA: mayor número = mejor desempate.
A9: 6 | B9: Horarios en Eastern Time (ET), como en el calendario de FIFA/CBS.
A11: Contenido
A12: Equipos_Grupos | B12: Listado de grupos, posiciones y códigos.
A13: Partidos | B13: Los 104 partidos, con columnas para ingresar resultados.
A14: Clasificacion | B14: Tabla automática por grupo.
A15: Mejores_Terceros | B15: Ranking automático de los terceros lugares.
A16: Llaves | B16: Resumen del cuadro eliminatorio con placeholders.
A17: Fuentes | B17: URLs usadas para armar el archivo.
A18: Notas | B18: El calendario está sujeto a cambios por FIFA.

Sheet Equipos_Grupos
A1: Grupo | B1: Posición | C1: Código | D1: Equipo
A2: A | B2: A1 | C2: MEX | D2: México
A3: A | B3: A2 | C3: RSA | D3: Sudáfrica
A4: A | B4: A3 | C4: KOR | D4: Corea República
A5: A | B5: A4 | C5: CZE | D5: Chequia
A6: B | B6: B1 | C6: CAN | D6: Canadá
A7: B | B7: B2 | C7: BIH | D7: Bosnia y Herzegovina
A8: B | B8: B3 | C8: QAT | D8: Qatar
A9: B | B9: B4 | C9: SUI | D9: Suiza
A10: C | B10: C1 | C10: BRA | D10: Brasil
A11: C | B11: C2 | C11: MAR | D11: Marruecos
A12: C | B12: C3 | C12: HAI | D12: Haití
... A49: L | B49: L4 | C49: PAN | D49: Panamá

Sheet Puntajes
A1: Número | B1: Posición. | C1: Nombre | D1: Puntaje | F1: =NOW() -> 46184.736
A2: =Participantes!A2 -> 1 | B2: =IF(ROW()=2,1,IF(D2=D1,B1,B1+1)) -> 1 | C2: =Participantes!B2 -> Alberto | D2: =Grupo!BS4 -> 0
A3: =Participantes!A3 -> 2 | B3: =IF(ROW()=2,1,IF(D3=D2,B2,B2+1)) -> 1 | C3: =Participantes!B3 -> Alexander | D3: =Grupo!BS5 -> 0
A4: =Participantes!A4 -> 3 | B4: =IF(ROW()=2,1,IF(D4=D3,B3,B3+1)) -> 1 | C4: =Participantes!B4 -> Alfredo 1 | D4: =Grupo!BS6 -> 0
A5: =Participantes!A5 -> 4 | B5: =IF(ROW()=2,1,IF(D5=D4,B4,B4+1)) -> 1 | C5: =Participantes!B5 -> Alfredo 2 | D5: =Grupo!BS7 -> 0
A6: =Participantes!A6 -> 5 | B6: =IF(ROW()=2,1,IF(D6=D5,B5,B5+1)) -> 1 | C6: =Participantes!B6 -> Aneth | D6: =Grupo!BS8 -> 0
A7: =Participantes!A7 -> 6 | B7: =IF(ROW()=2,1,IF(D7=D6,B6,B6+1)) -> 1 | C7: =Participantes!B7 -> Antonio | D7: =Grupo!BS9 -> 0
A8: =Participantes!A8 -> 7 | B8: =IF(ROW()=2,1,IF(D8=D7,B7,B7+1)) -> 1 | C8: =Participantes!B8 -> Carlos | D8: =Grupo!BS10 -> 0
A9: =Participantes!A9 -> 8 | B9: =IF(ROW()=2,1,IF(D9=D8,B8,B8+1)) -> 1 | C9: =Participantes!B9 -> Castillo L. | D9: =Grupo!BS11 -> 0 | G9: =Partidos!F2 -> México | H9: =Partidos!G2 -> Sudáfrica | J9: =Partidos!C2 -> 15:00
A10: =Participantes!A10 -> 9 | B10: =IF(ROW()=2,1,IF(D10=D9,B9,B9+1)) -> 1 | C10: =Participantes!B10 -> Christofer | D10: =Grupo!BS12 -> 0
A11: =Participantes!A11 -> 10 | B11: =IF(ROW()=2,1,IF(D11=D10,B10,B10+1)) -> 1 | C11: =Participantes!B11 -> Cynthia | D11: =Grupo!BS13 -> 0
A12: =Participantes!A12 -> 11 | B12: =IF(ROW()=2,1,IF(D12=D11,B11,B11+1)) -> 1 | C12: =Participantes!B12 -> Edward | D12: =Grupo!BS14 -> 0 | G12: =Partidos!F3 -> Corea República | H12: =Partidos!G3 -> Chequia | J12: =Partidos!C3 -> 22:00
A13: =Participantes!A13 -> 12 | B13: =IF(ROW()=2,1,IF(D13=D12,B12,B12+1)) -> 1 | C13: =Participantes!B13 -> Espinosa L. | D13: =Grupo!BS15 -> 0
A14: =Participantes!A14 -> 13 | B14: =IF(ROW()=2,1,IF(D14=D13,B13,B13+1)) -> 1 | C14: =Participantes!B14 -> Frida | D14: =Grupo!BS16 -> 0
A15: =Participantes!A15 -> 14 | B15: =IF(ROW()=2,1,IF(D15=D14,B14,B14+1)) -> 1 | C15: =Participantes!B15 -> Isabel 1 | D15: =Grupo!BS17 -> 0
A16: =Participantes!A16 -> 15 | B16: =IF(ROW()=2,1,IF(D16=D15,B15,B15+1)) -> 1 | C16: =Participantes!B16 -> Isabel 2 | D16: =Grupo!BS18 -> 0
A17: =Participantes!A17 -> 16 | B17: =IF(ROW()=2,1,IF(D17=D16,B16,B16+1)) -> 1 | C17: =Participantes!B17 -> Javier | D17: =Grupo!BS19 -> 0
A18: =Participantes!A18 -> 17 | B18: =IF(ROW()=2,1,IF(D18=D17,B17,B17+1)) -> 1 | C18: =Participantes!B18 -> Jose C 1 | D18: =Grupo!BS20 -> 0
A19: =Participantes!A19 -> 18 | B19: =IF(ROW()=2,1,IF(D19=D18,B18,B18+1)) -> 1 | C19: =Participantes!B19 -> Jose C 2 | D19: =Grupo!BS21 -> 0
A20: =Participantes!A20 -> 19 | B20: =IF(ROW()=2,1,IF(D20=D19,B19,B19+1)) -> 1 | C20: =Participantes!B20 -> Jose C Ahiza | D20: =Grupo!BS22 -> 0
A21: =Participantes!A21 -> 20 | B21: =IF(ROW()=2,1,IF(D21=D20,B20,B20+1)) -> 1 | C21: =Participantes!B21 -> Jose C Ana | D21: =Grupo!BS23 -> 0
A22: =Participantes!A22 -> 21 | B22: =IF(ROW()=2,1,IF(D22=D21,B21,B21+1)) -> 1 | C22: =Participantes!B22 -> Jose C Judith | D22: =Grupo!BS24 -> 0
A23: =Participantes!A23 -> 22 | B23: =IF(ROW()=2,1,IF(D23=D22,B22,B22+1)) -> 1 | C23: =Participantes!B23 -> José de León | D23: =Grupo!BS25 -> 0
A24: =Participantes!A24 -> 23 | B24: =IF(ROW()=2,1,IF(D24=D23,B23,B23+1)) -> 1 | C24: =Participantes!B24 -> Jovanna | D24: =Grupo!BS26 -> 0
... A49: =Participantes!A49 -> 48 | B49: =IF(ROW()=2,1,IF(D49=D48,B48,B48+1)) -> 1 | C49: =Participantes!B49 -> Waldo | D49: =Grupo!BS51 -> 0

Sheet Participantes
B1: Nombre | C1: México | D1: Sudáfrica | E1: Corea | F1: Chequia | G1: Canadá | H1: Bosnia | I1: Estados Unidos | J1: Paraguay | K1: Haití | L1: Escocia | M1: Australia | N1: Türkiye | O1: Brasil | P1: Marruecos | Q1: Qatar | R1: Suiza | S1: Costa de Marfil | T1: Ecuador | U1: Alemania | V1: Curazao | W1: Países Bajos | X1: Japón | Y1: Suecia | Z1: Túnez | AA1: Arabia Saudita | AB1: Uruguay | AC1: España | AD1: Cabo Verde | AE1: Irán | AF1: Nueva Zelanda | AG1: Bélgica | AH1: Egipto | AI1: Francia | AJ1: Senegal | AK1: Irak | AL1: Noruega | AM1: Argentina | AN1: Argelia | AO1: Austria | AP1: Jordania | AQ1: Ghana | AR1: Panamá | AS1: Inglaterra | AT1: Croacia | AU1: Portugal | AV1: RD Congo | AW1: Uzbekistán | AX1: Colombia | AY1: Chequia | AZ1: Sudáfrica | BA1: Suiza | BB1: Bosnia | BC1: Canadá | BD1: Qatar | BE1: México | BF1: Corea República | BG1: Brasil | BH1: Haití | BI1: Escocia | BJ1: Marruecos | BK1: Türkiye | BL1: Paraguay | BM1: Estados Unidos | BN1: Australia | BO1: Alemania | BP1: Costa de Marfil | BQ1: Ecuador | BR1: Curazao | BS1: Países Bajos | BT1: Suecia | BU1: Túnez | BV1: Japón | BW1: Uruguay | BX1: Cabo Verde | BY1: España | BZ1: Arabia Saudita | CA1: Bélgica | CB1: Irán | CC1: Nueva Zelanda | CD1: Egipto | CE1: Noruega | CF1: Senegal | CG1: Francia | CH1: Irak | CI1: Argentina | CJ1: Austria | CK1: Jordania | CL1: Argelia | CM1: Inglaterra | CN1: Ghana | CO1: Panamá | CP1: Croacia | CQ1: Portugal | CR1: Uzbekistán | CS1: Colombia | CT1: RD Congo | CU1: Escocia | CV1: Brasil | CW1: Marruecos | CX1: Haití | CY1: Suiza | CZ1: Canadá | DA1: Bosnia | DB1: Qatar | DC1: Chequia | DD1: México | DE1: Sudáfrica | DF1: Corea República | DG1: Curazao | DH1: Costa de Marfil | DI1: Ecuador | DJ1: Alemania | DK1: Japón | DL1: Suecia | DM1: Túnez | DN1: Países Bajos | DO1: Türkiye | DP1: Estados Unidos | DQ1: Paraguay | DR1: Australia | DS1: Noruega | DT1: Francia | DU1: Senegal | DV1: Irak | DW1: Egipto | DX1: Irán | DY1: Nueva Zelanda | DZ1: Bélgica | EA1: Cabo Verde | EB1: Arabia Saudita | EC1: Uruguay | ED1: España | EE1: Panamá | EF1: Inglaterra | EG1: Croacia | EH1: Ghana | EI1: Argelia | EJ1: Austria | EK1: Jordania | EL1: Argentina | EM1: Colombia | EN1: Portugal | EO1: RD Congo | EP1: Uzbekistán
A2: 1 | B2: Alberto | C2: 1 | D2: 1 | E2: 2 | F2: 0 | G2: 2 | H2: 1 | I2: 1 | J2: 3 | K2: 0 | L2: 2 | M2: 0 | N2: 1 | O2: 1 | P2: 2 | Q2: 0 | R2: 2 | S2: 1 | T2: 2 | U2: 5 | V2: 0 | W2: 3 | X2: 0 | Y2: 1 | Z2: 1 | AA2: 0 | AB2: 2 | AC2: 6 | AD2: 0 | AE2: 0 | AF2: 0 | AG2: 2 | AH2: 0 | AI2: 4 | AJ2: 0 | AK2: 0 | AL2: 4 | AM2: 4 | AN2: 0 | AO2: 1 | AP2: 0 | AQ2: 2 | AR2: 1 | AS2: 4 | AT2: 2 | AU2: 5 | AV2: 0 | AW2: 0 | AX2: 3 | AY2: 0 | AZ2: 1 | BA2: 1 | BB2: 0 | BC2: 3 | BD2: 1 | BE2: 1 | BF2: 0 | BG2: 5 | BH2: 0 | BI2: 0 | BJ2: 3 | BK2: 2 | BL2: 3 | BM2: 2 | BN2: 1 | BO2: 4 | BP2: 0 | BQ2: 4 | BR2: 0 | BS2: 3 | BT2: 1 | BU2: 0 | BV2: 2 | BW2: 4 | BX2: 0 | BY2: 5 | BZ2: 0 | CA2: 3 | CB2: 0 | CC2: 1 | CD2: 2 | CE2: 2 | CF2: 2 | CG2: 5 | CH2: 0 | CI2: 3 | CJ2: 0 | CK2: 0 | CL2: 0 | CM2: 5 | CN2: 0 | CO2: 0 | CP2: 4 | CQ2: 5 | CR2: 0 | CS2: 2 | CT2: 1 | CU2: 0 | CV2: 4 | CW2: 4 | CX2: 0 | CY2: 3 | CZ2: 2 | DA2: 1 | DB2: 1 | DC2: 1 | DD2: 3 | DE2: 0 | DF2: 1 | DG2: 0 | DH2: 2 | DI2: 2 | DJ2: 4 | DK2: 2 | DL2: 2 | DM2: 0 | DN2: 3 | DO2: 1 | DP2: 0 | DQ2: 1 | DR2: 0 | DS2: 1 | DT2: 3 | DU2: 2 | DV2: 0 | DW2: 2 | DX2: 1 | DY2: 0 | DZ2: 4 | EA2: 0 | EB2: 1 | EC2: 1 | ED2: 2 | EE2: 0 | EF2: 6 | EG2: 3 | EH2: 0 | EI2: 0 | EJ2: 0 | EK2: 0 | EL2: 4 | EM2: 0 | EN2: 2 | EO2: 1 | EP2: 1
A3: 2 | B3: Alexander | C3: 2 | D3: 0 | E3: 1 | F3: 1 | G3: 1 | H3: 1 | I3: 2 | J3: 0 | K3: 0 | L3: 2 | M3: 1 | N3: 1 | O3: 2 | P3: 0 | Q3: 0 | R3: 1 | S3: 1 | T3: 1 | U3: 3 | V3: 0 | W3: 2 | X3: 1 | Y3: 1 | Z3: 0 | AA3: 1 | AB3: 2 | AC3: 3 | AD3: 0 | AE3: 0 | AF3: 0 | AG3: 2 | AH3: 0 | AI3: 2 | AJ3: 1 | AK3: 0 | AL3: 2 | AM3: 2 | AN3: 0 | AO3: 1 | AP3: 0 | AQ3: 1 | AR3: 2 | AS3: 1 | AT3: 0 | AU3: 2 | AV3: 0 | AW3: 1 | AX3: 1 | AY3: 1 | AZ3: 0 | BA3: 1 | BB3: 1 | BC3: 2 | BD3: 0 | BE3: 2 | BF3: 1 | BG3: 3 | BH3: 1 | BI3: 0 | BJ3: 1 | BK3: 0 | BL3: 1 | BM3: 2 | BN3: 1 | BO3: 2 | BP3: 1 | BQ3: 2 | BR3: 0 | BS3: 2 | BT3: 0 | BU3: 1 | BV3: 1 | BW3: 2 | BX3: 0 | BY3: 2 | BZ3: 0 | CA3: 3 | CB3: 1 | CC3: 0 | CD3: 2 | CE3: 1 | CF3: 2 | CG3: 3 | CH3: 0 | CI3: 3 | CJ3: 1 | CK3: 1 | CL3: 2 | CM3: 2 | CN3: 0 | CO3: 1 | CP3: 1 | CQ3: 3 | CR3: 0 | CS3: 2 | CT3: 1 | CU3: 1 | CV3: 2 | CW3: 2 | CX3: 0 | CY3: 0 | CZ3: 1 | DB3: 1 | DC3: 0 | DD3: 1 | DE3: 1 | DF3: 2 | DG3: 1 | DH3: 2 | DI3: 0 | DJ3: 2 | DK3: 2 | DL3: 1 | DM3: 1 | DN3: 3 | DO3: 1 | DP3: 1 | DQ3: 3 | DR3: 0 | DS3: 0 | DT3: 2 | DU3: 2 | DV3: 0 | DW3: 1 | DX3: 1 | DY3: 0 | DZ3: 2 | EA3: 0 | EB3: 2 | EC3: 1 | ED3: 2 | EE3: 1 | EF3: 2 | EG3: 2 | EH3: 0 | EJ3: 1 | EK3: 1 | EL3: 0 | EM3: 2 | EN3: 1 | EO3: 2 | EP3: 1
A4: 3 | B4: Alfredo 1 | C4: 2 | D4: 1 | E4: 1 | F4: 1 | G4: 1 | H4: 0 | I4: 2 | J4: 1 | K4: 1 | L4: 1 | M4: 1 | N4: 2 | O4: 2 | P4: 0 | Q4: 0 | R4: 2 | S4: 1 | T4: 1 | U4: 4 | V4: 0 | W4: 2 | X4: 1 | Y4: 2 | Z4: 0 | AA4: 0 | AB4: 1 | AC4: 2 | AD4: 0 | AE4: 1 | AF4: 0 | AG4: 2 | AH4: 1 | AI4: 3 | AJ4: 1 | AK4: 0 | AL4: 3 | AM4: 2 | AN4: 0 | AO4: 2 | AP4: 0 | AQ4: 1 | AR4: 1 | AS4: 2 | AT4: 1 | AU4: 3 | AV4: 0 | AW4: 0 | AX4: 2 | AY4: 2 | AZ4: 0 | BA4: 2 | BB4: 1 | BC4: 1 | BD4: 0 | BE4: 2 | BF4: 1 | BG4: 3 | BH4: 0 | BI4: 1 | BJ4: 2 | BK4: 2 | BL4: 0 | BM4: 2 | BN4: 0 | BO4: 3 | BP4: 1 | BQ4: 3 | BR4: 0 | BS4: 2 | BT4: 1 | BU4: 0 | BV4: 2 | BW4: 2 | BX4: 1 | BY4: 3 | BZ4: 1 | CA4: 3 | CB4: 0 | CC4: 0 | CD4: 2 | CE4: 2 | CF4: 1 | CG4: 3 | CH4: 0 | CI4: 2 | CJ4: 1 | CK4: 0 | CL4: 1 | CM4: 3 | CN4: 1 | CO4: 1 | CP4: 2 | CQ4: 3 | CR4: 0 | CS4: 2 | CT4: 0 | CU4: 1 | CV4: 3 | CW4: 2 | CX4: 1 | CY4: 2 | CZ4: 1 | DA4: 2 | DB4: 0 | DC4: 0 | DD4: 2 | DE4: 1 | DF4: 1 | DG4: 0 | DH4: 2 | DI4: 1 | DJ4: 3 | DK4: 2 | DL4: 2 | DM4: 0 | DN4: 3 | DO4: 2 | DP4: 1 | DQ4: 1 | DR4: 1 | DS4: 2 | DT4: 2 | DU4: 1 | DV4: 1 | DW4: 3 | DX4: 0 | DY4: 0 | DZ4: 3 | EA4: 0 | EB4: 1 | EC4: 1 | ED4: 2 | EE4: 0 | EF4: 3 | EG4: 2 | EH4: 0 | EI4: 1 | EJ4: 2 | EK4: 0 | EL4: 2 | EM4: 1 | EN4: 1 | EO4: 1 | EP4: 1
A5: 4 | B5: Alfredo 2 | C5: 2 | D5: 0 | E5: 0 | F5: 1 | G5: 2 | H5: 0 | I5: 2 | J5: 0 | K5: 0 | L5: 1 | M5: 0 | N5: 2 | O5: 2 | P5: 1 | Q5: 0 | R5: 2 | S5: 0 | T5: 1 | U5: 3 | V5: 0 | W5: 2 | X5: 2 | Y5: 2 | Z5: 1 | AA5: 1 | AB5: 1 | AC5: 3 | AD5: 0 | AE5: 0 | AF5: 0 | AG5: 3 | AH5: 1 | AI5: 3 | AJ5: 0 | AK5: 0 | AL5: 2 | AM5: 2 | AN5: 1 | AO5: 1 | AP5: 0 | AQ5: 1 | AR5: 2 | AS5: 1 | AT5: 1 | AU5: 2 | AV5: 0 | AW5: 0 | AX5: 3 | AY5: 2 | AZ5: 1 | BA5: 2 | BB5: 2 | BC5: 2 | BD5: 0 | BE5: 2 | BF5: 0 | BG5: 3 | BH5: 1 | BI5: 0 | BJ5: 2 | BK5: 2 | BL5: 1 | BM5: 3 | BN5: 0 | BO5: 4 | BP5: 1 | BQ5: 2 | BR5: 0 | BS5: 1 | BT5: 1 | BU5: 0 | BV5: 2 | BW5: 2 | BX5: 0 | BY5: 3 | BZ5: 1 | CA5: 3 | CB5: 0 | CC5: 0 | CD5: 3 | CE5: 4 | CF5: 1 | CG5: 3 | CH5: 0 | CI5: 2 | CJ5: 1 | CK5: 0 | CL5: 2 | CM5: 3 | CN5: 0 | CO5: 1 | CP5: 1 | CQ5: 3 | CR5: 0 | CS5: 3 | CT5: 0 | CU5: 0 | CV5: 3 | CW5: 2 | CX5: 0 | CY5: 1 | CZ5: 1 | DA5: 1 | DB5: 0 | DC5: 1 | DD5: 2 | DE5: 0 | DF5: 1 | DG5: 0 | DH5: 1 | DI5: 1 | DJ5: 2 | DK5: 2 | DL5: 2 | DM5: 0 | DN5: 2 | DO5: 1 | DP5: 1 | DQ5: 1 | DR5: 0 | DS5: 2 | DT5: 2 | DU5: 1 | DV5: 0 | DW5: 2 | DX5: 0 | DY5: 0 | DZ5: 4 | EA5: 0 | EB5: 2 | EC5: 1 | ED5: 3 | EE5: 1 | EF5: 4 | EG5: 2 | EH5: 1 | EI5: 1 | EJ5: 1 | EK5: 0 | EL5: 3 | EM5: 2 | EN5: 2 | EO5: 0 | EP5: 0
A6: 5 | B6: Aneth | C6: 2 | D6: 0 | E6: 1 | F6: 1 | G6: 2 | H6: 1 | I6: 2 | J6: 1 | K6: 2 | L6: 0 | M6: 1 | N6: 1 | O6: 2 | P6: 1 | Q6: 2 | R6: 0 | S6: 1 | T6: 1 | U6: 4 | V6: 0 | W6: 2 | X6: 1 | Y6: 1 | Z6: 0 | AA6: 3 | AB6: 0 | AC6: 3 | AD6: 0 | AE6: 2 | AF6: 0 | AG6: 2 | AH6: 1 | AI6: 2 | AJ6: 1 | AK6: 2 | AL6: 0 | AM6: 3 | AN6: 0 | AO6: 2 | AP6: 0 | AQ6: 1 | AR6: 1 | AS6: 2 | AT6: 1 | AU6: 3 | AV6: 0 | AW6: 2 | AX6: 0 | AY6: 2 | AZ6: 1 | BA6: 2 | BB6: 0 | BC6: 1 | BD6: 1 | BE6: 2 | BF6: 1
A7: 6 | B7: Antonio | C7: 2 | D7: 0 | E7: 1 | F7: 1 | G7: 3 | H7: 1 | I7: 2 | J7: 0 | K7: 0 | L7: 3 | M7: 1 | N7: 2 | O7: 2 | P7: 2 | Q7: 0 | R7: 2 | S7: 1 | T7: 1 | U7: 4 | V7: 0 | W7: 3 | X7: 0 | Y7: 2 | Z7: 1 | AA7: 0 | AB7: 1 | AC7: 3 | AD7: 0 | AE7: 0 | AF7: 2 | AG7: 3 | AH7: 1 | AI7: 4 | AJ7: 0 | AK7: 0 | AL7: 1 | AM7: 3 | AN7: 1 | AO7: 2 | AP7: 1 | AQ7: 0 | AR7: 1 | AS7: 3 | AT7: 2 | AU7: 4 | AV7: 0 | AW7: 0 | AX7: 4 | AY7: 0 | AZ7: 1 | BA7: 3 | BB7: 2 | BC7: 2 | BD7: 1 | BE7: 3 | BF7: 1
A8: 7 | B8: Carlos | C8: 2 | D8: 1 | E8: 1 | F8: 1 | G8: 2 | H8: 1 | I8: 2 | J8: 0 | K8: 0 | L8: 2 | M8: 1 | N8: 2 | O8: 2 | P8: 1 | Q8: 0 | R8: 2 | S8: 1 | T8: 1 | U8: 5 | V8: 0 | W8: 2 | X8: 1 | Y8: 2 | Z8: 0 | AA8: 0 | AB8: 2 | AC8: 4 | AD8: 0 | AE8: 2 | AF8: 0 | AG8: 2 | AH8: 0 | AI8: 2 | AJ8: 1 | AK8: 0 | AL8: 3 | AM8: 3 | AN8: 0 | AO8: 2 | AP8: 0 | AQ8: 1 | AR8: 2 | AS8: 2 | AT8: 1 | AU8: 3 | AV8: 0 | AW8: 0 | AX8: 2 | AY8: 2 | AZ8: 1 | BA8: 1 | BB8: 1 | BC8: 3 | BD8: 1 | BE8: 2 | BF8: 1
A9: 8 | B9: Castillo L. | C9: 2 | D9: 1 | E9: 2 | F9: 1 | G9: 1 | H9: 1 | I9: 2 | J9: 1 | K9: 0 | L9: 2 | M9: 1 | N9: 3 | O9: 2 | P9: 1 | Q9: 0 | R9: 3 | S9: 1 | T9: 1 | U9: 4 | V9: 0 | W9: 2 | X9: 2 | Y9: 2 | Z9: 11 | AA9: 0 | AB9: 2 | AC9: 4 | AD9: 0 | AE9: 2 | AF9: 0 | AG9: 3 | AH9: 1 | AI9: 2 | AJ9: 1 | AK9: 0 | AL9: 3 | AM9: 3 | AN9: 0 | AO9: 2 | AP9: 1 | AQ9: 2 | AR9: 1 | AS9: 2 | AT9: 2 | AU9: 3 | AV9: 0 | AW9: 1 | AX9: 1 | AY9: 3 | AZ9: 0 | BA9: 2 | BB9: 0 | BC9: 3 | BD9: 1 | BE9: 1 | BF9: 2
A10: 9 | B10: Christofer | C10: 2 | D10: 3 | E10: 1 | F10: 1 | G10: 1 | H10: 2 | I10: 2 | J10: 4 | K10: 3 | L10: 4 | M10: 2 | N10: 1 | O10: 5 | P10: 1 | Q10: 2 | R10: 1 | S10: 0 | T10: 3 | U10: 2 | V10: 2 | W10: 2 | X10: 5 | Y10: 4 | Z10: 1 | AA10: 1 | AB10: 2 | AC10: 3 | AD10: 1 | AE10: 1 | AF10: 1 | AG10: 2 | AH10: 0 | AI10: 1 | AJ10: 3 | AK10: 1 | AL10: 4 | AM10: 3 | AN10: 2 | AO10: 1 | AP10: 1 | AQ10: 1 | AR10: 3 | AS10: 2 | AT10: 1 | AU10: 7 | AV10: 4 | AW10: 1 | AX10: 2 | AY10: 2 | AZ10: 2 | BA10: 3 | BB10: 4 | BC10: 2 | BD10: 3 | BE10: 1 | BF10: 2
A11: 10 | B11: Cynthia | C11: 1 | D11: 2 | E11: 1 | F11: 0 | G11: 2 | H11: 1 | I11: 0 | J11: 0 | K11: 1 | L11: 3 | M11: 1 | N11: 1 | O11: 2 | P11: 2 | Q11: 0 | R11: 1 | S11: 0 | T11: 1 | U11: 3 | V11: 1 | W11: 2 | X11: 2 | Y11: 3 | Z11: 1 | AA11: 2 | AB11: 2 | AC11: 3 | AD11: 1 | AE11: 1 | AF11: 1 | AG11: 0 | AH11: 0 | AI11: 2 | AJ11: 1 | AK11: 1 | AL11: 0 | AM11: 3 | AN11: 1 | AO11: 2 | AP11: 1 | AQ11: 0 | AR11: 1 | AS11: 3 | AT11: 1 | AU11: 2 | AV11: 1 | AW11: 1 | AX11: 3 | AY11: 1 | AZ11: 2 | BA11: 1 | BB11: 0 | BC11: 1 | BD11: 1 | BE11: 1 | BF11: 1
A12: 11 | B12: Edward | C12: 2 | D12: 0 | E12: 2 | F12: 1 | G12: 2 | H12: 1 | I12: 2 | J12: 1 | K12: 0 | L12: 2 | M12: 0 | N12: 1 | O12: 2 | P12: 1 | Q12: 0 | R12: 2 | S12: 1 | T12: 1 | U12: 3 | V12: 0 | W12: 2 | X12: 1 | Y12: 2 | Z12: 0 | AA12: 1 | AB12: 2 | AC12: 4 | AD12: 0 | AE12: 1 | AF12: 0 | AG12: 2 | AH12: 1 | AI12: 2 | AJ12: 1 | AK12: 0 | AL12: 2 | AM12: 2 | AN12: 0 | AO12: 2 | AP12: 0 | AQ12: 1 | AR12: 2 | AS12: 2 | AT12: 1 | AU12: 2 | AV12: 1 | AW12: 1 | AX12: 2 | AY12: 2 | AZ12: 0 | BA12: 2 | BB12: 1 | BC12: 2 | BD12: 0 | BE12: 1 | BF12: 1
A13: 12 | B13: Espinosa L. | C13: 2 | D13: 1 | E13: 1 | F13: 0 | G13: 3 | H13: 0 | I13: 2 | J13: 1 | K13: 3 | L13: 1 | M13: 1 | N13: 1 | O13: 2 | P13: 0 | Q13: 0 | R13: 0 | S13: 1 | T13: 2 | U13: 3 | V13: 0 | W13: 0 | X13: 2 | Y13: 1 | Z13: 1 | AA13: 0 | AB13: 1 | AC13: 2 | AD13: 0 | AE13: 2 | AF13: 0 | AG13: 1 | AH13: 0 | AI13: 3 | AJ13: 0 | AK13: 1 | AL13: 1 | AM13: 2 | AN13: 0 | AO13: 1 | AP13: 1 | AQ13: 0 | AR13: 1 | AS13: 1 | AT13: 0 | AU13: 2 | AV13: 0 | AW13: 1 | AX13: 2 | AY13: 1 | AZ13: 1 | BA13: 0 | BB13: 1 | BC13: 2 | BD13: 0 | BE13: 2 | BF13: 0
A14: 13 | B14: Frida | C14: 2 | D14: 0 | E14: 1 | F14: 1 | G14: 0 | H14: 1 | I14: 0 | J14: 1 | K14: 0 | M14: 1 | N14: 0 | O14: 3 | P14: 1 | Q14: 0 | R14: 1 | S14: 1 | T14: 0 | U14: 2 | V14: 0 | W14: 2 | X14: 1 | Y14: 2 | Z14: 1 | AA14: 1 | AB14: 2 | AC14: 2 | AD14: 0
A15: 14 | B15: Isabel 1 | C15: 3 | D15: 1 | E15: 1 | F15: 1 | G15: 2 | H15: 1 | I15: 2 | J15: 2 | K15: 1 | L15: 3 | M15: 1 | N15: 2 | O15: 3 | P15: 2 | Q15: 0 | R15: 2 | S15: 1 | T15: 2 | U15: 5 | V15: 1 | W15: 2 | X15: 2 | Y15: 1 | Z15: 1 | AA15: 1 | AB15: 2 | AC15: 4 | AD15: 0
A16: 15 | B16: Isabel 2 | C16: 1 | D16: 0 | E16: 2 | F16: 0 | G16: 2 | H16: 1 | I16: 3 | J16: 1 | K16: 0 | L16: 2 | M16: 0 | N16: 3 | O16: 4 | P16: 1 | Q16: 0 | R16: 1 | S16: 1 | T16: 1 | U16: 4 | V16: 0 | W16: 2 | X16: 1 | Y16: 3 | Z16: 0 | AA16: 0 | AB16: 1 | AC16: 5 | AD16: 0
A17: 16 | B17: Javier | C17: 2 | D17: 0 | E17: 3 | F17: 1 | G17: 2 | H17: 1 | I17: 2 | J17: 1 | K17: 1 | L17: 1 | M17: 1 | N17: 2 | O17: 2 | P17: 1 | Q17: 1 | R17: 1 | S17: 1 | T17: 1 | U17: 3 | V17: 1 | W17: 2 | X17: 1 | Y17: 1 | Z17: 1 | AA17: 5 | AB17: 2 | AC17: 3 | AD17: 0
A18: 17 | B18: Jose C 1 | C18: 0 | D18: 1 | E18: 1 | F18: 1 | G18: 2 | H18: 1 | I18: 2 | J18: 2 | K18: 1 | L18: 0 | M18: 0 | N18: 2 | O18: 3 | P18: 2 | Q18: 0 | R18: 2 | S18: 1 | T18: 1 | U18: 3 | V18: 0 | W18: 2 | X18: 1 | Y18: 2 | Z18: 0 | AA18: 0 | AB18: 2 | AC18: 3 | AD18: 0
A19: 18 | B19: Jose C 2 | C19: 1 | D19: 0 | E19: 2 | F19: 1 | G19: 1 | H19: 1 | I19: 2 | J19: 2 | K19: 2 | L19: 0 | M19: 1 | N19: 2 | O19: 1 | P19: 2 | Q19: 1 | R19: 1 | S19: 2 | T19: 1 | U19: 4 | V19: 1 | X19: 2 | Y19: 1 | Z19: 0 | AB19: 3 | AC19: 5 | AD19: 1
A20: 19 | B20: Jose C Ahiza | C20: 2 | D20: 1 | E20: 2 | F20: 1 | G20: 2 | H20: 0 | I20: 3 | J20: 1 | K20: 0 | L20: 2 | M20: 1 | N20: 2 | O20: 2 | P20: 0 | Q20: 1 | R20: 2 | S20: 1 | T20: 1 | U20: 3 | V20: 0 | W20: 2 | X20: 0 | Y20: 2 | Z20: 1 | AA20: 0 | AB20: 2 | AC20: 3 | AD20: 0
A21: 20 | B21: Jose C Ana | C21: 4 | D21: 2 | E21: 3 | F21: 1 | G21: 4 | H21: 0 | I21: 1 | J21: 2 | K21: 1 | L21: 1 | M21: 2 | N21: 1 | O21: 2 | P21: 0 | Q21: 0 | R21: 2 | S21: 2 | T21: 3 | U21: 6 | V21: 0 | W21: 3 | X21: 1 | Y21: 2 | Z21: 1 | AA21: 1 | AB21: 3 | AC21: 7 | AD21: 0
A22: 21 | B22: Jose C Judith | C22: 3 | D22: 2 | E22: 2 | F22: 2 | G22: 3 | H22: 1 | I22: 3 | J22: 2 | K22: 1 | L22: 1 | M22: 2 | N22: 1 | O22: 3 | P22: 0 | Q22: 1 | R22: 2 | S22: 2 | T22: 2 | U22: 4 | V22: 0 | W22: 2 | X22: 0 | Y22: 3 | Z22: 1 | AA22: 0 | AB22: 2 | AC22: 5 | AD22: 0
A23: 22 | B23: José de León | C23: 2 | D23: 1 | E23: 2 | F23: 1 | G23: 1 | H23: 0 | I23: 3 | J23: 0 | K23: 0 | L23: 3 | M23: 2 | N23: 2 | O23: 0 | P23: 2 | Q23: 1 | R23: 2 | S23: 4 | T23: 0 | U23: 1 | V23: 1 | W23: 1 | X23: 0 | Y23: 0 | Z23: 1 | AA23: 4 | AB23: 0 | AC23: 2 | AD23: 1
A24: 23 | B24: Jovanna | C24: 5 | D24: 2 | E24: 1 | F24: 3 | G24: 0 | H24: 2 | I24: 1 | J24: 1 | K24: 0 | L24: 3 | M24: 0 | N24: 1 | O24: 3 | P24: 2 | Q24: 0 | R24: 4 | S24: 2 | T24: 1 | U24: 6 | V24: 1 | W24: 0 | X24: 2 | Y24: 3 | Z24: 1 | AA24: 1 | AB24: 0 | AC24: 2 | AD24: 0
A25: 24 | B25: Karina | C25: 3 | D25: 1 | E25: 1 | F25: 2 | G25: 2 | H25: 1 | I25: 2 | J25: 1 | K25: 1 | L25: 3 | M25: 1 | N25: 1 | O25: 3 | P25: 2 | Q25: 1 | R25: 2 | S25: 2 | T25: 2 | U25: 3 | V25: 1 | W25: 3 | X25: 1 | Y25: 2 | Z25: 1 | AA25: 1 | AB25: 3 | AC25: 5 | AD25: 1
A26: 25 | B26: Kattia 1 | C26: 2 | D26: 1 | E26: 2 | F26: 0 | G26: 3 | H26: 0 | I26: 2 | J26: 1 | K26: 0 | L26: 2 | M26: 2 | N26: 0 | O26: 2 | P26: 2 | Q26: 0 | R26: 2 | S26: 2 | T26: 1 | U26: 3 | V26: 1 | W26: 4 | X26: 0 | Y26: 2 | Z26: 0 | AA26: 1 | AB26: 3 | AC26: 3 | AD26: 1
A27: 26 | B27: Kattia 2 | C27: 2 | D27: 0 | E27: 1 | F27: 1 | G27: 2 | H27: 1 | I27: 2 | J27: 1 | K27: 0 | L27: 3 | M27: 1 | N27: 1 | O27: 3 | P27: 2 | Q27: 0 | R27: 2 | S27: 2 | T27: 2 | U27: 4 | V27: 0 | W27: 2 | X27: 2 | Y27: 2 | Z27: 0 | AA27: 0 | AB27: 2 | AC27: 3 | AD27: 0
A28: 27 | B28: Kevin | C28: 2 | D28: 0 | E28: 1 | F28: 1 | G28: 1 | H28: 2 | I28: 2 | J28: 1 | K28: 0 | L28: 2 | M28: 1 | N28: 1 | O28: 3 | P28: 1 | Q28: 0 | R28: 2 | S28: 2 | T28: 2 | U28: 4 | V28: 0 | W28: 2 | X28: 1 | Y28: 1 | Z28: 0 | AA28: 0 | AB28: 2 | AC28: 3 | AD28: 0
A29: 28 | B29: Lizka | C29: 2 | D29: 0 | E29: 1 | F29: 1 | G29: 2 | H29: 1 | I29: 2 | J29: 1 | K29: 1 | L29: 2 | M29: 1 | N29: 2 | O29: 2 | P29: 1 | Q29: 0 | R29: 2 | S29: 1 | T29: 1 | U29: 3 | V29: 1 | W29: 2 | X29: 1 | Y29: 2 | Z29: 1 | AA29: 0 | AB29: 3 | AC29: 4 | AD29: 0
A30: 29 | B30: Luis Peña | C30: 2 | D30: 0 | E30: 2 | F30: 1 | G30: 1 | H30: 0 | I30: 2 | J30: 1 | K30: 1 | L30: 3 | M30: 0 | N30: 2 | O30: 2 | P30: 1 | Q30: 0 | R30: 4 | S30: 0 | T30: 2 | U30: 4 | V30: 0 | W30: 2 | X30: 2 | Y30: 2 | Z30: 0 | AA30: 0 | AB30: 2 | AC30: 7 | AD30: 0
A31: 30 | B31: Marco R. | C31: 2 | D31: 1 | E31: 1 | F31: 1 | G31: 1 | H31: 1 | I31: 2 | J31: 1 | K31: 1 | L31: 2 | M31: 0 | N31: 1 | O31: 2 | P31: 1 | Q31: 0 | R31: 2 | S31: 1 | T31: 1 | U31: 4 | V31: 0 | W31: 1 | X31: 1 | Y31: 1 | Z31: 1 | AA31: 0 | AB31: 2 | AC31: 4 | AD31: 0
... A36: 35 | B36: Mily CF 1 | C36: 3 | D36: 1 | E36: 2 | F36: 1 | G36: 2 | H36: 2 | I36: 3 | J36: 2 | K36: 2 | L36: 3 | M36: 3 | N36: 4 | O36: 4 | P36: 4 | Q36: 1 | R36: 2 | S36: 1 | T36: 3 | U36: 3 | V36: 1 | W36: 2 | X36: 2 | Y36: 2 | Z36: 1 | AA36: 2 | AB36: 2 | AC36: 3 | AD36: 1
A37: 36 | B37: Mily CF 2 | C37: 2 | D37: 1 | E37: 2 | F37: 0 | G37: 1 | H37: 0 | I37: 2 | J37: 1 | L37: 1 | M37: 1 | N37: 2 | O37: 2 | P37: 1 | Q37: 0 | R37: 1 | S37: 2 | T37: 3 | U37: 3 | V37: 1 | W37: 2 | X37: 1 | Y37: 1 | Z37: 1 | AA37: 1 | AB37: 2 | AC37: 3 | AD37: 0 | AE37: 1 | AF37: 0 | AG37: 2 | AH37: 0 | AI37: 2 | AJ37: 1 | AK37: 0 | AL37: 2 | AM37: 2 | AN37: 0 | AO37: 1 | AP37: 0
A38: 37 | B38: Mily Oliver | C38: 2 | D38: 0 | E38: 1 | F38: 1 | G38: 2 | H38: 1 | I38: 2 | J38: 0 | K38: 0 | L38: 0 | M38: 1 | N38: 2 | O38: 2 | P38: 1 | Q38: 0 | R38: 2 | S38: 1 | T38: 1 | U38: 3 | V38: 0 | W38: 2 | X38: 1 | Y38: 1 | Z38: 0 | AA38: 1 | AB38: 2 | AC38: 3 | AD38: 0
A39: 38 | B39: Mily Zeynneth | C39: 3 | D39: 1 | E39: 2 | F39: 2 | G39: 3 | H39: 1 | I39: 3 | J39: 0 | K39: 0 | L39: 1 | M39: 2 | N39: 3 | O39: 3 | P39: 1 | Q39: 0 | S39: 1 | T39: 2 | U39: 4 | V39: 0 | W39: 3 | X39: 1 | Y39: 2 | Z39: 1 | AA39: 2 | AB39: 3 | AC39: 4 | AD39: 1
A40: 39 | B40: Nefreteri | C40: 1 | D40: 2 | E40: 3 | F40: 0 | G40: 2 | H40: 0 | I40: 1 | J40: 2 | K40: 0 | L40: 1 | M40: 2 | N40: 2 | O40: 1 | P40: 1 | Q40: 0 | R40: 2 | S40: 2 | T40: 1 | U40: 3 | V40: 0 | W40: 2 | X40: 1 | Y40: 2 | Z40: 0 | AA40: 1 | AB40: 3 | AC40: 3 | AD40: 0
A41: 40 | B41: Ninoshka | C41: 2 | D41: 1 | E41: 1 | F41: 1 | G41: 2 | H41: 0 | I41: 1 | J41: 2 | K41: 0 | L41: 2 | M41: 1 | N41: 2 | O41: 3 | P41: 1 | Q41: 0 | R41: 2 | S41: 1 | T41: 1 | U41: 4 | V41: 0 | W41: 2 | X41: 1 | Y41: 2 | Z41: 0 | AA41: 0 | AB41: 2 | AC41: 3 | AD41: 0
A42: 41 | B42: Osvaldo | C42: 2 | D42: 1 | E42: 2 | F42: 1 | G42: 2 | H42: 1 | I42: 2 | J42: 1 | K42: 1 | L42: 1 | M42: 0 | N42: 2 | O42: 3 | P42: 2 | Q42: 1 | R42: 1 | S42: 1 | T42: 3 | U42: 3 | V42: 1 | W42: 2 | X42: 0 | Y42: 3 | Z42: 1 | AA42: 0 | AB42: 1 | AC42: 4 | AD42: 0
A43: 42 | B43: Peter | C43: 2 | D43: 0 | E43: 1 | F43: 0 | G43: 1 | H43: 1 | I43: 2 | J43: 2 | K43: 0 | L43: 3 | M43: 1 | N43: 2 | O43: 1 | P43: 2 | R43: 2 | S43: 0 | T43: 2 | U43: 4 | V43: 0 | W43: 2 | X43: 2 | Y43: 2 | Z43: 0 | AA43: 1 | AB43: 3 | AC43: 3 | AD43: 0
A44: 43 | B44: Quinnie | C44: 2 | D44: 0 | E44: 1 | F44: 1 | G44: 2 | H44: 1 | I44: 1 | J44: 1 | K44: 0 | L44: 2 | M44: 1 | N44: 2 | O44: 2 | P44: 1 | Q44: 0 | R44: 2 | S44: 1 | T44: 1 | U44: 5 | V44: 0 | W44: 2 | X44: 2 | Y44: 3 | Z44: 0 | AA44: 0 | AB44: 2 | AC44: 5 | AD44: 0
...

Sheet Partidos
A1: N° | B1: Fecha | C1: Hora ET | D1: Fase | E1: Grupo | F1: Local | G1: Visitante | H1: Goles Local | I1: Goles Visitante | J1: Ganador/Clasifica | K1: Sede | L1: Local código | M1: Visitante código | N1: Local posición | O1: Visitante posición | P1: Fuente/Nota | Q1: Nota
A2: 1 | B2: 46184 | C2: 15:00 | D2: Grupo | E2: A | F2: México | G2: Sudáfrica | J2: =IF(OR(H2="",I2=""),"",IF(H2>I2,F2,IF(I2>H2,G2,"Empate"))) | K2: Mexico City | L2: MEX | M2: RSA | N2: A1 | O2: A2 | P2: FIFA/CBS | Q2: Eliminatorias: si una posición aún no está definida, F/G muestran la llave (1A, 2B, 3A/B/C..., W74, L101). Un grupo solo clasifica cuando sus 4 equipos tienen al menos 1 partido con marcador.
A3: 2 | B3: 46184 | C3: 22:00 | D3: Grupo | E3: A | F3: Corea República | G3: Chequia | J3: =IF(OR(H3="",I3=""),"",IF(H3>I3,F3,IF(I3>H3,G3,"Empate"))) | K3: Guadalajara | L3: KOR | M3: CZE | N3: A3 | O3: A4 | P3: FIFA/CBS
A4: 3 | B4: 46185 | C4: 15:00 | D4: Grupo | E4: B | F4: Canadá | G4: Bosnia y Herzegovina | J4: =IF(OR(H4="",I4=""),"",IF(H4>I4,F4,IF(I4>H4,G4,"Empate"))) | K4: Toronto | L4: CAN | M4: BIH | N4: B1 | O4: B2 | P4: FIFA/CBS
A5: 4 | B5: 46185 | C5: 21:00 | D5: Grupo | E5: D | F5: Estados Unidos | G5: Paraguay | J5: =IF(OR(H5="",I5=""),"",IF(H5>I5,F5,IF(I5>H5,G5,"Empate"))) | K5: Los Angeles | L5: USA | M5: PAR | N5: D1 | O5: D2 | P5: FIFA/CBS
A6: 5 | B6: 46186 | C6: 21:00 | D6: Grupo | E6: C | F6: Haití | G6: Escocia | J6: =IF(OR(H6="",I6=""),"",IF(H6>I6,F6,IF(I6>H6,G6,"Empate"))) | K6: Boston | L6: HAI | M6: SCO | N6: C3 | O6: C4 | P6: FIFA/CBS
A7: 6 | B7: 46186 | C7: 00:00 | D7: Grupo | E7: D | F7: Australia | G7: Türkiye | J7: =IF(OR(H7="",I7=""),"",IF(H7>I7,F7,IF(I7>H7,G7,"Empate"))) | K7: Vancouver | L7: AUS | M7: TUR | N7: D3 | O7: D4 | P7: FIFA/CBS
A8: 7 | B8: 46186 | C8: 18:00 | D8: Grupo | E8: C | F8: Brasil | G8: Marruecos | J8: =IF(OR(H8="",I8=""),"",IF(H8>I8,F8,IF(I8>H8,G8,"Empate"))) | K8: New York New Jersey | L8: BRA | M8: MAR | N8: C1 | O8: C2 | P8: FIFA/CBS
A9: 8 | B9: 46186 | C9: 15:00 | D9: Grupo | E9: B | F9: Qatar | G9: Suiza | J9: =IF(OR(H9="",I9=""),"",IF(H9>I9,F9,IF(I9>H9,G9,"Empate"))) | K9: San Francisco Bay Area | L9: QAT | M9: SUI | N9: B3 | O9: B4 | P9: FIFA/CBS
A10: 9 | B10: 46187 | C10: 19:00 | D10: Grupo | E10: E | F10: Costa de Marfil | G10: Ecuador | J10: =IF(OR(H10="",I10=""),"",IF(H10>I10,F10,IF(I10>H10,G10,"Empate"))) | K10: Philadelphia | L10: CIV | M10: ECU | N10: E3 | O10: E4 | P10: FIFA/CBS
A11: 10 | B11: 46187 | C11: 13:00 | D11: Grupo | E11: E | F11: Alemania | G11: Curazao | J11: =IF(OR(H11="",I11=""),"",IF(H11>I11,F11,IF(I11>H11,G11,"Empate"))) | K11: Houston | L11: GER | M11: CUW | N11: E1 | O11: E2 | P11: FIFA/CBS
A12: 11 | B12: 46187 | C12: 16:00 | D12: Grupo | E12: F | F12: Países Bajos | G12: Japón | J12: =IF(OR(H12="",I12=""),"",IF(H12>I12,F12,IF(I12>H12,G12,"Empate"))) | K12: Dallas | L12: NED | M12: JPN | N12: F1 | O12: F2 | P12: FIFA/CBS
A13: 12 | B13: 46187 | C13: 22:00 | D13: Grupo | E13: F | F13: Suecia | G13: Túnez | J13: =IF(OR(H13="",I13=""),"",IF(H13>I13,F13,IF(I13>H13,G13,"Empate"))) | K13: Monterrey | L13: SWE | M13: TUN | N13: F3 | O13: F4 | P13: FIFA/CBS
A14: 13 | B14: 46188 | C14: 18:00 | D14: Grupo | E14: H | F14: Arabia Saudita | G14: Uruguay | J14: =IF(OR(H14="",I14=""),"",IF(H14>I14,F14,IF(I14>H14,G14,"Empate"))) | K14: Miami | L14: KSA | M14: URU | N14: H3 | O14: H4 | P14: FIFA/CBS
... A73: 72 | B73: 46200 | C73: 19:30 | D73: Grupo | E73: K | F73: RD Congo | G73: Uzbekistán | J73: =IF(OR(H73="",I73=""),"",IF(H73>I73,F73,IF(I73>H73,G73,"Empate"))) | K73: Atlanta | L73: COD | M73: UZB | N73: K2 | O73: K3 | P73: FIFA/CBS
A74: 73 | B74: 46201 | C74: 15:00 | D74: Ronda de 32 | F74: =IF(N74="","",IF(LEFT(N74,1)="3",IFERROR(IF(VLOOKUP($A74&"L",Asignacion_3ros!$A$2:$G$9,6,FALSE)="",N74,VLOOKUP($A74&"L",Asignacion_3ros!$A$2:$G$9,6,FALSE)),N74),IF(LEFT(N74,1)="W",IFERROR(IF(INDEX($J$2:$J$73,MATCH(VALUE(MID(N74,2,3)),$A$2:$A$73,0))="",N74,INDEX($J$2:$J$73,MATCH(VALUE(MID(N74,2,3)),$A$2:$A$73,0))),N74),IF(LEFT(N74,1)="L",IFERROR(IF(INDEX($J$2:$J$73,MATCH(VALUE(MID(N74,2,3)),$A$2:$A$73,0))=INDEX($F$2:$F$73,MATCH(VALUE(MID(N74,2,3)),$A$2:$A$73,0)),INDEX($G$2:$G$73,MATCH(VALUE(MID(N74,2,3)),$A$2:$A$73,0)),IF(INDEX($J$2:$J$73,MATCH(VALUE(MID(N74,2,3)),$A$2:$A$73,0))=INDEX($G$2:$G$73,MATCH(VALUE(MID(N74,2,3)),$A$2:$A$73,0)),INDEX($F$2:$F$73,MATCH(VALUE(MID(N74,2,3)),$A$2:$A$73,0)),N74)),N74),IFERROR(IF(VLOOKUP(RIGHT(N74,1)&LEFT(N74,1),Clasificacion!$O$2:$Q$49,2,FALSE)="",N74,VLOOKUP(RIGHT(N74,1)&LEFT(N74,1),Clasificacion!$O$2:$Q$49,2,FALSE)),N74))))) -> 2A | G74: =IF(O74="","",IF(LEFT(O74,1)="3",IFERROR(IF(VLOOKUP($A74&"V",Asignacion_3ros!$A$2:$G$9,6,FALSE)="",O74,VLOOKUP($A74&"V",Asignacion_3ros!$A$2:$G$9,6,FALSE)),O74),IF(LEFT(O74,1)="W",IFERROR(IF(INDEX($J$2:$J$73,MATCH(VALUE(MID(O74,2,3)),$A$2:$A$73,0))="",O74,INDEX($J$2:$J$73,MATCH(VALUE(MID(O74,2,3)),$A$2:$A$73,0))),O74),IF(LEFT(O74,1)="L",IFERROR(IF(INDEX($J$2:$J$73,MATCH(VALUE(MID(O74,2,3)),$A$2:$A$73,0))=INDEX($F$2:$F$73,MATCH(VALUE(MID(O74,2,3)),$A$2:$A$73,0)),INDEX($G$2:$G$73,MATCH(VALUE(MID(O74,2,3)),$A$2:$A$73,0)),IF(INDEX($J$2:$J$73,MATCH(VALUE(MID(O74,2,3)),$A$2:$A$73,0))=INDEX($G$2:$G$73,MATCH(VALUE(MID(O74,2,3)),$A$2:$A$73,0)),INDEX($F$2:$F$73,MATCH(VALUE(MID(O74,2,3)),$A$2:$A$73,0)),O74)),O74),IFERROR(IF(VLOOKUP(RIGHT(O74,1)&LEFT(O74,1),Clasificacion!$O$2:$Q$49,2,FALSE)="",O74,VLOOKUP(RIGHT(O74,1)&LEFT(O74,1),Clasificacion!$O$2:$Q$49,2,FALSE)),O74))))) -> 2B | J74: =IF(OR(H74="",I74=""),"",IF(H74>I74,F74,IF(I74>H74,G74,"Empate"))) | K74: Los Angeles | L74: =IF(N74="","",IF(LEFT(N74,1)="3",IFERROR(IF(VLOOKUP($A74&"L",Asignacion_3ros!$A$2:$G$9,7,FALSE)="",N74,VLOOKUP($A74&"L",Asignacion_3ros!$A$2:$G$9,7,FALSE)),N74),IF(LEFT(N74,1)="W",IFERROR(IF(INDEX($J$2:$J$73,MATCH(VALUE(MID(N74,2,3)),$A$2:$A$73,0))=INDEX($F$2:$F$73,MATCH(VALUE(MID(N74,2,3)),$A$2:$A$73,0)),INDEX($L$2:$L$73,MATCH(VALUE(MID(N74,2,3)),$A$2:$A$73,0)),IF(INDEX($J$2:$J$73,MATCH(VALUE(MID(N74,2,3)),$A$2:$A$73,0))=INDEX($G$2:$G$73,MATCH(VALUE(MID(N74,2,3)),$A$2:$A$73,0)),INDEX($M$2:$M$73,MATCH(VALUE(MID(N74,2,3)),$A$2:$A$73,0)),N74)),N74),IF(LEFT(N74,1)="L",IFERROR(IF(INDEX($J$2:$J$73,MATCH(VALUE(MID(N74,2,3)),$A$2:$A$73,0))=INDEX($F$2:$F$73,MATCH(VALUE(MID(N74,2,3)),$A$2:$A$73,0)),INDEX($M$2:$M$73,MATCH(VALUE(MID(N74,2,3)),$A$2:$A$73,0)),IF(INDEX($J$2:$J$73,MATCH(VALUE(MID(N74,2,3)),$A$2:$A$73,0))=INDEX($G$2:$G$73,MATCH(VALUE(MID(N74,2,3)),$A$2:$A$73,0)),INDEX($L$2:$L$73,MATCH(VALUE(MID(N74,2,3)),$A$2:$A$73,0)),N74)),N74),IFERROR(IF(VLOOKUP(RIGHT(N74,1)&LEFT(N74,1),Clasificacion!$O$2:$Q$49,3,FALSE)="",N74,VLOOKUP(RIGHT(N74,1)&LEFT(N74,1),Clasificacion!$O$2:$Q$49,3,FALSE)),N74))))) -> 2A | M74: =IF(O74="","",IF(LEFT(O74,1)="3",IFERROR(IF(VLOOKUP($A74&"V",Asignacion_3ros!$A$2:$G$9,7,FALSE)="",O74,VLOOKUP($A74&"V",Asignacion_3ros!$A$2:$G$9,7,FALSE)),O74),IF(LEFT(O74,1)="W",IFERROR(IF(INDEX($J$2:$J$73,MATCH(VALUE(MID(O74,2,3)),$A$2:$A$73,0))=INDEX($F$2:$F$73,MATCH(VALUE(MID(O74,2,3)),$A$2:$A$73,0)),INDEX($L$2:$L$73,MATCH(VALUE(MID(O74,2,3)),$A$2:$A$73,0)),IF(INDEX($J$2:$J$73,MATCH(VALUE(MID(O74,2,3)),$A$2:$A$73,0))=INDEX($G$2:$G$73,MATCH(VALUE(MID(O74,2,3)),$A$2:$A$73,0)),INDEX($M$2:$M$73,MATCH(VALUE(MID(O74,2,3)),$A$2:$A$73,0)),O74)),O74),IF(LEFT(O74,1)="L",IFERROR(IF(INDEX($J$2:$J$73,MATCH(VALUE(MID(O74,2,3)),$A$2:$A$73,0))=INDEX($F$2:$F$73,MATCH(VALUE(MID(O74,2,3)),$A$2:$A$73,0)),INDEX($M$2:$M$73,MATCH(VALUE(MID(O74,2,3)),$A$2:$A$73,0)),IF(INDEX($J$2:$J$73,MATCH(VALUE(MID(O74,2,3)),$A$2:$A$73,0))=INDEX($G$2:$G$73,MATCH(VALUE(MID(O74,2,3)),$A$2:$A$73,0)),INDEX($L$2:$L$73,MATCH(VALUE(MID(O74,2,3)),$A$2:$A$73,0)),O74)),O74),IFERROR(IF(VLOOKUP(RIGHT(O74,1)&LEFT(O74,1),Clasificacion!$O$2:$Q$49,3,FALSE)="",O74,VLOOKUP(RIGHT(O74,1)&LEFT(O74,1),Clasificacion!$O$2:$Q$49,3,FALSE)),O74))))) -> 2B | N74: 2A | O74: 2B | P74: FIFA/CBS
A75: 74 | B75: 46201 | C75: 16:30 | D75: Ronda de 32 | F75: =IF(N75="","",IF(LEFT(N75,1)="3",IFERROR(IF(VLOOKUP($A75&"L",Asignacion_3ros!$A$2:$G$9,6,FALSE)="",N75,VLOOKUP($A75&"L",Asignacion_3ros!$A$2:$G$9,6,FALSE)),N75),IF(LEFT(N75,1)="W",IFERROR(IF(INDEX($J$2:$J$74,MATCH(VALUE(MID(N75,2,3)),$A$2:$A$74,0))="",N75,INDEX($J$2:$J$74,MATCH(VALUE(MID(N75,2,3)),$A$2:$A$74,0))),N75),IF(LEFT(N75,1)="L",IFERROR(IF(INDEX($J$2:$J$74,MATCH(VALUE(MID(N75,2,3)),$A$2:$A$74,0))=INDEX($F$2:$F$74,MATCH(VALUE(MID(N75,2,3)),$A$2:$A$74,0)),INDEX($G$2:$G$74,MATCH(VALUE(MID(N75,2,3)),$A$2:$A$74,0)),IF(INDEX($J$2:$J$74,MATCH(VALUE(MID(N75,2,3)),$A$2:$A$74,0))=INDEX($G$2:$G$74,MATCH(VALUE(MID(N75,2,3)),$A$2:$A$74,0)),INDEX($F$2:$F$74,MATCH(VALUE(MID(N75,2,3)),$A$2:$A$74,0)),N75)),N75),IFERROR(IF(VLOOKUP(RIGHT(N75,1)&LEFT(N75,1),Clasificacion!$O$2:$Q$49,2,FALSE)="",N75,VLOOKUP(RIGHT(N75,1)&LEFT(N75,1),Clasificacion!$O$2:$Q$49,2,FALSE)),N75))))) -> 1E | G75: =IF(O75="","",IF(LEFT(O75,1)="3",IFERROR(IF(VLOOKUP($A75&"V",Asignacion_3ros!$A$2:$G$9,6,FALSE)="",O75,VLOOKUP($A75&"V",Asignacion_3ros!$A$2:$G$9,6,FALSE)),O75),IF(LEFT(O75,1)="W",IFERROR(IF(INDEX($J$2:$J$74,MATCH(VALUE(MID(O75,2,3)),$A$2:$A$74,0))="",O75,INDEX($J$2:$J$74,MATCH(VALUE(MID(O75,2,3)),$A$2:$A$74,0))),O75),IF(LEFT(O75,1)="L",IFERROR(IF(INDEX($J$2:$J$74,MATCH(VALUE(MID(O75,2,3)),$A$2:$A$74,0))=INDEX($F$2:$F$74,MATCH(VALUE(MID(O75,2,3)),$A$2:$A$74,0)),INDEX($G$2:$G$74,MATCH(VALUE(MID(O75,2,3)),$A$2:$A$74,0)),IF(INDEX($J$2:$J$74,MATCH(VALUE(MID(O75,2,3)),$A$2:$A$74,0))=INDEX($G$2:$G$74,MATCH(VALUE(MID(O75,2,3)),$A$2:$A$74,0)),INDEX($F$2:$F$74,MATCH(VALUE(MID(O75,2,3)),$A$2:$A$74,0)),O75)),O75),IFERROR(IF(VLOOKUP(RIGHT(O75,1)&LEFT(O75,1),Clasificacion!$O$2:$Q$49,2,FALSE)="",O75,VLOOKUP(RIGHT(O75,1)&LEFT(O75,1),Clasificacion!$O$2:$Q$49,2,FALSE)),O75))))) -> Corea República | J75: =IF(OR(H75="",I75=""),"",IF(H75>I75,F75,IF(I75>H75,G75,"Empate"))) | K75: Boston | L75: =IF(N75="","",IF(LEFT(N75,1)="3",IFERROR(IF(VLOOKUP($A75&"L",Asignacion_3ros!$A$2:$G$9,7,FALSE)="",N75,VLOOKUP($A75&"L",Asignacion_3ros!$A$2:$G$9,7,FALSE)),N75),IF(LEFT(N75,1)="W",IFERROR(IF(INDEX($J$2:$J$74,MATCH(VALUE(MID(N75,2,3)),$A$2:$A$74,0))=INDEX($F$2:$F$74,MATCH(VALUE(MID(N75,2,3)),$A$2:$A$74,0)),INDEX($L$2:$L$74,MATCH(VALUE(MID(N75,2,3)),$A$2:$A$74,0)),IF(INDEX($J$2:$J$74,MATCH(VALUE(MID(N75,2,3)),$A$2:$A$74,0))=INDEX($G$2:$G$74,MATCH(VALUE(MID(N75,2,3)),$A$2:$A$74,0)),INDEX($M$2:$M$74,MATCH(VALUE(MID(N75,2,3)),$A$2:$A$74,0)),N75)),N75),IF(LEFT(N75,1)="L",IFERROR(IF(INDEX($J$2:$J$74,MATCH(VALUE(MID(N75,2,3)),$A$2:$A$74,0))=INDEX($F$2:$F$74,MATCH(VALUE(MID(N75,2,3)),$A$2:$A$74,0)),INDEX($M$2:$M$74,MATCH(VALUE(MID(N75,2,3)),$A$2:$A$74,0)),IF(INDEX($J$2:$J$74,MATCH(VALUE(MID(N75,2,3)),$A$2:$A$74,0))=INDEX($G$2:$G$74,MATCH(VALUE(MID(N75,2,3)),$A$2:$A$74,0)),INDEX($L$2:$L$74,MATCH(VALUE(MID(N75,2,3)),$A$2:$A$74,0)),N75)),N75),IFERROR(IF(VLOOKUP(RIGHT(N75,1)&LEFT(N75,1),Clasificacion!$O$2:$Q$49,3,FALSE)="",N75,VLOOKUP(RIGHT(N75,1)&LEFT(N75,1),Clasificacion!$O$2:$Q$49,3,FALSE)),N75))))) -> 1E | M75: =IF(O75="","",IF(LEFT(O75,1)="3",IFERROR(IF(VLOOKUP($A75&"V",Asignacion_3ros!$A$2:$G$9,7,FALSE)="",O75,VLOOKUP($A75&"V",Asignacion_3ros!$A$2:$G$9,7,FALSE)),O75),IF(LEFT(O75,1)="W",IFERROR(IF(INDEX($J$2:$J$74,MATCH(VALUE(MID(O75,2,3)),$A$2:$A$74,0))=INDEX($F$2:$F$74,MATCH(VALUE(MID(O75,2,3)),$A$2:$A$74,0)),INDEX($L$2:$L$74,MATCH(VALUE(MID(O75,2,3)),$A$2:$A$74,0)),IF(INDEX($J$2:$J$74,MATCH(VALUE(MID(O75,2,3)),$A$2:$A$74,0))=INDEX($G$2:$G$74,MATCH(VALUE(MID(O75,2,3)),$A$2:$A$74,0)),INDEX($M$2:$M$74,MATCH(VALUE(MID(O75,2,3)),$A$2:$A$74,0)),O75)),O75),IF(LEFT(O75,1)="L",IFERROR(IF(INDEX($J$2:$J$74,MATCH(VALUE(MID(O75,2,3)),$A$2:$A$74,0))=INDEX($F$2:$F$74,MATCH(VALUE(MID(O75,2,3)),$A$2:$A$74,0)),INDEX($M$2:$M$74,MATCH(VALUE(MID(O75,2,3)),$A$2:$A$74,0)),IF(INDEX($J$2:$J$74,MATCH(VALUE(MID(O75,2,3)),$A$2:$A$74,0))=INDEX($G$2:$G$74,MATCH(VALUE(MID(O75,2,3)),$A$2:$A$74,0)),INDEX($L$2:$L$74,MATCH(VALUE(MID(O75,2,3)),$A$2:$A$74,0)),O75)),O75),IFERROR(IF(VLOOKUP(RIGHT(O75,1)&LEFT(O75,1),Clasificacion!$O$2:$Q$49,3,FALSE)="",O75,VLOOKUP(RIGHT(O75,1)&LEFT(O75,1),Clasificacion!$O$2:$Q$49,3,FALSE)),O75))))) -> KOR | N75: 1E | O75: 3A/B/C/D/F | P75: FIFA/CBS
A76: 75 | B76: 46202 | C76: 21:00 | D76: Ronda de 32 | F76: =IF(N76="","",IF(LEFT(N76,1)="3",IFERROR(IF(VLOOKUP($A76&"L",Asignacion_3ros!$A$2:$G$9,6,FALSE)="",N76,VLOOKUP($A76&"L",Asignacion_3ros!$A$2:$G$9,6,FALSE)),N76),IF(LEFT(N76,1)="W",IFERROR(IF(INDEX($J$2:$J$75,MATCH(VALUE(MID(N76,2,3)),$A$2:$A$75,0))="",N76,INDEX($J$2:$J$75,MATCH(VALUE(MID(N76,2,3)),$A$2:$A$75,0))),N76),IF(LEFT(N76,1)="L",IFERROR(IF(INDEX($J$2:$J$75,MATCH(VALUE(MID(N76,2,3)),$A$2:$A$75,0))=INDEX($F$2:$F$75,MATCH(VALUE(MID(N76,2,3)),$A$2:$A$75,0)),INDEX($G$2:$G$75,MATCH(VALUE(MID(N76,2,3)),$A$2:$A$75,0)),IF(INDEX($J$2:$J$75,MATCH(VALUE(MID(N76,2,3)),$A$2:$A$75,0))=INDEX($G$2:$G$75,MATCH(VALUE(MID(N76,2,3)),$A$2:$A$75,0)),INDEX($F$2:$F$75,MATCH(VALUE(MID(N76,2,3)),$A$2:$A$75,0)),N76)),N76),IFERROR(IF(VLOOKUP(RIGHT(N76,1)&LEFT(N76,1),Clasificacion!$O$2:$Q$49,2,FALSE)="",N76,VLOOKUP(RIGHT(N76,1)&LEFT(N76,1),Clasificacion!$O$2:$Q$49,2,FALSE)),N76))))) -> 1F | G76: =IF(O76="","",IF(LEFT(O76,1)="3",IFERROR(IF(VLOOKUP($A76&"V",Asignacion_3ros!$A$2:$G$9,6,FALSE)="",O76,VLOOKUP($A76&"V",Asignacion_3ros!$A$2:$G$9,6,FALSE)),O76),IF(LEFT(O76,1)="W",IFERROR(IF(INDEX($J$2:$J$75,MATCH(VALUE(MID(O76,2,3)),$A$2:$A$75,0))="",O76,INDEX($J$2:$J$75,MATCH(VALUE(MID(O76,2,3)),$A$2:$A$75,0))),O76),IF(LEFT(O76,1)="L",IFERROR(IF(INDEX($J$2:$J$75,MATCH(VALUE(MID(O76,2,3)),$A$2:$A$75,0))=INDEX($F$2:$F$75,MATCH(VALUE(MID(O76,2,3)),$A$2:$A$75,0)),INDEX($G$2:$G$75,MATCH(VALUE(MID(O76,2,3)),$A$2:$A$75,0)),IF(INDEX($J$2:$J$75,MATCH(VALUE(MID(O76,2,3)),$A$2:$A$75,0))=INDEX($G$2:$G$75,MATCH(VALUE(MID(O76,2,3)),$A$2:$A$75,0)),INDEX($F$2:$F$75,MATCH(VALUE(MID(O76,2,3)),$A$2:$A$75,0)),O76)),O76),IFERROR(IF(VLOOKUP(RIGHT(O76,1)&LEFT(O76,1),Clasificacion!$O$2:$Q$49,2,FALSE)="",O76,VLOOKUP(RIGHT(O76,1)&LEFT(O76,1),Clasificacion!$O$2:$Q$49,2,FALSE)),O76))))) -> 2C | J76: =IF(OR(H76="",I76=""),"",IF(H76>I76,F76,IF(I76>H76,G76,"Empate"))) | K76: Monterrey | L76: =IF(N76="","",IF(LEFT(N76,1)="3",IFERROR(IF(VLOOKUP($A76&"L",Asignacion_3ros!$A$2:$G$9,7,FALSE)="",N76,VLOOKUP($A76&"L",Asignacion_3ros!$A$2:$G$9,7,FALSE)),N76),IF(LEFT(N76,1)="W",IFERROR(IF(INDEX($J$2:$J$75,MATCH(VALUE(MID(N76,2,3)),$A$2:$A$75,0))=INDEX($F$2:$F$75,MATCH(VALUE(MID(N76,2,3)),$A$2:$A$75,0)),INDEX($L$2:$L$75,MATCH(VALUE(MID(N76,2,3)),$A$2:$A$75,0)),IF(INDEX($J$2:$J$75,MATCH(VALUE(MID(N76,2,3)),$A$2:$A$75,0))=INDEX($G$2:$G$75,MATCH(VALUE(MID(N76,2,3)),$A$2:$A$75,0)),INDEX($M$2:$M$75,MATCH(VALUE(MID(N76,2,3)),$A$2:$A$75,0)),N76)),N76),IF(LEFT(N76,1)="L",IFERROR(IF(INDEX($J$2:$J$75,MATCH(VALUE(MID(N76,2,3)),$A$2:$A$75,0))=INDEX($F$2:$F$75,MATCH(VALUE(MID(N76,2,3)),$A$2:$A$75,0)),INDEX($M$2:$M$75,MATCH(VALUE(MID(N76,2,3)),$A$2:$A$75,0)),IF(INDEX($J$2:$J$75,MATCH(VALUE(MID(N76,2,3)),$A$2:$A$75,0))=INDEX($G$2:$G$75,MATCH(VALUE(MID(N76,2,3)),$A$2:$A$75,0)),INDEX($L$2:$L$75,MATCH(VALUE(MID(N76,2,3)),$A$2:$A$75,0)),N76)),N76),IFERROR(IF(VLOOKUP(RIGHT(N76,1)&LEFT(N76,1),Clasificacion!$O$2:$Q$49,3,FALSE)="",N76,VLOOKUP(RIGHT(N76,1)&LEFT(N76,1),Clasificacion!$O$2:$Q$49,3,FALSE)),N76))))) -> 1F | M76: =IF(O76="","",IF(LEFT(O76,1)="3",IFERROR(IF(VLOOKUP($A76&"V",Asignacion_3ros!$A$2:$G$9,7,FALSE)="",O76,VLOOKUP($A76&"V",Asignacion_3ros!$A$2:$G$9,7,FALSE)),O76),IF(LEFT(O76,1)="W",IFERROR(IF(INDEX($J$2:$J$75,MATCH(VALUE(MID(O76,2,3)),$A$2:$A$75,0))=INDEX($F$2:$F$75,MATCH(VALUE(MID(O76,2,3)),$A$2:$A$75,0)),INDEX($L$2:$L$75,MATCH(VALUE(MID(O76,2,3)),$A$2:$A$75,0)),IF(INDEX($J$2:$J$75,MATCH(VALUE(MID(O76,2,3)),$A$2:$A$75,0))=INDEX($G$2:$G$75,MATCH(VALUE(MID(O76,2,3)),$A$2:$A$75,0)),INDEX($M$2:$M$75,MATCH(VALUE(MID(O76,2,3)),$A$2:$A$75,0)),O76)),O76),IF(LEFT(O76,1)="L",IFERROR(IF(INDEX($J$2:$J$75,MATCH(VALUE(MID(O76,2,3)),$A$2:$A$75,0))=INDEX($F$2:$F$75,MATCH(VALUE(MID(O76,2,3)),$A$2:$A$75,0)),INDEX($M$2:$M$75,MATCH(VALUE(MID(O76,2,3)),$A$2:$A$75,0)),IF(INDEX($J$2:$J$75,MATCH(VALUE(MID(O76,2,3)),$A$2:$A$75,0))=INDEX($G$2:$G$75,MATCH(VALUE(MID(O76,2,3)),$A$2:$A$75,0)),INDEX($L$2:$L$75,MATCH(VALUE(MID(O76,2,3)),$A$2:$A$75,0)),O76)),O76),IFERROR(IF(VLOOKUP(RIGHT(O76,1)&LEFT(O76,1),Clasificacion!$O$2:$Q$49,3,FALSE)="",O76,VLOOKUP(RIGHT(O76,1)&LEFT(O76,1),Clasificacion!$O$2:$Q$49,3,FALSE)),O76))))) -> 2C | N76: 1F | O76: 2C | P76: FIFA/CBS
A77: 76 | B77: 46202 | C77: 13:00 | D77: Ronda de 32 | F77: =IF(N77="","",IF(LEFT(N77,1)="3",IFERROR(IF(VLOOKUP($A77&"L",Asignacion_3ros!$A$2:$G$9,6,FALSE)="",N77,VLOOKUP($A77&"L",Asignacion_3ros!$A$2:$G$9,6,FALSE)),N77),IF(LEFT(N77,1)="W",IFERROR(IF(INDEX($J$2:$J$76,MATCH(VALUE(MID(N77,2,3)),$A$2:$A$76,0))="",N77,INDEX($J$2:$J$76,MATCH(VALUE(MID(N77,2,3)),$A$2:$A$76,0))),N77),IF(LEFT(N77,1)="L",IFERROR(IF(INDEX($J$2:$J$76,MATCH(VALUE(MID(N77,2,3)),$A$2:$A$76,0))=INDEX($F$2:$F$76,MATCH(VALUE(MID(N77,2,3)),$A$2:$A$76,0)),INDEX($G$2:$G$76,MATCH(VALUE(MID(N77,2,3)),$A$2:$A$76,0)),IF(INDEX($J$2:$J$76,MATCH(VALUE(MID(N77,2,3)),$A$2:$A$76,0))=INDEX($G$2:$G$76,MATCH(VALUE(MID(N77,2,3)),$A$2:$A$76,0)),INDEX($F$2:$F$76,MATCH(VALUE(MID(N77,2,3)),$A$2:$A$76,0)),N77)),N77),IFERROR(IF(VLOOKUP(RIGHT(N77,1)&LEFT(N77,1),Clasificacion!$O$2:$Q$49,2,FALSE)="",N77,VLOOKUP(RIGHT(N77,1)&LEFT(N77,1),Clasificacion!$O$2:$Q$49,2,FALSE)),N77))))) -> 1C | G77: =IF(O77="","",IF(LEFT(O77,1)="3",IFERROR(IF(VLOOKUP($A77&"V",Asignacion_3ros!$A$2:$G$9,6,FALSE)="",O77,VLOOKUP($A77&"V",Asignacion_3ros!$A$2:$G$9,6,FALSE)),O77),IF(LEFT(O77,1)="W",IFERROR(IF(INDEX($J$2:$J$76,MATCH(VALUE(MID(O77,2,3)),$A$2:$A$76,0))="",O77,INDEX($J$2:$J$76,MATCH(VALUE(MID(O77,2,3)),$A$2:$A$76,0))),O77),IF(LEFT(O77,1)="L",IFERROR(IF(INDEX($J$2:$J$76,MATCH(VALUE(MID(O77,2,3)),$A$2:$A$76,0))=INDEX($F$2:$F$76,MATCH(VALUE(MID(O77,2,3)),$A$2:$A$76,0)),INDEX($G$2:$G$76,MATCH(VALUE(MID(O77,2,3)),$A$2:$A$76,0)),IF(INDEX($J$2:$J$76,MATCH(VALUE(MID(O77,2,3)),$A$2:$A$76,0))=INDEX($G$2:$G$76,MATCH(VALUE(MID(O77,2,3)),$A$2:$A$76,0)),INDEX($F$2:$F$76,MATCH(VALUE(MID(O77,2,3)),$A$2:$A$76,0)),O77)),O77),IFERROR(IF(VLOOKUP(RIGHT(O77,1)&LEFT(O77,1),Clasificacion!$O$2:$Q$49,2,FALSE)="",O77,VLOOKUP(RIGHT(O77,1)&LEFT(O77,1),Clasificacion!$O$2:$Q$49,2,FALSE)),O77))))) -> 2F | J77: =IF(OR(H77="",I77=""),"",IF(H77>I77,F77,IF(I77>H77,G77,"Empate"))) | K77: Houston | L77: =IF(N77="","",IF(LEFT(N77,1)="3",IFERROR(IF(VLOOKUP($A77&"L",Asignacion_3ros!$A$2:$G$9,7,FALSE)="",N77,VLOOKUP($A77&"L",Asignacion_3ros!$A$2:$G$9,7,FALSE)),N77),IF(LEFT(N77,1)="W",IFERROR(IF(INDEX($J$2:$J$76,MATCH(VALUE(MID(N77,2,3)),$A$2:$A$76,0))=INDEX($F$2:$F$76,MATCH(VALUE(MID(N77,2,3)),$A$2:$A$76,0)),INDEX($L$2:$L$76,MATCH(VALUE(MID(N77,2,3)),$A$2:$A$76,0)),IF(INDEX($J$2:$J$76,MATCH(VALUE(MID(N77,2,3)),$A$2:$A$76,0))=INDEX($G$2:$G$76,MATCH(VALUE(MID(N77,2,3)),$A$2:$A$76,0)),INDEX($M$2:$M$76,MATCH(VALUE(MID(N77,2,3)),$A$2:$A$76,0)),N77)),N77),IF(LEFT(N77,1)="L",IFERROR(IF(INDEX($J$2:$J$76,MATCH(VALUE(MID(N77,2,3)),$A$2:$A$76,0))=INDEX($F$2:$F$76,MATCH(VALUE(MID(N77,2,3)),$A$2:$A$76,0)),INDEX($M$2:$M$76,MATCH(VALUE(MID(N77,2,3)),$A$2:$A$76,0)),IF(INDEX($J$2:$J$76,MATCH(VALUE(MID(N77,2,3)),$A$2:$A$76,0))=INDEX($G$2:$G$76,MATCH(VALUE(MID(N77,2,3)),$A$2:$A$76,0)),INDEX($L$2:$L$76,MATCH(VALUE(MID(N77,2,3)),$A$2:$A$76,0)),N77)),N77),IFERROR(IF(VLOOKUP(RIGHT(N77,1)&LEFT(N77,1),Clasificacion!$O$2:$Q$49,3,FALSE)="",N77,VLOOKUP(RIGHT(N77,1)&LEFT(N77,1),Clasificacion!$O$2:$Q$49,3,FALSE)),N77))))) -> 1C | M77: =IF(O77="","",IF(LEFT(O77,1)="3",IFERROR(IF(VLOOKUP($A77&"V",Asignacion_3ros!$A$2:$G$9,7,FALSE)="",O77,VLOOKUP($A77&"V",Asignacion_3ros!$A$2:$G$9,7,FALSE)),O77),IF(LEFT(O77,1)="W",IFERROR(IF(INDEX($J$2:$J$76,MATCH(VALUE(MID(O77,2,3)),$A$2:$A$76,0))=INDEX($F$2:$F$76,MATCH(VALUE(MID(O77,2,3)),$A$2:$A$76,0)),INDEX($L$2:$L$76,MATCH(VALUE(MID(O77,2,3)),$A$2:$A$76,0)),IF(INDEX($J$2:$J$76,MATCH(VALUE(MID(O77,2,3)),$A$2:$A$76,0))=INDEX($G$2:$G$76,MATCH(VALUE(MID(O77,2,3)),$A$2:$A$76,0)),INDEX($M$2:$M$76,MATCH(VALUE(MID(O77,2,3)),$A$2:$A$76,0)),O77)),O77),IF(LEFT(O77,1)="L",IFERROR(IF(INDEX($J$2:$J$76,MATCH(VALUE(MID(O77,2,3)),$A$2:$A$76,0))=INDEX($F$2:$F$76,MATCH(VALUE(MID(O77,2,3)),$A$2:$A$76,0)),INDEX($M$2:$M$76,MATCH(VALUE(MID(O77,2,3)),$A$2:$A$76,0)),IF(INDEX($J$2:$J$76,MATCH(VALUE(MID(O77,2,3)),$A$2:$A$76,0))=INDEX($G$2:$G$76,MATCH(VALUE(MID(O77,2,3)),$A$2:$A$76,0)),INDEX($L$2:$L$76,MATCH(VALUE(MID(O77,2,3)),$A$2:$A$76,0)),O77)),O77),IFERROR(IF(VLOOKUP(RIGHT(O77,1)&LEFT(O77,1),Clasificacion!$O$2:$Q$49,3,FALSE)="",O77,VLOOKUP(RIGHT(O77,1)&LEFT(O77,1),Clasificacion!$O$2:$Q$49,3,FALSE)),O77))))) -> 2F | N77: 1C | O77: 2F | P77: FIFA/CBS
A78: 77 | B78: 46202 | C78: 17:00 | D78: Ronda de 32 | F78: =IF(N78="","",IF(LEFT(N78,1)="3",IFERROR(IF(VLOOKUP($A78&"L",Asignacion_3ros!$A$2:$G$9,6,FALSE)="",N78,VLOOKUP($A78&"L",Asignacion_3ros!$A$2:$G$9,6,FALSE)),N78),IF(LEFT(N78,1)="W",IFERROR(IF(INDEX($J$2:$J$77,MATCH(VALUE(MID(N78,2,3)),$A$2:$A$77,0))="",N78,INDEX($J$2:$J$77,MATCH(VALUE(MID(N78,2,3)),$A$2:$A$77,0))),N78),IF(LEFT(N78,1)="L",IFERROR(IF(INDEX($J$2:$J$77,MATCH(VALUE(MID(N78,2,3)),$A$2:$A$77,0))=INDEX($F$2:$F$77,MATCH(VALUE(MID(N78,2,3)),$A$2:$A$77,0)),INDEX($G$2:$G$77,MATCH(VALUE(MID(N78,2,3)),$A$2:$A$77,0)),IF(INDEX($J$2:$J$77,MATCH(VALUE(MID(N78,2,3)),$A$2:$A$77,0))=INDEX($G$2:$G$77,MATCH(VALUE(MID(N78,2,3)),$A$2:$A$77,0)),INDEX($F$2:$F$77,MATCH(VALUE(MID(N78,2,3)),$A$2:$A$77,0)),N78)),N78),IFERROR(IF(VLOOKUP(RIGHT(N78,1)&LEFT(N78,1),Clasificacion!$O$2:$Q$49,2,FALSE)="",N78,VLOOKUP(RIGHT(N78,1)&LEFT(N78,1),Clasificacion!$O$2:$Q$49,2,FALSE)),N78))))) -> 1I | G78: =IF(O78="","",IF(LEFT(O78,1)="3",IFERROR(IF(VLOOKUP($A78&"V",Asignacion_3ros!$A$2:$G$9,6,FALSE)="",O78,VLOOKUP($A78&"V",Asignacion_3ros!$A$2:$G$9,6,FALSE)),O78),IF(LEFT(O78,1)="W",IFERROR(IF(INDEX($J$2:$J$77,MATCH(VALUE(MID(O78,2,3)),$A$2:$A$77,0))="",O78,INDEX($J$2:$J$77,MATCH(VALUE(MID(O78,2,3)),$A$2:$A$77,0))),O78),IF(LEFT(O78,1)="L",IFERROR(IF(INDEX($J$2:$J$77,MATCH(VALUE(MID(O78,2,3)),$A$2:$A$77,0))=INDEX($F$2:$F$77,MATCH(VALUE(MID(O78,2,3)),$A$2:$A$77,0)),INDEX($G$2:$G$77,MATCH(VALUE(MID(O78,2,3)),$A$2:$A$77,0)),IF(INDEX($J$2:$J$77,MATCH(VALUE(MID(O78,2,3)),$A$2:$A$77,0))=INDEX($G$2:$G$77,MATCH(VALUE(MID(O78,2,3)),$A$2:$A$77,0)),INDEX($F$2:$F$77,MATCH(VALUE(MID(O78,2,3)),$A$2:$A$77,0)),O78)),O78),IFERROR(IF(VLOOKUP(RIGHT(O78,1)&LEFT(O78,1),Clasificacion!$O$2:$Q$49,2,FALSE)="",O78,VLOOKUP(RIGHT(O78,1)&LEFT(O78,1),Clasificacion!$O$2:$Q$49,2,FALSE)),O78))))) -> Qatar | J78: =IF(OR(H78="",I78=""),"",IF(H78>I78,F78,IF(I78>H78,G78,"Empate"))) | K78: New York New Jersey | L78: =IF(N78="","",IF(LEFT(N78,1)="3",IFERROR(IF(VLOOKUP($A78&"L",Asignacion_3ros!$A$2:$G$9,7,FALSE)="",N78,VLOOKUP($A78&"L",Asignacion_3ros!$A$2:$G$9,7,FALSE)),N78),IF(LEFT(N78,1)="W",IFERROR(IF(INDEX($J$2:$J$77,MATCH(VALUE(MID(N78,2,3)),$A$2:$A$77,0))=INDEX($F$2:$F$77,MATCH(VALUE(MID(N78,2,3)),$A$2:$A$77,0)),INDEX($L$2:$L$77,MATCH(VALUE(MID(N78,2,3)),$A$2:$A$77,0)),IF(INDEX($J$2:$J$77,MATCH(VALUE(MID(N78,2,3)),$A$2:$A$77,0))=INDEX($G$2:$G$77,MATCH(VALUE(MID(N78,2,3)),$A$2:$A$77,0)),INDEX($M$2:$M$77,MATCH(VALUE(MID(N78,2,3)),$A$2:$A$77,0)),N78)),N78),IF(LEFT(N78,1)="L",IFERROR(IF(INDEX($J$2:$J$77,MATCH(VALUE(MID(N78,2,3)),$A$2:$A$77,0))=INDEX($F$2:$F$77,MATCH(VALUE(MID(N78,2,3)),$A$2:$A$77,0)),INDEX($M$2:$M$77,MATCH(VALUE(MID(N78,2,3)),$A$2:$A$77,0)),IF(INDEX($J$2:$J$77,MATCH(VALUE(MID(N78,2,3)),$A$2:$A$77,0))=INDEX($G$2:$G$77,MATCH(VALUE(MID(N78,2,3)),$A$2:$A$77,0)),INDEX($L$2:$L$77,MATCH(VALUE(MID(N78,2,3)),$A$2:$A$77,0)),N78)),N78),IFERROR(IF(VLOOKUP(RIGHT(N78,1)&LEFT(N78,1),Clasificacion!$O$2:$Q$49,3,FALSE)="",N78,VLOOKUP(RIGHT(N78,1)&LEFT(N78,1),Clasificacion!$O$2:$Q$49,3,FALSE)),N78))))) -> 1I | M78: =IF(O78="","",IF(LEFT(O78,1)="3",IFERROR(IF(VLOOKUP($A78&"V",Asignacion_3ros!$A$2:$G$9,7,FALSE)="",O78,VLOOKUP($A78&"V",Asignacion_3ros!$A$2:$G$9,7,FALSE)),O78),IF(LEFT(O78,1)="W",IFERROR(IF(INDEX($J$2:$J$77,MATCH(VALUE(MID(O78,2,3)),$A$2:$A$77,0))=INDEX($F$2:$F$77,MATCH(VALUE(MID(O78,2,3)),$A$2:$A$77,0)),INDEX($L$2:$L$77,MATCH(VALUE(MID(O78,2,3)),$A$2:$A$77,0)),IF(INDEX($J$2:$J$77,MATCH(VALUE(MID(O78,2,3)),$A$2:$A$77,0))=INDEX($G$2:$G$77,MATCH(VALUE(MID(O78,2,3)),$A$2:$A$77,0)),INDEX($M$2:$M$77,MATCH(VALUE(MID(O78,2,3)),$A$2:$A$77,0)),O78)),O78),IF(LEFT(O78,1)="L",IFERROR(IF(INDEX($J$2:$J$77,MATCH(VALUE(MID(O78,2,3)),$A$2:$A$77,0))=INDEX($F$2:$F$77,MATCH(VALUE(MID(O78,2,3)),$A$2:$A$77,0)),INDEX($M$2:$M$77,MATCH(VALUE(MID(O78,2,3)),$A$2:$A$77,0)),IF(INDEX($J$2:$J$77,MATCH(VALUE(MID(O78,2,3)),$A$2:$A$77,0))=INDEX($G$2:$G$77,MATCH(VALUE(MID(O78,2,3)),$A$2:$A$77,0)),INDEX($L$2:$L$77,MATCH(VALUE(MID(O78,2,3)),$A$2:$A$77,0)),O78)),O78),IFERROR(IF(VLOOKUP(RIGHT(O78,1)&LEFT(O78,1),Clasificacion!$O$2:$Q$49,3,FALSE)="",O78,VLOOKUP(RIGHT(O78,1)&LEFT(O78,1),Clasificacion!$O$2:$Q$49,3,FALSE)),O78))))) -> QAT | N78: 1I | O78: 3C/D/F/G/H | P78: FIFA/CBS
A79: 78 | B79: 46203 | C79: 13:00 | D79: Ronda de 32 | F79: =IF(N79="","",IF(LEFT(N79,1)="3",IFERROR(IF(VLOOKUP($A79&"L",Asignacion_3ros!$A$2:$G$9,6,FALSE)="",N79,VLOOKUP($A79&"L",Asignacion_3ros!$A$2:$G$9,6,FALSE)),N79),IF(LEFT(N79,1)="W",IFERROR(IF(INDEX($J$2:$J$78,MATCH(VALUE(MID(N79,2,3)),$A$2:$A$78,0))="",N79,INDEX($J$2:$J$78,MATCH(VALUE(MID(N79,2,3)),$A$2:$A$78,0))),N79),IF(LEFT(N79,1)="L",IFERROR(IF(INDEX($J$2:$J$78,MATCH(VALUE(MID(N79,2,3)),$A$2:$A$78,0))=INDEX($F$2:$F$78,MATCH(VALUE(MID(N79,2,3)),$A$2:$A$78,0)),INDEX($G$2:$G$78,MATCH(VALUE(MID(N79,2,3)),$A$2:$A$78,0)),IF(INDEX($J$2:$J$78,MATCH(VALUE(MID(N79,2,3)),$A$2:$A$78,0))=INDEX($G$2:$G$78,MATCH(VALUE(MID(N79,2,3)),$A$2:$A$78,0)),INDEX($F$2:$F$78,MATCH(VALUE(MID(N79,2,3)),$A$2:$A$78,0)),N79)),N79),IFERROR(IF(VLOOKUP(RIGHT(N79,1)&LEFT(N79,1),Clasificacion!$O$2:$Q$49,2,FALSE)="",N79,VLOOKUP(RIGHT(N79,1)&LEFT(N79,1),Clasificacion!$O$2:$Q$49,2,FALSE)),N79))))) -> 2E | G79: =IF(O79="","",IF(LEFT(O79,1)="3",IFERROR(IF(VLOOKUP($A79&"V",Asignacion_3ros!$A$2:$G$9,6,FALSE)="",O79,VLOOKUP($A79&"V",Asignacion_3ros!$A$2:$G$9,6,FALSE)),O79),IF(LEFT(O79,1)="W",IFERROR(IF(INDEX($J$2:$J$78,MATCH(VALUE(MID(O79,2,3)),$A$2:$A$78,0))="",O79,INDEX($J$2:$J$78,MATCH(VALUE(MID(O79,2,3)),$A$2:$A$78,0))),O79),IF(LEFT(O79,1)="L",IFERROR(IF(INDEX($J$2:$J$78,MATCH(VALUE(MID(O79,2,3)),$A$2:$A$78,0))=INDEX($F$2:$F$78,MATCH(VALUE(MID(O79,2,3)),$A$2:$A$78,0)),INDEX($G$2:$G$78,MATCH(VALUE(MID(O79,2,3)),$A$2:$A$78,0)),IF(INDEX($J$2:$J$78,MATCH(VALUE(MID(O79,2,3)),$A$2:$A$78,0))=INDEX($G$2:$G$78,MATCH(VALUE(MID(O79,2,3)),$A$2:$A$78,0)),INDEX($F$2:$F$78,MATCH(VALUE(MID(O79,2,3)),$A$2:$A$78,0)),O79)),O79),IFERROR(IF(VLOOKUP(RIGHT(O79,1)&LEFT(O79,1),Clasificacion!$O$2:$Q$49,2,FALSE)="",O79,VLOOKUP(RIGHT(O79,1)&LEFT(O79,1),Clasificacion!$O$2:$Q$49,2,FALSE)),O79))))) -> 2I | J79: =IF(OR(H79="",I79=""),"",IF(H79>I79,F79,IF(I79>H79,G79,"Empate"))) | K79: Dallas | L79: =IF(N79="","",IF(LEFT(N79,1)="3",IFERROR(IF(VLOOKUP($A79&"L",Asignacion_3ros!$A$2:$G$9,7,FALSE)="",N79,VLOOKUP($A79&"L",Asignacion_3ros!$A$2:$G$9,7,FALSE)),N79),IF(LEFT(N79,1)="W",IFERROR(IF(INDEX($J$2:$J$78,MATCH(VALUE(MID(N79,2,3)),$A$2:$A$78,0))=INDEX($F$2:$F$78,MATCH(VALUE(MID(N79,2,3)),$A$2:$A$78,0)),INDEX($L$2:$L$78,MATCH(VALUE(MID(N79,2,3)),$A$2:$A$78,0)),IF(INDEX($J$2:$J$78,MATCH(VALUE(MID(N79,2,3)),$A$2:$A$78,0))=INDEX($G$2:$G$78,MATCH(VALUE(MID(N79,2,3)),$A$2:$A$78,0)),INDEX($M$2:$M$78,MATCH(VALUE(MID(N79,2,3)),$A$2:$A$78,0)),N79)),N79),IF(LEFT(N79,1)="L",IFERROR(IF(INDEX($J$2:$J$78,MATCH(VALUE(MID(N79,2,3)),$A$2:$A$78,0))=INDEX($F$2:$F$78,MATCH(VALUE(MID(N79,2,3)),$A$2:$A$78,0)),INDEX($M$2:$M$78,MATCH(VALUE(MID(N79,2,3)),$A$2:$A$78,0)),IF(INDEX($J$2:$J$78,MATCH(VALUE(MID(N79,2,3)),$A$2:$A$78,0))=INDEX($G$2:$G$78,MATCH(VALUE(MID(N79,2,3)),$A$2:$A$78,0)),INDEX($L$2:$L$78,MATCH(VALUE(MID(N79,2,3)),$A$2:$A$78,0)),N79)),N79),IFERROR(IF(VLOOKUP(RIGHT(N79,1)&LEFT(N79,1),Clasificacion!$O$2:$Q$49,3,FALSE)="",N79,VLOOKUP(RIGHT(N79,1)&LEFT(N79,1),Clasificacion!$O$2:$Q$49,3,FALSE)),N79))))) -> 2E | M79: =IF(O79="","",IF(LEFT(O79,1)="3",IFERROR(IF(VLOOKUP($A79&"V",Asignacion_3ros!$A$2:$G$9,7,FALSE)="",O79,VLOOKUP($A79&"V",Asignacion_3ros!$A$2:$G$9,7,FALSE)),O79),IF(LEFT(O79,1)="W",IFERROR(IF(INDEX($J$2:$J$78,MATCH(VALUE(MID(O79,2,3)),$A$2:$A$78,0))=INDEX($F$2:$F$78,MATCH(VALUE(MID(O79,2,3)),$A$2:$A$78,0)),INDEX($L$2:$L$78,MATCH(VALUE(MID(O79,2,3)),$A$2:$A$78,0)),IF(INDEX($J$2:$J$78,MATCH(VALUE(MID(O79,2,3)),$A$2:$A$78,0))=INDEX($G$2:$G$78,MATCH(VALUE(MID(O79,2,3)),$A$2:$A$78,0)),INDEX($M$2:$M$78,MATCH(VALUE(MID(O79,2,3)),$A$2:$A$78,0)),O79)),O79),IF(LEFT(O79,1)="L",IFERROR(IF(INDEX($J$2:$J$78,MATCH(VALUE(MID(O79,2,3)),$A$2:$A$78,0))=INDEX($F$2:$F$78,MATCH(VALUE(MID(O79,2,3)),$A$2:$A$78,0)),INDEX($M$2:$M$78,MATCH(VALUE(MID(O79,2,3)),$A$2:$A$78,0)),IF(INDEX($J$2:$J$78,MATCH(VALUE(MID(O79,2,3)),$A$2:$A$78,0))=INDEX($G$2:$G$78,MATCH(VALUE(MID(O79,2,3)),$A$2:$A$78,0)),INDEX($L$2:$L$78,MATCH(VALUE(MID(O79,2,3)),$A$2:$A$78,0)),O79)),O79),IFERROR(IF(VLOOKUP(RIGHT(O79,1)&LEFT(O79,1),Clasificacion!$O$2:$Q$49,3,FALSE)="",O79,VLOOKUP(RIGHT(O79,1)&LEFT(O79,1),Clasificacion!$O$2:$Q$49,3,FALSE)),O79))))) -> 2I | N79: 2E | O79: 2I | P79: FIFA/CBS
A80: 79 | B80: 46203 | C80: 21:00 | D80: Ronda de 32 | F80: =IF(N80="","",IF(LEFT(N80,1)="3",IFERROR(IF(VLOOKUP($A80&"L",Asignacion_3ros!$A$2:$G$9,6,FALSE)="",N80,VLOOKUP($A80&"L",Asignacion_3ros!$A$2:$G$9,6,FALSE)),N80),IF(LEFT(N80,1)="W",IFERROR(IF(INDEX($J$2:$J$79,MATCH(VALUE(MID(N80,2,3)),$A$2:$A$79,0))="",N80,INDEX($J$2:$J$79,MATCH(VALUE(MID(N80,2,3)),$A$2:$A$79,0))),N80),IF(LEFT(N80,1)="L",IFERROR(IF(INDEX($J$2:$J$79,MATCH(VALUE(MID(N80,2,3)),$A$2:$A$79,0))=INDEX($F$2:$F$79,MATCH(VALUE(MID(N80,2,3)),$A$2:$A$79,0)),INDEX($G$2:$G$79,MATCH(VALUE(MID(N80,2,3)),$A$2:$A$79,0)),IF(INDEX($J$2:$J$79,MATCH(VALUE(MID(N80,2,3)),$A$2:$A$79,0))=INDEX($G$2:$G$79,MATCH(VALUE(MID(N80,2,3)),$A$2:$A$79,0)),INDEX($F$2:$F$79,MATCH(VALUE(MID(N80,2,3)),$A$2:$A$79,0)),N80)),N80),IFERROR(IF(VLOOKUP(RIGHT(N80,1)&LEFT(N80,1),Clasificacion!$O$2:$Q$49,2,FALSE)="",N80,VLOOKUP(RIGHT(N80,1)&LEFT(N80,1),Clasificacion!$O$2:$Q$49,2,FALSE)),N80))))) -> 1A | G80: =IF(O80="","",IF(LEFT(O80,1)="3",IFERROR(IF(VLOOKUP($A80&"V",Asignacion_3ros!$A$2:$G$9,6,FALSE)="",O80,VLOOKUP($A80&"V",Asignacion_3ros!$A$2:$G$9,6,FALSE)),O80),IF(LEFT(O80,1)="W",IFERROR(IF(INDEX($J$2:$J$79,MATCH(VALUE(MID(O80,2,3)),$A$2:$A$79,0))="",O80,INDEX($J$2:$J$79,MATCH(VALUE(MID(O80,2,3)),$A$2:$A$79,0))),O80),IF(LEFT(O80,1)="L",IFERROR(IF(INDEX($J$2:$J$79,MATCH(VALUE(MID(O80,2,3)),$A$2:$A$79,0))=INDEX($F$2:$F$79,MATCH(VALUE(MID(O80,2,3)),$A$2:$A$79,0)),INDEX($G$2:$G$79,MATCH(VALUE(MID(O80,2,3)),$A$2:$A$79,0)),IF(INDEX($J$2:$J$79,MATCH(VALUE(MID(O80,2,3)),$A$2:$A$79,0))=INDEX($G$2:$G$79,MATCH(VALUE(MID(O80,2,3)),$A$2:$A$79,0)),INDEX($F$2:$F$79,MATCH(VALUE(MID(O80,2,3)),$A$2:$A$79,0)),O80)),O80),IFERROR(IF(VLOOKUP(RIGHT(O80,1)&LEFT(O80,1),Clasificacion!$O$2:$Q$49,2,FALSE)="",O80,VLOOKUP(RIGHT(O80,1)&LEFT(O80,1),Clasificacion!$O$2:$Q$49,2,FALSE)),O80))))) -> Suiza | J80: =IF(OR(H80="",I80=""),"",IF(H80>I80,F80,IF(I80>H80,G80,"Empate"))) | K80: Mexico City | L80: =IF(N80="","",IF(LEFT(N80,1)="3",IFERROR(IF(VLOOKUP($A80&"L",Asignacion_3ros!$A$2:$G$9,7,FALSE)="",N80,VLOOKUP($A80&"L",Asignacion_3ros!$A$2:$G$9,7,FALSE)),N80),IF(LEFT(N80,1)="W",IFERROR(IF(INDEX($J$2:$J$79,MATCH(VALUE(MID(N80,2,3)),$A$2:$A$79,0))=INDEX($F$2:$F$79,MATCH(VALUE(MID(N80,2,3)),$A$2:$A$79,0)),INDEX($L$2:$L$79,MATCH(VALUE(MID(N80,2,3)),$A$2:$A$79,0)),IF(INDEX($J$2:$J$79,MATCH(VALUE(MID(N80,2,3)),$A$2:$A$79,0))=INDEX($G$2:$G$79,MATCH(VALUE(MID(N80,2,3)),$A$2:$A$79,0)),INDEX($M$2:$M$79,MATCH(VALUE(MID(N80,2,3)),$A$2:$A$79,0)),N80)),N80),IF(LEFT(N80,1)="L",IFERROR(IF(INDEX($J$2:$J$79,MATCH(VALUE(MID(N80,2,3)),$A$2:$A$79,0))=INDEX($F$2:$F$79,MATCH(VALUE(MID(N80,2,3)),$A$2:$A$79,0)),INDEX($M$2:$M$79,MATCH(VALUE(MID(N80,2,3)),$A$2:$A$79,0)),IF(INDEX($J$2:$J$79,MATCH(VALUE(MID(N80,2,3)),$A$2:$A$79,0))=INDEX($G$2:$G$79,MATCH(VALUE(MID(N80,2,3)),$A$2:$A$79,0)),INDEX($L$2:$L$79,MATCH(VALUE(MID(N80,2,3)),$A$2:$A$79,0)),N80)),N80),IFERROR(IF(VLOOKUP(RIGHT(N80,1)&LEFT(N80,1),Clasificacion!$O$2:$Q$49,3,FALSE)="",N80,VLOOKUP(RIGHT(N80,1)&LEFT(N80,1),Clasificacion!$O$2:$Q$49,3,FALSE)),N80))))) -> 1A | M80: =IF(O80="","",IF(LEFT(O80,1)="3",IFERROR(IF(VLOOKUP($A80&"V",Asignacion_3ros!$A$2:$G$9,7,FALSE)="",O80,VLOOKUP($A80&"V",Asignacion_3ros!$A$2:$G$9,7,FALSE)),O80),IF(LEFT(O80,1)="W",IFERROR(IF(INDEX($J$2:$J$79,MATCH(VALUE(MID(O80,2,3)),$A$2:$A$79,0))=INDEX($F$2:$F$79,MATCH(VALUE(MID(O80,2,3)),$A$2:$A$79,0)),INDEX($L$2:$L$79,MATCH(VALUE(MID(O80,2,3)),$A$2:$A$79,0)),IF(INDEX($J$2:$J$79,MATCH(VALUE(MID(O80,2,3)),$A$2:$A$79,0))=INDEX($G$2:$G$79,MATCH(VALUE(MID(O80,2,3)),$A$2:$A$79,0)),INDEX($M$2:$M$79,MATCH(VALUE(MID(O80,2,3)),$A$2:$A$79,0)),O80)),O80),IF(LEFT(O80,1)="L",IFERROR(IF(INDEX($J$2:$J$79,MATCH(VALUE(MID(O80,2,3)),$A$2:$A$79,0))=INDEX($F$2:$F$79,MATCH(VALUE(MID(O80,2,3)),$A$2:$A$79,0)),INDEX($M$2:$M$79,MATCH(VALUE(MID(O80,2,3)),$A$2:$A$79,0)),IF(INDEX($J$2:$J$79,MATCH(VALUE(MID(O80,2,3)),$A$2:$A$79,0))=INDEX($G$2:$G$79,MATCH(VALUE(MID(O80,2,3)),$A$2:$A$79,0)),INDEX($L$2:$L$79,MATCH(VALUE(MID(O80,2,3)),$A$2:$A$79,0)),O80)),O80),IFERROR(IF(VLOOKUP(RIGHT(O80,1)&LEFT(O80,1),Clasificacion!$O$2:$Q$49,3,FALSE)="",O80,VLOOKUP(RIGHT(O80,1)&LEFT(O80,1),Clasificacion!$O$2:$Q$49,3,FALSE)),O80))))) -> SUI | N80: 1A | O80: 3C/E/F/H/I | P80: FIFA/CBS
