Workbook

Sheet Portada
A1: Mundial FIFA 2026 - Calendario y clasificación
A3: Uso
A4: 1 | B4: Escribe los goles en la hoja Partidos, columnas H e I. Las tablas se recalculan automáticamente.
A5: 2 | B5: Las posiciones de grupo están identificadas como A1, A2, A3, A4, etc.
A6: 3 | B6: Los cruces de eliminatoria usan placeholders oficiales: 1A, 2B, 3C/D/E, W74, etc.
A7: 4 | B7: La hoja Clasificacion calcula puntos, goles y posición básica; al inicio conserva el orden A1-A4 por grupo.
A8: 5 | B8: La columna Desempate manual permite resolver empates complejos de FIFA: mayor número = mejor desempate.
A9: 6 | B9: Horarios en Eastern Time (ET), como en el calendario de FIFA/CBS.
A11: Contenido
A12: Equipos_Grupos | B12: Listado de grupos, posiciones y códigos.
A13: Partidos | B13: Los 104 partidos, con columnas para ingresar resultados.
A14: Clasificacion | B14: Tabla automática por grupo.
A15: Mejores_Terceros | B15: Ranking automático de los terceros lugares.
A16: Llaves | B16: Resumen del cuadro eliminatorio con placeholders.
A17: Fuentes | B17: URLs usadas para armar el archivo.
A18: Notas | B18: El calendario está sujeto a cambios por FIFA.

Sheet Equipos_Grupos
A1: Grupo | B1: Posición | C1: Código | D1: Equipo
A2: A | B2: A1 | C2: MEX | D2: México
A3: A | B3: A2 | C3: RSA | D3: Sudáfrica
A4: A | B4: A3 | C4: KOR | D4: Corea República
A5: A | B5: A4 | C5: CZE | D5: Chequia
A6: B | B6: B1 | C6: CAN | D6: Canadá
A7: B | B7: B2 | C7: BIH | D7: Bosnia y Herzegovina
A8: B | B8: B3 | C8: QAT | D8: Qatar
A9: B | B9: B4 | C9: SUI | D9: Suiza
A10: C | B10: C1 | C10: BRA | D10: Brasil
A11: C | B11: C2 | C11: MAR | D11: Marruecos
A12: C | B12: C3 | C12: HAI | D12: Haití
... A49: L | B49: L4 | C49: PAN | D49: Panamá

Sheet Puntajes
A1: Número | B1: Posición | C1: Nombre | D1: Puntaje | F1: =NOW() -> 46185.263 | L1: _Nombre | M1: _Numero | N1: _Puntaje | O1: _Key | P1: _Rank
A2: =INDEX($M$2:$M$50,SUMPRODUCT(($P$2:$P$50=1)*ROW($M$2:$M$50))-1) -> 11 | B2: 1 | C2: =INDEX($L$2:$L$50,SUMPRODUCT(($P$2:$P$50=1)*ROW($L$2:$L$50))-1) -> Edward | D2: =INDEX($N$2:$N$50,SUMPRODUCT(($P$2:$P$50=1)*ROW($N$2:$N$50))-1) -> 6 | L2: =Grupo!A3 -> Alberto | M2: =Participantes!A2 -> 1 | N2: =Grupo!HJ3 -> 1 | O2: =N2*100-ROW() -> 98 | P2: =SUMPRODUCT(($O$2:$O$50>O2)*1)+1 -> 32
A3: =INDEX($M$2:$M$50,SUMPRODUCT(($P$2:$P$50=2)*ROW($M$2:$M$50))-1) -> 30 | B3: =IF(D3=D2,B2,B2+1) -> 1 | C3: =INDEX($L$2:$L$50,SUMPRODUCT(($P$2:$P$50=2)*ROW($L$2:$L$50))-1) -> Luis Peña | D3: =INDEX($N$2:$N$50,SUMPRODUCT(($P$2:$P$50=2)*ROW($N$2:$N$50))-1) -> 6 | L3: =Grupo!A4 -> Alexander | M3: =Participantes!A3 -> 2 | N3: =Grupo!HJ4 -> 3 | O3: =N3*100-ROW() -> 297 | P3: =SUMPRODUCT(($O$2:$O$50>O3)*1)+1 -> 13
A4: =INDEX($M$2:$M$50,SUMPRODUCT(($P$2:$P$50=3)*ROW($M$2:$M$50))-1) -> 33 | B4: =IF(D4=D3,B3,B3+1) -> 1 | C4: =INDEX($L$2:$L$50,SUMPRODUCT(($P$2:$P$50=3)*ROW($L$2:$L$50))-1) -> Marilyn | D4: =INDEX($N$2:$N$50,SUMPRODUCT(($P$2:$P$50=3)*ROW($N$2:$N$50))-1) -> 6 | L4: =Grupo!A5 -> Alfredo 1 | M4: =Participantes!A4 -> 3 | N4: =Grupo!HJ5 -> 1 | O4: =N4*100-ROW() -> 96 | P4: =SUMPRODUCT(($O$2:$O$50>O4)*1)+1 -> 33
A5: =INDEX($M$2:$M$50,SUMPRODUCT(($P$2:$P$50=4)*ROW($M$2:$M$50))-1) -> 8 | B5: =IF(D5=D4,B4,B4+1) -> 2 | C5: =INDEX($L$2:$L$50,SUMPRODUCT(($P$2:$P$50=4)*ROW($L$2:$L$50))-1) -> Castillo L. | D5: =INDEX($N$2:$N$50,SUMPRODUCT(($P$2:$P$50=4)*ROW($N$2:$N$50))-1) -> 4 | L5: =Grupo!A6 -> Alfredo 2 | M5: =Participantes!A5 -> 4 | N5: =Grupo!HJ6 -> 3 | O5: =N5*100-ROW() -> 295 | P5: =SUMPRODUCT(($O$2:$O$50>O5)*1)+1 -> 14
A6: =INDEX($M$2:$M$50,SUMPRODUCT(($P$2:$P$50=5)*ROW($M$2:$M$50))-1) -> 17 | B6: =IF(D6=D5,B5,B5+1) -> 2 | C6: =INDEX($L$2:$L$50,SUMPRODUCT(($P$2:$P$50=5)*ROW($L$2:$L$50))-1) -> Javier | D6: =INDEX($N$2:$N$50,SUMPRODUCT(($P$2:$P$50=5)*ROW($N$2:$N$50))-1) -> 4 | L6: =Grupo!A7 -> Aneth | M6: =Participantes!A6 -> 5 | N6: =Grupo!HJ7 -> 3 | O6: =N6*100-ROW() -> 294 | P6: =SUMPRODUCT(($O$2:$O$50>O6)*1)+1 -> 15
A7: =INDEX($M$2:$M$50,SUMPRODUCT(($P$2:$P$50=6)*ROW($M$2:$M$50))-1) -> 19 | B7: =IF(D7=D6,B6,B6+1) -> 2 | C7: =INDEX($L$2:$L$50,SUMPRODUCT(($P$2:$P$50=6)*ROW($L$2:$L$50))-1) -> Jose C 2 | D7: =INDEX($N$2:$N$50,SUMPRODUCT(($P$2:$P$50=6)*ROW($N$2:$N$50))-1) -> 4 | L7: =Grupo!A8 -> Antonio | M7: =Participantes!A7 -> 6 | N7: =Grupo!HJ8 -> 3 | O7: =N7*100-ROW() -> 293 | P7: =SUMPRODUCT(($O$2:$O$50>O7)*1)+1 -> 16
A8: =INDEX($M$2:$M$50,SUMPRODUCT(($P$2:$P$50=7)*ROW($M$2:$M$50))-1) -> 20 | B8: =IF(D8=D7,B7,B7+1) -> 2 | C8: =INDEX($L$2:$L$50,SUMPRODUCT(($P$2:$P$50=7)*ROW($L$2:$L$50))-1) -> Jose C Ahiza | D8: =INDEX($N$2:$N$50,SUMPRODUCT(($P$2:$P$50=7)*ROW($N$2:$N$50))-1) -> 4 | L8: =Grupo!A9 -> Carlos | M8: =Participantes!A8 -> 7 | N8: =Grupo!HJ9 -> 1 | O8: =N8*100-ROW() -> 92 | P8: =SUMPRODUCT(($O$2:$O$50>O8)*1)+1 -> 34
A9: =INDEX($M$2:$M$50,SUMPRODUCT(($P$2:$P$50=8)*ROW($M$2:$M$50))-1) -> 23 | B9: =IF(D9=D8,B8,B8+1) -> 2 | C9: =INDEX($L$2:$L$50,SUMPRODUCT(($P$2:$P$50=8)*ROW($L$2:$L$50))-1) -> José de León | D9: =INDEX($N$2:$N$50,SUMPRODUCT(($P$2:$P$50=8)*ROW($N$2:$N$50))-1) -> 4 | G9: =Partidos!G2 -> México | H9: =Partidos!H2 -> Sudáfrica | J9: =Partidos!C2 -> 0.58333333 | L9: =Grupo!A10 -> Castillo L. | M9: =Participantes!A9 -> 8 | N9: =Grupo!HJ10 -> 4 | O9: =N9*100-ROW() -> 391 | P9: =SUMPRODUCT(($O$2:$O$50>O9)*1)+1 -> 4
A10: =INDEX($M$2:$M$50,SUMPRODUCT(($P$2:$P$50=9)*ROW($M$2:$M$50))-1) -> 35 | B10: =IF(D10=D9,B9,B9+1) -> 2 | C10: =INDEX($L$2:$L$50,SUMPRODUCT(($P$2:$P$50=9)*ROW($L$2:$L$50))-1) -> Milagros | D10: =INDEX($N$2:$N$50,SUMPRODUCT(($P$2:$P$50=9)*ROW($N$2:$N$50))-1) -> 4 | G10: =Partidos!I2 -> 2 | H10: =Partidos!J2 -> 0 | L10: =Grupo!A11 -> Christofer | M10: =Participantes!A10 -> 9 | N10: =Grupo!HJ11 -> 0 | O10: =N10*100-ROW() -> -10 | P10: =SUMPRODUCT(($O$2:$O$50>O10)*1)+1 -> 48
A11: =INDEX($M$2:$M$50,SUMPRODUCT(($P$2:$P$50=10)*ROW($M$2:$M$50))-1) -> 36 | B11: =IF(D11=D10,B10,B10+1) -> 2 | C11: =INDEX($L$2:$L$50,SUMPRODUCT(($P$2:$P$50=10)*ROW($L$2:$L$50))-1) -> Mily CF 1 | D11: =INDEX($N$2:$N$50,SUMPRODUCT(($P$2:$P$50=10)*ROW($N$2:$N$50))-1) -> 4 | L11: =Grupo!A12 -> Cynthia | M11: =Participantes!A11 -> 10 | N11: =Grupo!HJ12 -> 1 | O11: =N11*100-ROW() -> 89 | P11: =SUMPRODUCT(($O$2:$O$50>O11)*1)+1 -> 35
A12: =INDEX($M$2:$M$50,SUMPRODUCT(($P$2:$P$50=11)*ROW($M$2:$M$50))-1) -> 42 | B12: =IF(D12=D11,B11,B11+1) -> 2 | C12: =INDEX($L$2:$L$50,SUMPRODUCT(($P$2:$P$50=11)*ROW($L$2:$L$50))-1) -> Osvaldo | D12: =INDEX($N$2:$N$50,SUMPRODUCT(($P$2:$P$50=11)*ROW($N$2:$N$50))-1) -> 4 | G12: =Partidos!G3 -> Corea República | H12: =Partidos!H3 -> Chequia | J12: =Partidos!C3 -> 0.875 | L12: =Grupo!A13 -> Edward | M12: =Participantes!A12 -> 11 | N12: =Grupo!HJ13 -> 6 | O12: =N12*100-ROW() -> 588 | P12: =SUMPRODUCT(($O$2:$O$50>O12)*1)+1 -> 1
A13: =INDEX($M$2:$M$50,SUMPRODUCT(($P$2:$P$50=12)*ROW($M$2:$M$50))-1) -> 43 | B13: =IF(D13=D12,B12,B12+1) -> 2 | C13: =INDEX($L$2:$L$50,SUMPRODUCT(($P$2:$P$50=12)*ROW($L$2:$L$50))-1) -> Peter | D13: =INDEX($N$2:$N$50,SUMPRODUCT(($P$2:$P$50=12)*ROW($N$2:$N$50))-1) -> 4 | G13: =Partidos!I3 -> 2 | H13: =Partidos!J3 -> 1 | L13: =Grupo!A14 -> Espinosa L. | M13: =Participantes!A13 -> 12 | N13: =Grupo!HJ14 -> 2 | O13: =N13*100-ROW() -> 187 | P13: =SUMPRODUCT(($O$2:$O$50>O13)*1)+1 -> 27
A14: =INDEX($M$2:$M$50,SUMPRODUCT(($P$2:$P$50=13)*ROW($M$2:$M$50))-1) -> 2 | B14: =IF(D14=D13,B13,B13+1) -> 3 | C14: =INDEX($L$2:$L$50,SUMPRODUCT(($P$2:$P$50=13)*ROW($L$2:$L$50))-1) -> Alexander | D14: =INDEX($N$2:$N$50,SUMPRODUCT(($P$2:$P$50=13)*ROW($N$2:$N$50))-1) -> 3 | L14: =Grupo!A15 -> Freddy | M14: =Participantes!A14 -> 13 | N14: =Grupo!HJ15 -> 1 | O14: =N14*100-ROW() -> 86 | P14: =SUMPRODUCT(($O$2:$O$50>O14)*1)+1 -> 36
A15: =INDEX($M$2:$M$50,SUMPRODUCT(($P$2:$P$50=14)*ROW($M$2:$M$50))-1) -> 4 | B15: =IF(D15=D14,B14,B14+1) -> 3 | C15: =INDEX($L$2:$L$50,SUMPRODUCT(($P$2:$P$50=14)*ROW($L$2:$L$50))-1) -> Alfredo 2 | D15: =INDEX($N$2:$N$50,SUMPRODUCT(($P$2:$P$50=14)*ROW($N$2:$N$50))-1) -> 3 | L15: =Grupo!A16 -> Isabel 1 | M15: =Participantes!A15 -> 15 | N15: =Grupo!HJ16 -> 1 | O15: =N15*100-ROW() -> 85 | P15: =SUMPRODUCT(($O$2:$O$50>O15)*1)+1 -> 37
A16: =INDEX($M$2:$M$50,SUMPRODUCT(($P$2:$P$50=15)*ROW($M$2:$M$50))-1) -> 5 | B16: =IF(D16=D15,B15,B15+1) -> 3 | C16: =INDEX($L$2:$L$50,SUMPRODUCT(($P$2:$P$50=15)*ROW($L$2:$L$50))-1) -> Aneth | D16: =INDEX($N$2:$N$50,SUMPRODUCT(($P$2:$P$50=15)*ROW($N$2:$N$50))-1) -> 3 | L16: =Grupo!A17 -> Isabel 2 | M16: =Participantes!A16 -> 16 | N16: =Grupo!HJ17 -> 2 | O16: =N16*100-ROW() -> 184 | P16: =SUMPRODUCT(($O$2:$O$50>O16)*1)+1 -> 28
A17: =INDEX($M$2:$M$50,SUMPRODUCT(($P$2:$P$50=16)*ROW($M$2:$M$50))-1) -> 6 | B17: =IF(D17=D16,B16,B16+1) -> 3 | C17: =INDEX($L$2:$L$50,SUMPRODUCT(($P$2:$P$50=16)*ROW($L$2:$L$50))-1) -> Antonio | D17: =INDEX($N$2:$N$50,SUMPRODUCT(($P$2:$P$50=16)*ROW($N$2:$N$50))-1) -> 3 | L17: =Grupo!A18 -> Javier | M17: =Participantes!A17 -> 17 | N17: =Grupo!HJ18 -> 4 | O17: =N17*100-ROW() -> 383 | P17: =SUMPRODUCT(($O$2:$O$50>O17)*1)+1 -> 5
A18: =INDEX($M$2:$M$50,SUMPRODUCT(($P$2:$P$50=17)*ROW($M$2:$M$50))-1) -> 27 | B18: =IF(D18=D17,B17,B17+1) -> 3 | C18: =INDEX($L$2:$L$50,SUMPRODUCT(($P$2:$P$50=17)*ROW($L$2:$L$50))-1) -> Kattia 2 | D18: =INDEX($N$2:$N$50,SUMPRODUCT(($P$2:$P$50=17)*ROW($N$2:$N$50))-1) -> 3 | L18: =Grupo!A19 -> Jose C 1 | M18: =Participantes!A18 -> 18 | N18: =Grupo!HJ19 -> 0 | O18: =N18*100-ROW() -> -18 | P18: =SUMPRODUCT(($O$2:$O$50>O18)*1)+1 -> 49
A19: =INDEX($M$2:$M$50,SUMPRODUCT(($P$2:$P$50=18)*ROW($M$2:$M$50))-1) -> 28 | B19: =IF(D19=D18,B18,B18+1) -> 3 | C19: =INDEX($L$2:$L$50,SUMPRODUCT(($P$2:$P$50=18)*ROW($L$2:$L$50))-1) -> Kevin | D19: =INDEX($N$2:$N$50,SUMPRODUCT(($P$2:$P$50=18)*ROW($N$2:$N$50))-1) -> 3 | L19: =Grupo!A20 -> Jose C 2 | M19: =Participantes!A19 -> 19 | N19: =Grupo!HJ20 -> 4 | O19: =N19*100-ROW() -> 381 | P19: =SUMPRODUCT(($O$2:$O$50>O19)*1)+1 -> 6
A20: =INDEX($M$2:$M$50,SUMPRODUCT(($P$2:$P$50=19)*ROW($M$2:$M$50))-1) -> 29 | B20: =IF(D20=D19,B19,B19+1) -> 3 | C20: =INDEX($L$2:$L$50,SUMPRODUCT(($P$2:$P$50=19)*ROW($L$2:$L$50))-1) -> Lizka | D20: =INDEX($N$2:$N$50,SUMPRODUCT(($P$2:$P$50=19)*ROW($N$2:$N$50))-1) -> 3 | L20: =Grupo!A21 -> Jose C Ahiza | M20: =Participantes!A20 -> 20 | N20: =Grupo!HJ21 -> 4 | O20: =N20*100-ROW() -> 380 | P20: =SUMPRODUCT(($O$2:$O$50>O20)*1)+1 -> 7
A21: =INDEX($M$2:$M$50,SUMPRODUCT(($P$2:$P$50=20)*ROW($M$2:$M$50))-1) -> 14 | B21: =IF(D21=D20,B20,B20+1) -> 3 | C21: =INDEX($L$2:$L$50,SUMPRODUCT(($P$2:$P$50=20)*ROW($L$2:$L$50))-1) -> Mily Frida | D21: =INDEX($N$2:$N$50,SUMPRODUCT(($P$2:$P$50=20)*ROW($N$2:$N$50))-1) -> 3 | L21: =Grupo!A22 -> Jose C Ana | M21: =Participantes!A21 -> 21 | N21: =Grupo!HJ22 -> 2 | O21: =N21*100-ROW() -> 179 | P21: =SUMPRODUCT(($O$2:$O$50>O21)*1)+1 -> 29
A22: =INDEX($M$2:$M$50,SUMPRODUCT(($P$2:$P$50=21)*ROW($M$2:$M$50))-1) -> 38 | B22: =IF(D22=D21,B21,B21+1) -> 3 | C22: =INDEX($L$2:$L$50,SUMPRODUCT(($P$2:$P$50=21)*ROW($L$2:$L$50))-1) -> Mily Oliver | D22: =INDEX($N$2:$N$50,SUMPRODUCT(($P$2:$P$50=21)*ROW($N$2:$N$50))-1) -> 3 | L22: =Grupo!A23 -> Jose C Judith | M22: =Participantes!A22 -> 22 | N22: =Grupo!HJ23 -> 1 | O22: =N22*100-ROW() -> 78 | P22: =SUMPRODUCT(($O$2:$O$50>O22)*1)+1 -> 38
A23: =INDEX($M$2:$M$50,SUMPRODUCT(($P$2:$P$50=22)*ROW($M$2:$M$50))-1) -> 44 | B23: =IF(D23=D22,B22,B22+1) -> 3 | C23: =INDEX($L$2:$L$50,SUMPRODUCT(($P$2:$P$50=22)*ROW($L$2:$L$50))-1) -> Quinnie | D23: =INDEX($N$2:$N$50,SUMPRODUCT(($P$2:$P$50=22)*ROW($N$2:$N$50))-1) -> 3 | L23: =Grupo!A24 -> José de León | M23: =Participantes!A23 -> 23 | N23: =Grupo!HJ24 -> 4 | O23: =N23*100-ROW() -> 377 | P23: =SUMPRODUCT(($O$2:$O$50>O23)*1)+1 -> 8
A24: =INDEX($M$2:$M$50,SUMPRODUCT(($P$2:$P$50=23)*ROW($M$2:$M$50))-1) -> 45 | B24: =IF(D24=D23,B23,B23+1) -> 3 | C24: =INDEX($L$2:$L$50,SUMPRODUCT(($P$2:$P$50=23)*ROW($L$2:$L$50))-1) -> Radames | D24: =INDEX($N$2:$N$50,SUMPRODUCT(($P$2:$P$50=23)*ROW($N$2:$N$50))-1) -> 3 | L24: =Grupo!A25 -> Jovanna | M24: =Participantes!A24 -> 24 | N24: =Grupo!HJ25 -> 1 | O24: =N24*100-ROW() -> 76 | P24: =SUMPRODUCT(($O$2:$O$50>O24)*1)+1 -> 39
A25: =INDEX($M$2:$M$50,SUMPRODUCT(($P$2:$P$50=24)*ROW($M$2:$M$50))-1) -> 46 | B25: =IF(D25=D24,B24,B24+1) -> 3 | C25: =INDEX($L$2:$L$50,SUMPRODUCT(($P$2:$P$50=24)*ROW($L$2:$L$50))-1) -> Saul | D25: =INDEX($N$2:$N$50,SUMPRODUCT(($P$2:$P$50=24)*ROW($N$2:$N$50))-1) -> 3 | L25: =Grupo!A26 -> Karina | M25: =Participantes!A25 -> 25 | N25: =Grupo!HJ26 -> 1 | O25: =N25*100-ROW() -> 75 | P25: =SUMPRODUCT(($O$2:$O$50>O25)*1)+1 -> 40
A26: =INDEX($M$2:$M$50,SUMPRODUCT(($P$2:$P$50=25)*ROW($M$2:$M$50))-1) -> 47 | B26: =IF(D26=D25,B25,B25+1) -> 3 | C26: =INDEX($L$2:$L$50,SUMPRODUCT(($P$2:$P$50=25)*ROW($L$2:$L$50))-1) -> Silvia | D26: =INDEX($N$2:$N$50,SUMPRODUCT(($P$2:$P$50=25)*ROW($N$2:$N$50))-1) -> 3 | L26: =Grupo!A27 -> Kattia 1 | M26: =Participantes!A26 -> 26 | N26: =Grupo!HJ27 -> 2 | O26: =N26*100-ROW() -> 174 | P26: =SUMPRODUCT(($O$2:$O$50>O26)*1)+1 -> 30
A27: =INDEX($M$2:$M$50,SUMPRODUCT(($P$2:$P$50=26)*ROW($M$2:$M$50))-1) -> 49 | B27: =IF(D27=D26,B26,B26+1) -> 3 | C27: =INDEX($L$2:$L$50,SUMPRODUCT(($P$2:$P$50=26)*ROW($L$2:$L$50))-1) -> Waldo | D27: =INDEX($N$2:$N$50,SUMPRODUCT(($P$2:$P$50=26)*ROW($N$2:$N$50))-1) -> 3 | L27: =Grupo!A28 -> Kattia 2 | M27: =Participantes!A27 -> 27 | N27: =Grupo!HJ28 -> 3 | O27: =N27*100-ROW() -> 273 | P27: =SUMPRODUCT(($O$2:$O$50>O27)*1)+1 -> 17
A28: =INDEX($M$2:$M$50,SUMPRODUCT(($P$2:$P$50=27)*ROW($M$2:$M$50))-1) -> 12 | B28: =IF(D28=D27,B27,B27+1) -> 4 | C28: =INDEX($L$2:$L$50,SUMPRODUCT(($P$2:$P$50=27)*ROW($L$2:$L$50))-1) -> Espinosa L. | D28: =INDEX($N$2:$N$50,SUMPRODUCT(($P$2:$P$50=27)*ROW($N$2:$N$50))-1) -> 2 | L28: =Grupo!A29 -> Kevin | M28: =Participantes!A28 -> 28 | N28: =Grupo!HJ29 -> 3 | O28: =N28*100-ROW() -> 272 | P28: =SUMPRODUCT(($O$2:$O$50>O28)*1)+1 -> 18
A29: =INDEX($M$2:$M$50,SUMPRODUCT(($P$2:$P$50=28)*ROW($M$2:$M$50))-1) -> 16 | B29: =IF(D29=D28,B28,B28+1) -> 4 | C29: =INDEX($L$2:$L$50,SUMPRODUCT(($P$2:$P$50=28)*ROW($L$2:$L$50))-1) -> Isabel 2 | D29: =INDEX($N$2:$N$50,SUMPRODUCT(($P$2:$P$50=28)*ROW($N$2:$N$50))-1) -> 2 | L29: =Grupo!A30 -> Lizka | M29: =Participantes!A29 -> 29 | N29: =Grupo!HJ30 -> 3 | O29: =N29*100-ROW() -> 271 | P29: =SUMPRODUCT(($O$2:$O$50>O29)*1)+1 -> 19
A30: =INDEX($M$2:$M$50,SUMPRODUCT(($P$2:$P$50=29)*ROW($M$2:$M$50))-1) -> 21 | B30: =IF(D30=D29,B29,B29+1) -> 4 | C30: =INDEX($L$2:$L$50,SUMPRODUCT(($P$2:$P$50=29)*ROW($L$2:$L$50))-1) -> Jose C Ana | D30: =INDEX($N$2:$N$50,SUMPRODUCT(($P$2:$P$50=29)*ROW($N$2:$N$50))-1) -> 2 | L30: =Grupo!A31 -> Luis Peña | M30: =Participantes!A30 -> 30 | N30: =Grupo!HJ31 -> 6 | O30: =N30*100-ROW() -> 570 | P30: =SUMPRODUCT(($O$2:$O$50>O30)*1)+1 -> 2
A31: =INDEX($M$2:$M$50,SUMPRODUCT(($P$2:$P$50=30)*ROW($M$2:$M$50))-1) -> 26 | B31: =IF(D31=D30,B30,B30+1) -> 4 | C31: =INDEX($L$2:$L$50,SUMPRODUCT(($P$2:$P$50=30)*ROW($L$2:$L$50))-1) -> Kattia 1 | D31: =INDEX($N$2:$N$50,SUMPRODUCT(($P$2:$P$50=30)*ROW($N$2:$N$50))-1) -> 2 | L31: =Grupo!A32 -> Marco R. | M31: =Participantes!A31 -> 31 | N31: =Grupo!HJ32 -> 1 | O31: =N31*100-ROW() -> 69 | P31: =SUMPRODUCT(($O$2:$O$50>O31)*1)+1 -> 41
A32: =INDEX($M$2:$M$50,SUMPRODUCT(($P$2:$P$50=31)*ROW($M$2:$M$50))-1) -> 37 | B32: =IF(D32=D31,B31,B31+1) -> 4 | C32: =INDEX($L$2:$L$50,SUMPRODUCT(($P$2:$P$50=31)*ROW($L$2:$L$50))-1) -> Mily CF 2 | D32: =INDEX($N$2:$N$50,SUMPRODUCT(($P$2:$P$50=31)*ROW($N$2:$N$50))-1) -> 2 | L32: =Grupo!A33 -> Maricela | M32: =Participantes!A32 -> 32 | N32: =Grupo!HJ33 -> 1 | O32: =N32*100-ROW() -> 68 | P32: =SUMPRODUCT(($O$2:$O$50>O32)*1)+1 -> 42
A33: =INDEX($M$2:$M$50,SUMPRODUCT(($P$2:$P$50=32)*ROW($M$2:$M$50))-1) -> 1 | B33: =IF(D33=D32,B32,B32+1) -> 5 | C33: =INDEX($L$2:$L$50,SUMPRODUCT(($P$2:$P$50=32)*ROW($L$2:$L$50))-1) -> Alberto | D33: =INDEX($N$2:$N$50,SUMPRODUCT(($P$2:$P$50=32)*ROW($N$2:$N$50))-1) -> 1 | L33: =Grupo!A34 -> Marilyn | M33: =Participantes!A33 -> 33 | N33: =Grupo!HJ34 -> 6 | O33: =N33*100-ROW() -> 567 | P33: =SUMPRODUCT(($O$2:$O$50>O33)*1)+1 -> 3
A34: =INDEX($M$2:$M$50,SUMPRODUCT(($P$2:$P$50=33)*ROW($M$2:$M$50))-1) -> 3 | B34: =IF(D34=D33,B33,B33+1) -> 5 | C34: =INDEX($L$2:$L$50,SUMPRODUCT(($P$2:$P$50=33)*ROW($L$2:$L$50))-1) -> Alfredo 1 | D34: =INDEX($N$2:$N$50,SUMPRODUCT(($P$2:$P$50=33)*ROW($N$2:$N$50))-1) -> 1 | L34: =Grupo!A35 -> Medica | M34: =Participantes!A34 -> 34 | N34: =Grupo!HJ35 -> 1 | O34: =N34*100-ROW() -> 66 | P34: =SUMPRODUCT(($O$2:$O$50>O34)*1)+1 -> 43
A35: =INDEX($M$2:$M$50,SUMPRODUCT(($P$2:$P$50=34)*ROW($M$2:$M$50))-1) -> 7 | B35: =IF(D35=D34,B34,B34+1) -> 5 | C35: =INDEX($L$2:$L$50,SUMPRODUCT(($P$2:$P$50=34)*ROW($L$2:$L$50))-1) -> Carlos | D35: =INDEX($N$2:$N$50,SUMPRODUCT(($P$2:$P$50=34)*ROW($N$2:$N$50))-1) -> 1 | L35: =Grupo!A36 -> Milagros | M35: =Participantes!A35 -> 35 | N35: =Grupo!HJ36 -> 4 | O35: =N35*100-ROW() -> 365 | P35: =SUMPRODUCT(($O$2:$O$50>O35)*1)+1 -> 9
A36: =INDEX($M$2:$M$50,SUMPRODUCT(($P$2:$P$50=35)*ROW($M$2:$M$50))-1) -> 10 | B36: =IF(D36=D35,B35,B35+1) -> 5 | C36: =INDEX($L$2:$L$50,SUMPRODUCT(($P$2:$P$50=35)*ROW($L$2:$L$50))-1) -> Cynthia | D36: =INDEX($N$2:$N$50,SUMPRODUCT(($P$2:$P$50=35)*ROW($N$2:$N$50))-1) -> 1 | L36: =Grupo!A37 -> Mily CF 1 | M36: =Participantes!A36 -> 36 | N36: =Grupo!HJ37 -> 4 | O36: =N36*100-ROW() -> 364 | P36: =SUMPRODUCT(($O$2:$O$50>O36)*1)+1 -> 10
A37: =INDEX($M$2:$M$50,SUMPRODUCT(($P$2:$P$50=36)*ROW($M$2:$M$50))-1) -> 13 | B37: =IF(D37=D36,B36,B36+1) -> 5 | C37: =INDEX($L$2:$L$50,SUMPRODUCT(($P$2:$P$50=36)*ROW($L$2:$L$50))-1) -> Freddy | D37: =INDEX($N$2:$N$50,SUMPRODUCT(($P$2:$P$50=36)*ROW($N$2:$N$50))-1) -> 1 | L37: =Grupo!A38 -> Mily CF 2 | M37: =Participantes!A37 -> 37 | N37: =Grupo!HJ38 -> 2 | O37: =N37*100-ROW() -> 163 | P37: =SUMPRODUCT(($O$2:$O$50>O37)*1)+1 -> 31
A38: =INDEX($M$2:$M$50,SUMPRODUCT(($P$2:$P$50=37)*ROW($M$2:$M$50))-1) -> 15 | B38: =IF(D38=D37,B37,B37+1) -> 5 | C38: =INDEX($L$2:$L$50,SUMPRODUCT(($P$2:$P$50=37)*ROW($L$2:$L$50))-1) -> Isabel 1 | D38: =INDEX($N$2:$N$50,SUMPRODUCT(($P$2:$P$50=37)*ROW($N$2:$N$50))-1) -> 1 | L38: =Grupo!A39 -> Mily Frida | M38: =Participantes!A38 -> 14 | N38: =Grupo!HJ39 -> 3 | O38: =N38*100-ROW() -> 262 | P38: =SUMPRODUCT(($O$2:$O$50>O38)*1)+1 -> 20
A39: =INDEX($M$2:$M$50,SUMPRODUCT(($P$2:$P$50=38)*ROW($M$2:$M$50))-1) -> 22 | B39: =IF(D39=D38,B38,B38+1) -> 5 | C39: =INDEX($L$2:$L$50,SUMPRODUCT(($P$2:$P$50=38)*ROW($L$2:$L$50))-1) -> Jose C Judith | D39: =INDEX($N$2:$N$50,SUMPRODUCT(($P$2:$P$50=38)*ROW($N$2:$N$50))-1) -> 1 | L39: =Grupo!A40 -> Mily Oliver | M39: =Participantes!A39 -> 38 | N39: =Grupo!HJ40 -> 3 | O39: =N39*100-ROW() -> 261 | P39: =SUMPRODUCT(($O$2:$O$50>O39)*1)+1 -> 21
A40: =INDEX($M$2:$M$50,SUMPRODUCT(($P$2:$P$50=39)*ROW($M$2:$M$50))-1) -> 24 | B40: =IF(D40=D39,B39,B39+1) -> 5 | C40: =INDEX($L$2:$L$50,SUMPRODUCT(($P$2:$P$50=39)*ROW($L$2:$L$50))-1) -> Jovanna | D40: =INDEX($N$2:$N$50,SUMPRODUCT(($P$2:$P$50=39)*ROW($N$2:$N$50))-1) -> 1 | L40: =Grupo!A41 -> Mily Zeynneth | M40: =Participantes!A40 -> 39 | N40: =Grupo!HJ41 -> 1 | O40: =N40*100-ROW() -> 60 | P40: =SUMPRODUCT(($O$2:$O$50>O40)*1)+1 -> 44
...

Sheet Participantes
B1: Nombre | C1: México | D1: Sudáfrica | E1: Corea | F1: Chequia | G1: Canadá | H1: Bosnia | I1: Estados Unidos | J1: Paraguay | K1: Haití | L1: Escocia | M1: Australia | N1: Türkiye | O1: Brasil | P1: Marruecos | Q1: Qatar | R1: Suiza | S1: Costa de Marfil | T1: Ecuador | U1: Alemania | V1: Curazao | W1: Países Bajos | X1: Japón | Y1: Suecia | Z1: Túnez | AA1: Arabia Saudita | AB1: Uruguay | AC1: España | AD1: Cabo Verde | AE1: Irán | AF1: Nueva Zelanda | AG1: Bélgica | AH1: Egipto | AI1: Francia | AJ1: Senegal | AK1: Irak | AL1: Noruega | AM1: Argentina | AN1: Argelia | AO1: Austria | AP1: Jordania | AQ1: Ghana | AR1: Panamá | AS1: Inglaterra | AT1: Croacia | AU1: Portugal | AV1: RD Congo | AW1: Uzbekistán | AX1: Colombia | AY1: Chequia | AZ1: Sudáfrica | BA1: Suiza | BB1: Bosnia | BC1: Canadá | BD1: Qatar | BE1: México | BF1: Corea República | BG1: Brasil | BH1: Haití | BI1: Escocia | BJ1: Marruecos | BK1: Türkiye | BL1: Paraguay | BM1: Estados Unidos | BN1: Australia | BO1: Alemania | BP1: Costa de Marfil | BQ1: Ecuador | BR1: Curazao | BS1: Países Bajos | BT1: Suecia | BU1: Túnez | BV1: Japón | BW1: Uruguay | BX1: Cabo Verde | BY1: España | BZ1: Arabia Saudita | CA1: Bélgica | CB1: Irán | CC1: Nueva Zelanda | CD1: Egipto | CE1: Noruega | CF1: Senegal | CG1: Francia | CH1: Irak | CI1: Argentina | CJ1: Austria | CK1: Jordania | CL1: Argelia | CM1: Inglaterra | CN1: Ghana | CO1: Panamá | CP1: Croacia | CQ1: Portugal | CR1: Uzbekistán | CS1: Colombia | CT1: RD Congo | CU1: Escocia | CV1: Brasil | CW1: Marruecos | CX1: Haití | CY1: Suiza | CZ1: Canadá | DA1: Bosnia | DB1: Qatar | DC1: Chequia | DD1: México | DE1: Sudáfrica | DF1: Corea República | DG1: Curazao | DH1: Costa de Marfil | DI1: Ecuador | DJ1: Alemania | DK1: Japón | DL1: Suecia | DM1: Túnez | DN1: Países Bajos | DO1: Türkiye | DP1: Estados Unidos | DQ1: Paraguay | DR1: Australia | DS1: Noruega | DT1: Francia | DU1: Senegal | DV1: Irak | DW1: Egipto | DX1: Irán | DY1: Nueva Zelanda | DZ1: Bélgica | EA1: Cabo Verde | EB1: Arabia Saudita | EC1: Uruguay | ED1: España | EE1: Panamá | EF1: Inglaterra | EG1: Croacia | EH1: Ghana | EI1: Argelia | EJ1: Austria | EK1: Jordania | EL1: Argentina | EM1: Colombia | EN1: Portugal | EO1: RD Congo | EP1: Uzbekistán
A2: 1 | B2: Alberto | C2: 1 | D2: 1 | E2: 2 | F2: 0 | G2: 2 | H2: 1 | I2: 1 | J2: 3 | K2: 0 | L2: 2 | M2: 0 | N2: 1 | O2: 1 | P2: 2 | Q2: 0 | R2: 2 | S2: 1 | T2: 2 | U2: 5 | V2: 0 | W2: 3 | X2: 0 | Y2: 1 | Z2: 1 | AA2: 0 | AB2: 2 | AC2: 6 | AD2: 0 | AE2: 0 | AF2: 0 | AG2: 2 | AH2: 0 | AI2: 4 | AJ2: 0 | AK2: 0 | AL2: 4 | AM2: 4 | AN2: 0 | AO2: 1 | AP2: 0 | AQ2: 2 | AR2: 1 | AS2: 4 | AT2: 2 | AU2: 5 | AV2: 0 | AW2: 0 | AX2: 3 | AY2: 0 | AZ2: 1 | BA2: 1 | BB2: 0 | BC2: 3 | BD2: 1 | BE2: 1 | BF2: 0 | BG2: 5 | BH2: 0 | BI2: 0 | BJ2: 3 | BK2: 2 | BL2: 3 | BM2: 2 | BN2: 1 | BO2: 4 | BP2: 0 | BQ2: 4 | BR2: 0 | BS2: 3 | BT2: 1 | BU2: 0 | BV2: 2 | BW2: 4 | BX2: 0 | BY2: 5 | BZ2: 0 | CA2: 3 | CB2: 0 | CC2: 1 | CD2: 2 | CE2: 2 | CF2: 2 | CG2: 5 | CH2: 0 | CI2: 3 | CJ2: 0 | CK2: 0 | CL2: 0 | CM2: 5 | CN2: 0 | CO2: 0 | CP2: 4 | CQ2: 5 | CR2: 0 | CS2: 2 | CT2: 1 | CU2: 0 | CV2: 4 | CW2: 4 | CX2: 0 | CY2: 3 | CZ2: 2 | DA2: 1 | DB2: 1 | DC2: 1 | DD2: 3 | DE2: 0 | DF2: 1 | DG2: 0 | DH2: 2 | DI2: 2 | DJ2: 4 | DK2: 2 | DL2: 2 | DM2: 0 | DN2: 3 | DO2: 1 | DP2: 0 | DQ2: 1 | DR2: 0 | DS2: 1 | DT2: 3 | DU2: 2 | DV2: 0 | DW2: 2 | DX2: 1 | DY2: 0 | DZ2: 4 | EA2: 0 | EB2: 1 | EC2: 1 | ED2: 2 | EE2: 0 | EF2: 6 | EG2: 3 | EH2: 0 | EI2: 0 | EJ2: 0 | EK2: 0 | EL2: 4 | EM2: 0 | EN2: 2 | EO2: 1 | EP2: 1
A3: 2 | B3: Alexander | C3: 2 | D3: 0 | E3: 1 | F3: 1 | G3: 1 | H3: 1 | I3: 2 | J3: 0 | K3: 0 | L3: 2 | M3: 1 | N3: 1 | O3: 2 | P3: 0 | Q3: 0 | R3: 1 | S3: 1 | T3: 1 | U3: 3 | V3: 0 | W3: 2 | X3: 1 | Y3: 1 | Z3: 0 | AA3: 1 | AB3: 2 | AC3: 3 | AD3: 0 | AE3: 0 | AF3: 0 | AG3: 2 | AH3: 0 | AI3: 2 | AJ3: 1 | AK3: 0 | AL3: 2 | AM3: 2 | AN3: 0 | AO3: 1 | AP3: 0 | AQ3: 1 | AR3: 2 | AS3: 1 | AT3: 0 | AU3: 2 | AV3: 0 | AW3: 1 | AX3: 1 | AY3: 1 | AZ3: 0 | BA3: 1 | BB3: 1 | BC3: 2 | BD3: 0 | BE3: 2 | BF3: 1 | BG3: 3 | BH3: 1 | BI3: 0 | BJ3: 1 | BK3: 0 | BL3: 1 | BM3: 2 | BN3: 1 | BO3: 2 | BP3: 1 | BQ3: 2 | BR3: 0 | BS3: 2 | BT3: 0 | BU3: 1 | BV3: 1 | BW3: 2 | BX3: 0 | BY3: 2 | BZ3: 0 | CA3: 3 | CB3: 1 | CC3: 0 | CD3: 2 | CE3: 1 | CF3: 2 | CG3: 3 | CH3: 0 | CI3: 3 | CJ3: 1 | CK3: 1 | CL3: 2 | CM3: 2 | CN3: 0 | CO3: 1 | CP3: 1 | CQ3: 3 | CR3: 0 | CS3: 2 | CT3: 1 | CU3: 1 | CV3: 2 | CW3: 2 | CX3: 0 | CY3: 0 | CZ3: 1 | DA3: 2 | DB3: 1 | DC3: 0 | DD3: 1 | DE3: 1 | DF3: 2 | DG3: 1 | DH3: 2 | DI3: 0 | DJ3: 2 | DK3: 2 | DL3: 1 | DM3: 1 | DN3: 3 | DO3: 1 | DP3: 1 | DQ3: 3 | DR3: 0 | DS3: 0 | DT3: 2 | DU3: 2 | DV3: 0 | DW3: 1 | DX3: 1 | DY3: 0 | DZ3: 2 | EA3: 0 | EB3: 2 | EC3: 1 | ED3: 2 | EE3: 1 | EF3: 2 | EG3: 2 | EH3: 0 | EI3: 1 | EJ3: 1 | EK3: 1 | EL3: 0 | EM3: 2 | EN3: 1 | EO3: 2 | EP3: 1
A4: 3 | B4: Alfredo 1 | C4: 2 | D4: 1 | E4: 1 | F4: 1 | G4: 1 | H4: 0 | I4: 2 | J4: 1 | K4: 1 | L4: 1 | M4: 1 | N4: 2 | O4: 2 | P4: 0 | Q4: 0 | R4: 2 | S4: 1 | T4: 1 | U4: 4 | V4: 0 | W4: 2 | X4: 1 | Y4: 2 | Z4: 0 | AA4: 0 | AB4: 1 | AC4: 2 | AD4: 0 | AE4: 1 | AF4: 0 | AG4: 2 | AH4: 1 | AI4: 3 | AJ4: 1 | AK4: 0 | AL4: 3 | AM4: 2 | AN4: 0 | AO4: 2 | AP4: 0 | AQ4: 1 | AR4: 1 | AS4: 2 | AT4: 1 | AU4: 3 | AV4: 0 | AW4: 0 | AX4: 2 | AY4: 2 | AZ4: 0 | BA4: 2 | BB4: 1 | BC4: 1 | BD4: 0 | BE4: 2 | BF4: 1 | BG4: 3 | BH4: 0 | BI4: 1 | BJ4: 2 | BK4: 2 | BL4: 0 | BM4: 2 | BN4: 0 | BO4: 3 | BP4: 1 | BQ4: 3 | BR4: 0 | BS4: 2 | BT4: 1 | BU4: 0 | BV4: 2 | BW4: 2 | BX4: 1 | BY4: 3 | BZ4: 1 | CA4: 3 | CB4: 0 | CC4: 0 | CD4: 2 | CE4: 2 | CF4: 1 | CG4: 3 | CH4: 0 | CI4: 2 | CJ4: 1 | CK4: 0 | CL4: 1 | CM4: 3 | CN4: 1 | CO4: 1 | CP4: 2 | CQ4: 3 | CR4: 0 | CS4: 2 | CT4: 0 | CU4: 1 | CV4: 3 | CW4: 2 | CX4: 1 | CY4: 2 | CZ4: 1 | DA4: 2 | DB4: 0 | DC4: 0 | DD4: 2 | DE4: 1 | DF4: 1 | DG4: 0 | DH4: 2 | DI4: 1 | DJ4: 3 | DK4: 2 | DL4: 2 | DM4: 0 | DN4: 3 | DO4: 2 | DP4: 1 | DQ4: 1 | DR4: 1 | DS4: 2 | DT4: 2 | DU4: 1 | DV4: 1 | DW4: 3 | DX4: 0 | DY4: 0 | DZ4: 3 | EA4: 0 | EB4: 1 | EC4: 1 | ED4: 2 | EE4: 0 | EF4: 3 | EG4: 2 | EH4: 0 | EI4: 1 | EJ4: 2 | EK4: 0 | EL4: 2 | EM4: 1 | EN4: 1 | EO4: 1 | EP4: 1
A5: 4 | B5: Alfredo 2 | C5: 2 | D5: 0 | E5: 0 | F5: 1 | G5: 2 | H5: 0 | I5: 2 | J5: 0 | K5: 0 | L5: 1 | M5: 0 | N5: 2 | O5: 2 | P5: 1 | Q5: 0 | R5: 2 | S5: 0 | T5: 1 | U5: 3 | V5: 0 | W5: 2 | X5: 2 | Y5: 2 | Z5: 1 | AA5: 1 | AB5: 1 | AC5: 3 | AD5: 0 | AE5: 0 | AF5: 0 | AG5: 3 | AH5: 1 | AI5: 3 | AJ5: 0 | AK5: 0 | AL5: 2 | AM5: 2 | AN5: 1 | AO5: 1 | AP5: 0 | AQ5: 1 | AR5: 2 | AS5: 1 | AT5: 1 | AU5: 2 | AV5: 0 | AW5: 0 | AX5: 3 | AY5: 2 | AZ5: 1 | BA5: 2 | BB5: 2 | BC5: 2 | BD5: 0 | BE5: 2 | BF5: 0 | BG5: 3 | BH5: 1 | BI5: 0 | BJ5: 2 | BK5: 2 | BL5: 1 | BM5: 3 | BN5: 0 | BO5: 4 | BP5: 1 | BQ5: 2 | BR5: 0 | BS5: 1 | BT5: 1 | BU5: 0 | BV5: 2 | BW5: 2 | BX5: 0 | BY5: 3 | BZ5: 1 | CA5: 3 | CB5: 0 | CC5: 0 | CD5: 3 | CE5: 4 | CF5: 1 | CG5: 3 | CH5: 0 | CI5: 2 | CJ5: 1 | CK5: 0 | CL5: 2 | CM5: 3 | CN5: 0 | CO5: 1 | CP5: 1 | CQ5: 3 | CR5: 0 | CS5: 3 | CT5: 0 | CU5: 0 | CV5: 3 | CW5: 2 | CX5: 0 | CY5: 1 | CZ5: 1 | DA5: 1 | DB5: 0 | DC5: 1 | DD5: 2 | DE5: 0 | DF5: 1 | DG5: 0 | DH5: 1 | DI5: 1 | DJ5: 2 | DK5: 2 | DL5: 2 | DM5: 0 | DN5: 2 | DO5: 1 | DP5: 1 | DQ5: 1 | DR5: 0 | DS5: 2 | DT5: 2 | DU5: 1 | DV5: 0 | DW5: 2 | DX5: 0 | DY5: 0 | DZ5: 4 | EA5: 0 | EB5: 2 | EC5: 1 | ED5: 3 | EE5: 1 | EF5: 4 | EG5: 2 | EH5: 1 | EI5: 1 | EJ5: 1 | EK5: 0 | EL5: 3 | EM5: 2 | EN5: 2 | EO5: 0 | EP5: 0
A6: 5 | B6: Aneth | C6: 2 | D6: 0 | E6: 1 | F6: 1 | G6: 2 | H6: 1 | I6: 2 | J6: 1 | K6: 2 | L6: 0 | M6: 1 | N6: 1 | O6: 2 | P6: 1 | Q6: 2 | R6: 0 | S6: 1 | T6: 1 | U6: 4 | V6: 0 | W6: 2 | X6: 1 | Y6: 1 | Z6: 0 | AA6: 3 | AB6: 0 | AC6: 3 | AD6: 0 | AE6: 2 | AF6: 0 | AG6: 2 | AH6: 1 | AI6: 2 | AJ6: 1 | AK6: 2 | AL6: 0 | AM6: 3 | AN6: 0 | AO6: 2 | AP6: 0 | AQ6: 1 | AR6: 1 | AS6: 2 | AT6: 1 | AU6: 3 | AV6: 0 | AW6: 2 | AX6: 0 | AY6: 2 | AZ6: 1 | BA6: 2 | BB6: 0 | BC6: 1 | BD6: 1 | BE6: 2 | BF6: 1
A7: 6 | B7: Antonio | C7: 2 | D7: 0 | E7: 1 | F7: 1 | G7: 3 | H7: 1 | I7: 2 | J7: 0 | K7: 0 | L7: 3 | M7: 1 | N7: 2 | O7: 2 | P7: 2 | Q7: 0 | R7: 2 | S7: 1 | T7: 1 | U7: 4 | V7: 0 | W7: 3 | X7: 0 | Y7: 2 | Z7: 1 | AA7: 0 | AB7: 1 | AC7: 3 | AD7: 0 | AE7: 0 | AF7: 2 | AG7: 3 | AH7: 1 | AI7: 4 | AJ7: 0 | AK7: 0 | AL7: 1 | AM7: 3 | AN7: 1 | AO7: 2 | AP7: 1 | AQ7: 0 | AR7: 1 | AS7: 3 | AT7: 2 | AU7: 4 | AV7: 0 | AW7: 0 | AX7: 4 | AY7: 0 | AZ7: 1 | BA7: 3 | BB7: 2 | BC7: 2 | BD7: 1 | BE7: 3 | BF7: 1
A8: 7 | B8: Carlos | C8: 2 | D8: 1 | E8: 1 | F8: 1 | G8: 2 | H8: 1 | I8: 2 | J8: 0 | K8: 0 | L8: 2 | M8: 1 | N8: 2 | O8: 2 | P8: 1 | Q8: 0 | R8: 2 | S8: 1 | T8: 1 | U8: 5 | V8: 0 | W8: 2 | X8: 1 | Y8: 2 | Z8: 0 | AA8: 0 | AB8: 2 | AC8: 4 | AD8: 0 | AE8: 2 | AF8: 0 | AG8: 2 | AH8: 0 | AI8: 2 | AJ8: 1 | AK8: 0 | AL8: 3 | AM8: 3 | AN8: 0 | AO8: 2 | AP8: 0 | AQ8: 1 | AR8: 2 | AS8: 2 | AT8: 1 | AU8: 3 | AV8: 0 | AW8: 0 | AX8: 2 | AY8: 2 | AZ8: 1 | BA8: 1 | BB8: 1 | BC8: 3 | BD8: 1 | BE8: 2 | BF8: 1
A9: 8 | B9: Castillo L. | C9: 2 | D9: 1 | E9: 2 | F9: 1 | G9: 1 | H9: 1 | I9: 2 | J9: 1 | K9: 0 | L9: 2 | M9: 1 | N9: 3 | O9: 2 | P9: 1 | Q9: 0 | R9: 3 | S9: 1 | T9: 1 | U9: 4 | V9: 0 | W9: 2 | X9: 2 | Y9: 2 | Z9: 11 | AA9: 0 | AB9: 2 | AC9: 4 | AD9: 0 | AE9: 2 | AF9: 0 | AG9: 3 | AH9: 1 | AI9: 2 | AJ9: 1 | AK9: 0 | AL9: 3 | AM9: 3 | AN9: 0 | AO9: 2 | AP9: 1 | AQ9: 2 | AR9: 1 | AS9: 2 | AT9: 2 | AU9: 3 | AV9: 0 | AW9: 1 | AX9: 1 | AY9: 3 | AZ9: 0 | BA9: 2 | BB9: 0 | BC9: 3 | BD9: 1 | BE9: 1 | BF9: 2
A10: 9 | B10: Christofer | C10: 2 | D10: 3 | E10: 1 | F10: 1 | G10: 1 | H10: 2 | I10: 2 | J10: 4 | K10: 3 | L10: 4 | M10: 2 | N10: 1 | O10: 5 | P10: 1 | Q10: 2 | R10: 1 | S10: 0 | T10: 3 | U10: 2 | V10: 2 | W10: 2 | X10: 5 | Y10: 4 | Z10: 1 | AA10: 1 | AB10: 2 | AC10: 3 | AD10: 1 | AE10: 1 | AF10: 1 | AG10: 2 | AH10: 0 | AI10: 1 | AJ10: 3 | AK10: 1 | AL10: 4 | AM10: 3 | AN10: 2 | AO10: 1 | AP10: 1 | AQ10: 1 | AR10: 3 | AS10: 2 | AT10: 1 | AU10: 7 | AV10: 4 | AW10: 1 | AX10: 2 | AY10: 2 | AZ10: 2 | BA10: 3 | BB10: 4 | BC10: 2 | BD10: 3 | BE10: 1 | BF10: 2
A11: 10 | B11: Cynthia | C11: 1 | D11: 2 | E11: 1 | F11: 0 | G11: 2 | H11: 1 | I11: 0 | J11: 0 | K11: 1 | L11: 3 | M11: 1 | N11: 1 | O11: 2 | P11: 2 | Q11: 0 | R11: 1 | S11: 0 | T11: 1 | U11: 3 | V11: 1 | W11: 2 | X11: 2 | Y11: 3 | Z11: 1 | AA11: 2 | AB11: 2 | AC11: 3 | AD11: 1 | AE11: 1 | AF11: 1 | AG11: 0 | AH11: 0 | AI11: 2 | AJ11: 1 | AK11: 1 | AL11: 0 | AM11: 3 | AN11: 1 | AO11: 2 | AP11: 1 | AQ11: 0 | AR11: 1 | AS11: 3 | AT11: 1 | AU11: 2 | AV11: 1 | AW11: 1 | AX11: 3 | AY11: 1 | AZ11: 2 | BA11: 1 | BB11: 0 | BC11: 1 | BD11: 1 | BE11: 1 | BF11: 1
A12: 11 | B12: Edward | C12: 2 | D12: 0 | E12: 2 | F12: 1 | G12: 2 | H12: 1 | I12: 2 | J12: 1 | K12: 0 | L12: 2 | M12: 0 | N12: 1 | O12: 2 | P12: 1 | Q12: 0 | R12: 2 | S12: 1 | T12: 1 | U12: 3 | V12: 0 | W12: 2 | X12: 1 | Y12: 2 | Z12: 0 | AA12: 1 | AB12: 2 | AC12: 4 | AD12: 0 | AE12: 1 | AF12: 0 | AG12: 2 | AH12: 1 | AI12: 2 | AJ12: 1 | AK12: 0 | AL12: 2 | AM12: 2 | AN12: 0 | AO12: 2 | AP12: 0 | AQ12: 1 | AR12: 2 | AS12: 2 | AT12: 1 | AU12: 2 | AV12: 1 | AW12: 1 | AX12: 2 | AY12: 2 | AZ12: 0 | BA12: 2 | BB12: 1 | BC12: 2 | BD12: 0 | BE12: 1 | BF12: 1
A13: 12 | B13: Espinosa L. | C13: 2 | D13: 1 | E13: 1 | F13: 0 | G13: 3 | H13: 0 | I13: 2 | J13: 1 | K13: 3 | L13: 1 | M13: 1 | N13: 1 | O13: 2 | P13: 0 | Q13: 0 | R13: 0 | S13: 1 | T13: 2 | U13: 3 | V13: 0 | W13: 0 | X13: 2 | Y13: 1 | Z13: 1 | AA13: 0 | AB13: 1 | AC13: 2 | AD13: 0 | AE13: 2 | AF13: 0 | AG13: 1 | AH13: 0 | AI13: 3 | AJ13: 0 | AK13: 1 | AL13: 1 | AM13: 2 | AN13: 0 | AO13: 1 | AP13: 1 | AQ13: 0 | AR13: 1 | AS13: 1 | AT13: 0 | AU13: 2 | AV13: 0 | AW13: 1 | AX13: 2 | AY13: 1 | AZ13: 1 | BA13: 0 | BB13: 1 | BC13: 2 | BD13: 0 | BE13: 2 | BF13: 0
A14: 13 | B14: Freddy | C14: 3 | D14: 1 | E14: 1 | F14: 1 | G14: 3 | H14: 1 | I14: 2 | J14: 0 | K14: 0 | L14: 1 | M14: 1 | N14: 2 | O14: 2 | P14: 2 | Q14: 1 | R14: 2 | S14: 0 | T14: 1 | U14: 6 | V14: 0 | W14: 1 | X14: 0 | Y14: 3 | Z14: 0 | AA14: 0 | AB14: 2 | AC14: 5 | AD14: 0 | AE14: 0 | AF14: 1 | AG14: 4 | AH14: 1 | AI14: 4 | AJ14: 0 | AK14: 0 | AL14: 3 | AM14: 4 | AN14: 1 | AO14: 3 | AP14: 0 | AQ14: 1 | AR14: 1 | AS14: 2 | AT14: 1 | AU14: 5 | AV14: 0 | AW14: 1 | AX14: 2 | AY14: 0 | AZ14: 0 | BA14: 1 | BB14: 0 | BC14: 2 | BD14: 0 | BE14: 1 | BF14: 1
A15: 15 | B15: Isabel 1 | C15: 3 | D15: 1 | E15: 1 | F15: 1 | G15: 2 | H15: 1 | I15: 2 | J15: 2 | K15: 1 | L15: 3 | M15: 1 | N15: 2 | O15: 3 | P15: 2 | Q15: 0 | R15: 2 | S15: 1 | T15: 2 | U15: 5 | V15: 1 | W15: 2 | X15: 2 | Y15: 1 | Z15: 1 | AA15: 1 | AB15: 2 | AC15: 4 | AD15: 0 | AE15: 2 | AF15: 0 | AG15: 2 | AH15: 2 | AI15: 3 | AJ15: 1 | AK15: 0 | AL15: 2 | AM15: 3 | AN15: 1 | AO15: 2 | AP15: 0 | AQ15: 1 | AR15: 1 | AS15: 1 | AT15: 2 | AU15: 3 | AV15: 1 | AW15: 1 | AX15: 2 | AY15: 1 | AZ15: 1 | BA15: 2 | BB15: 1 | BC15: 2 | BD15: 1 | BE15: 2 | BF15: 2
A16: 16 | B16: Isabel 2 | C16: 1 | D16: 0 | E16: 2 | F16: 0 | G16: 2 | H16: 1 | I16: 3 | J16: 1 | K16: 0 | L16: 2 | M16: 0 | N16: 3 | O16: 4 | P16: 1 | Q16: 0 | R16: 1 | S16: 1 | T16: 1 | U16: 4 | V16: 0 | W16: 2 | X16: 1 | Y16: 3 | Z16: 0 | AA16: 0 | AB16: 1 | AC16: 5 | AD16: 0 | AE16: 1 | AF16: 0 | AG16: 2 | AH16: 0 | AI16: 3 | AJ16: 1 | AK16: 0 | AL16: 2 | AM16: 2 | AN16: 0 | AO16: 1 | AP16: 0 | AQ16: 1 | AR16: 2 | AS16: 3 | AT16: 2 | AU16: 3 | AV16: 0 | AW16: 0 | AX16: 4 | AY16: 1 | AZ16: 1 | BA16: 2 | BB16: 1 | BC16: 2 | BD16: 1 | BE16: 1 | BF16: 1
A17: 17 | B17: Javier | C17: 2 | D17: 0 | E17: 3 | F17: 1 | G17: 2 | H17: 1 | I17: 2 | J17: 1 | K17: 1 | L17: 1 | M17: 1 | N17: 2 | O17: 2 | P17: 1 | Q17: 1 | R17: 1 | S17: 1 | T17: 1 | U17: 3 | V17: 1 | W17: 2 | X17: 1 | Y17: 1 | Z17: 1 | AA17: 5 | AB17: 2 | AC17: 3 | AD17: 0 | AE17: 1 | AF17: 2 | AG17: 2 | AH17: 1 | AI17: 2 | AJ17: 1 | AK17: 3 | AL17: 2 | AM17: 3 | AN17: 0 | AO17: 3 | AP17: 1 | AQ17: 1 | AR17: 2 | AS17: 3 | AT17: 2 | AU17: 4 | AV17: 0 | AW17: 5 | AX17: 2 | AY17: 1 | AZ17: 1 | BA17: 4 | BB17: 1 | BC17: 2 | BD17: 1 | BE17: 1 | BF17: 2
A18: 18 | B18: Jose C 1 | C18: 0 | D18: 1 | E18: 1 | F18: 1 | G18: 2 | H18: 1 | I18: 2 | J18: 2 | K18: 1 | L18: 0 | M18: 0 | N18: 2 | O18: 3 | P18: 2 | Q18: 0 | R18: 2 | S18: 1 | T18: 1 | U18: 3 | V18: 0 | W18: 2 | X18: 1 | Y18: 2 | Z18: 0 | AA18: 0 | AB18: 2 | AC18: 3 | AD18: 0
A19: 19 | B19: Jose C 2 | C19: 1 | D19: 0 | E19: 2 | F19: 1 | G19: 1 | H19: 1 | I19: 2 | J19: 2 | K19: 2 | L19: 0 | M19: 1 | N19: 2 | O19: 1 | P19: 2 | Q19: 1 | R19: 1 | S19: 2 | T19: 1 | U19: 4 | V19: 1 | X19: 2 | Y19: 1 | Z19: 0 | AB19: 3 | AC19: 5 | AD19: 1
A20: 20 | B20: Jose C Ahiza | C20: 2 | D20: 1 | E20: 2 | F20: 1 | G20: 2 | H20: 0 | I20: 3 | J20: 1 | K20: 0 | L20: 2 | M20: 1 | N20: 2 | O20: 2 | P20: 0 | Q20: 1 | R20: 2 | S20: 1 | T20: 1 | U20: 3 | V20: 0 | W20: 2 | X20: 0 | Y20: 2 | Z20: 1 | AA20: 0 | AB20: 2 | AC20: 3 | AD20: 0
A21: 21 | B21: Jose C Ana | C21: 4 | D21: 2 | E21: 3 | F21: 1 | G21: 4 | H21: 0 | I21: 1 | J21: 2 | K21: 1 | L21: 1 | M21: 2 | N21: 1 | O21: 2 | P21: 0 | Q21: 0 | R21: 2 | S21: 2 | T21: 3 | U21: 6 | V21: 0 | W21: 3 | X21: 1 | Y21: 2 | Z21: 1 | AA21: 1 | AB21: 3 | AC21: 7 | AD21: 0
A22: 22 | B22: Jose C Judith | C22: 3 | D22: 2 | E22: 2 | F22: 2 | G22: 3 | H22: 1 | I22: 3 | J22: 2 | K22: 1 | L22: 1 | M22: 2 | N22: 1 | O22: 3 | P22: 0 | Q22: 1 | R22: 2 | S22: 2 | T22: 2 | U22: 4 | V22: 0 | W22: 2 | X22: 0 | Y22: 3 | Z22: 1 | AA22: 0 | AB22: 2 | AC22: 5 | AD22: 0
A23: 23 | B23: José de León | C23: 2 | D23: 1 | E23: 2 | F23: 1 | G23: 1 | H23: 0 | I23: 3 | J23: 0 | K23: 0 | L23: 3 | M23: 2 | N23: 2 | O23: 0 | P23: 2 | Q23: 1 | R23: 2 | S23: 4 | T23: 0 | U23: 1 | V23: 1 | W23: 1 | X23: 0 | Y23: 0 | Z23: 1 | AA23: 4 | AB23: 0 | AC23: 2 | AD23: 1
A24: 24 | B24: Jovanna | C24: 5 | D24: 2 | E24: 1 | F24: 3 | G24: 0 | H24: 2 | I24: 1 | J24: 1 | K24: 0 | L24: 3 | M24: 0 | N24: 1 | O24: 3 | P24: 2 | Q24: 0 | R24: 4 | S24: 2 | T24: 1 | U24: 6 | V24: 1 | W24: 0 | X24: 2 | Y24: 3 | Z24: 1 | AA24: 1 | AB24: 0 | AC24: 2 | AD24: 0 | AE24: 0 | AF24: 1 | AG24: 3 | AH24: 3 | AI24: 1 | AJ24: 1 | AK24: 0 | AL24: 3 | AM24: 1 | AN24: 2 | AO24: 4 | AP24: 1 | AQ24: 0 | AR24: 1 | AS24: 3 | AT24: 5 | AU24: 2 | AV24: 0 | AW24: 2 | AX24: 4 | AY24: 2 | AZ24: 1 | BA24: 2 | BB24: 0 | BC24: 3 | BD24: 0 | BE24: 1 | BF24: 1
A25: 25 | B25: Karina | C25: 3 | D25: 1 | E25: 1 | F25: 2 | G25: 2 | H25: 1 | I25: 2 | J25: 1 | K25: 1 | L25: 3 | M25: 1 | N25: 1 | O25: 3 | P25: 2 | Q25: 1 | R25: 2 | S25: 2 | T25: 2 | U25: 3 | V25: 1 | W25: 3 | X25: 1 | Y25: 2 | Z25: 1 | AA25: 1 | AB25: 3 | AC25: 5 | AD25: 1
A26: 26 | B26: Kattia 1 | C26: 2 | D26: 1 | E26: 2 | F26: 0 | G26: 3 | H26: 0 | I26: 2 | J26: 1 | K26: 0 | L26: 2 | M26: 2 | N26: 0 | O26: 2 | P26: 2 | Q26: 0 | R26: 2 | S26: 2 | T26: 1 | U26: 3 | V26: 1 | W26: 4 | X26: 0 | Y26: 2 | Z26: 0 | AA26: 1 | AB26: 3 | AC26: 3 | AD26: 1
A27: 27 | B27: Kattia 2 | C27: 2 | D27: 0 | E27: 1 | F27: 1 | G27: 2 | H27: 1 | I27: 2 | J27: 1 | K27: 0 | L27: 3 | M27: 1 | N27: 1 | O27: 3 | P27: 2 | Q27: 0 | R27: 2 | S27: 2 | T27: 2 | U27: 4 | V27: 0 | W27: 2 | X27: 2 | Y27: 2 | Z27: 0 | AA27: 0 | AB27: 2 | AC27: 3 | AD27: 0
A28: 28 | B28: Kevin | C28: 2 | D28: 0 | E28: 1 | F28: 1 | G28: 1 | H28: 2 | I28: 2 | J28: 1 | K28: 0 | L28: 2 | M28: 1 | N28: 1 | O28: 3 | P28: 1 | Q28: 0 | R28: 2 | S28: 2 | T28: 2 | U28: 4 | V28: 0 | W28: 2 | X28: 1 | Y28: 1 | Z28: 0 | AA28: 0 | AB28: 2 | AC28: 3 | AD28: 0
A29: 29 | B29: Lizka | C29: 2 | D29: 0 | E29: 1 | F29: 1 | G29: 2 | H29: 1 | I29: 2 | J29: 1 | K29: 1 | L29: 2 | M29: 1 | N29: 2 | O29: 2 | P29: 1 | Q29: 0 | R29: 2 | S29: 1 | T29: 1 | U29: 3 | V29: 1 | W29: 2 | X29: 1 | Y29: 2 | Z29: 1 | AA29: 0 | AB29: 3 | AC29: 4 | AD29: 0
A30: 30 | B30: Luis Peña | C30: 2 | D30: 0 | E30: 2 | F30: 1 | G30: 1 | H30: 0 | I30: 2 | J30: 1 | K30: 1 | L30: 3 | M30: 0 | N30: 2 | O30: 2 | P30: 1 | Q30: 0 | R30: 4 | S30: 0 | T30: 2 | U30: 4 | V30: 0 | W30: 2 | X30: 2 | Y30: 2 | Z30: 0 | AA30: 0 | AB30: 2 | AC30: 7 | AD30: 0
A31: 31 | B31: Marco R. | C31: 2 | D31: 1 | E31: 1 | F31: 1 | G31: 1 | H31: 1 | I31: 2 | J31: 1 | K31: 1 | L31: 2 | M31: 0 | N31: 1 | O31: 2 | P31: 1 | Q31: 0 | R31: 2 | S31: 1 | T31: 1 | U31: 4 | V31: 0 | W31: 1 | X31: 1 | Y31: 1 | Z31: 1 | AA31: 0 | AB31: 2 | AC31: 4 | AD31: 0
A32: 32 | B32: Maricela | C32: 3 | D32: 1 | E32: 2 | F32: 2 | G32: 3 | H32: 1 | I32: 2 | J32: 1 | K32: 0 | L32: 3 | M32: 1 | N32: 3 | O32: 4 | P32: 2 | Q32: 1 | R32: 2 | S32: 1 | T32: 3 | U32: 5 | V32: 0 | W32: 4 | X32: 1 | Y32: 2 | Z32: 2 | AA32: 1 | AB32: 3 | AC32: 5 | AD32: 0
A33: 33 | B33: Marilyn | C33: 2 | D33: 0 | E33: 2 | F33: 1 | G33: 3 | H33: 0 | I33: 2 | J33: 0 | K33: 0 | L33: 2 | M33: 1 | N33: 1 | O33: 1 | P33: 1 | Q33: 1 | R33: 2 | S33: 3 | T33: 0 | U33: 2 | V33: 1 | W33: 2 | X33: 2 | Y33: 3 | Z33: 1 | AA33: 1 | AB33: 2 | AC33: 3 | AD33: 0
A34: 34 | B34: Medica | C34: 2 | D34: 1 | E34: 1 | F34: 1 | G34: 1 | H34: 1 | I34: 1 | J34: 0 | K34: 0 | L34: 3 | M34: 0 | N34: 1 | O34: 2 | P34: 2 | Q34: 0 | R34: 2 | S34: 1 | T34: 1 | U34: 3 | V34: 1 | W34: 2 | X34: 2 | Y34: 2 | Z34: 0 | AA34: 0 | AB34: 1 | AC34: 4 | AD34: 0
A35: 35 | B35: Milagros | C35: 2 | D35: 0 | E35: 3 | F35: 1 | G35: 2 | H35: 1 | I35: 2 | J35: 1 | K35: 1 | L35: 1 | M35: 1 | N35: 2 | O35: 2 | P35: 1 | Q35: 1 | R35: 1 | S35: 1 | T35: 1 | U35: 3 | V35: 1 | W35: 2 | X35: 1 | Y35: 1 | Z35: 1 | AA35: 1 | AB35: 2 | AC35: 3 | AD35: 0
A36: 36 | B36: Mily CF 1 | C36: 3 | D36: 1 | E36: 2 | F36: 1 | G36: 2 | H36: 2 | I36: 3 | J36: 2 | K36: 2 | L36: 3 | M36: 3 | N36: 4 | O36: 4 | P36: 4 | Q36: 1 | R36: 2 | S36: 1 | T36: 3 | U36: 3 | V36: 1 | W36: 2 | X36: 2 | Y36: 2 | Z36: 1 | AA36: 2 | AB36: 2 | AC36: 3 | AD36: 1
A37: 37 | B37: Mily CF 2 | C37: 2 | D37: 1 | E37: 2 | F37: 0 | G37: 1 | H37: 0 | I37: 2 | J37: 1 | L37: 1 | M37: 1 | N37: 2 | O37: 2 | P37: 1 | Q37: 0 | R37: 1 | S37: 2 | T37: 3 | U37: 3 | V37: 1 | W37: 2 | X37: 1 | Y37: 1 | Z37: 1 | AA37: 1 | AB37: 2 | AC37: 3 | AD37: 0 | AE37: 1 | AF37: 0 | AG37: 2 | AH37: 0 | AI37: 2 | AJ37: 1 | AK37: 0 | AL37: 2 | AM37: 2 | AN37: 0 | AO37: 1 | AP37: 0
A38: 14 | B38: Mily Frida | C38: 2 | D38: 0 | E38: 1 | F38: 1 | G38: 0 | H38: 1 | I38: 0 | J38: 1 | K38: 0 | M38: 1 | N38: 0 | O38: 3 | P38: 1 | Q38: 0 | R38: 1 | S38: 1 | T38: 0 | U38: 2 | V38: 0 | W38: 2 | X38: 1 | Y38: 2 | Z38: 1 | AA38: 1 | AB38: 2 | AC38: 2 | AD38: 0
A39: 38 | B39: Mily Oliver | C39: 2 | D39: 0 | E39: 1 | F39: 1 | G39: 2 | H39: 1 | I39: 2 | J39: 0 | K39: 0 | L39: 0 | M39: 1 | N39: 2 | O39: 2 | P39: 1 | Q39: 0 | R39: 2 | S39: 1 | T39: 1 | U39: 3 | V39: 0 | W39: 2 | X39: 1 | Y39: 1 | Z39: 0 | AA39: 1 | AB39: 2 | AC39: 3 | AD39: 0
A40: 39 | B40: Mily Zeynneth | C40: 3 | D40: 1 | E40: 2 | F40: 2 | G40: 3 | H40: 1 | I40: 3 | J40: 0 | K40: 0 | L40: 1 | M40: 2 | N40: 3 | O40: 3 | P40: 1 | Q40: 0 | S40: 1 | T40: 2 | U40: 4 | V40: 0 | W40: 3 | X40: 1 | Y40: 2 | Z40: 1 | AA40: 2 | AB40: 3 | AC40: 4 | AD40: 1
...

Sheet Partidos
A1: N° | B1: Fecha | C1: Hora ET | D1: Columna1 | E1: Fase | F1: Grupo | G1: Local | H1: Visitante | I1: Goles Local | J1: Goles Visitante | K1: Ganador/Clasifica | L1: Sede | M1: Local código | N1: Visitante código | O1: Local posición | P1: Visitante posición | Q1: Fuente/Nota | R1: Nota
A2: 1 | B2: 46184 | C2: 0.58333333 | D2: =HOUR(tblPartidos[[#This Row],[Hora ET]])-1 -> 13 | E2: Grupo | F2: A | G2: México | H2: Sudáfrica | I2: 2 | J2: 0 | K2: =IF(OR(I2="",J2=""),"",IF(I2>J2,G2,IF(J2>I2,H2,"Empate"))) -> México | L2: Mexico City | M2: MEX | N2: RSA | O2: A1 | P2: A2 | Q2: FIFA/CBS | R2: Eliminatorias: si una posición aún no está definida, F/G muestran la llave (1A, 2B, 3A/B/C..., W74, L101). Un grupo solo clasifica cuando sus 4 equipos tienen al menos 1 partido con marcador.
A3: 2 | B3: 46184 | C3: 0.875 | D3: =HOUR(tblPartidos[[#This Row],[Hora ET]])-1 -> 20 | E3: Grupo | F3: A | G3: Corea República | H3: Chequia | I3: 2 | J3: 1 | K3: =IF(OR(I3="",J3=""),"",IF(I3>J3,G3,IF(J3>I3,H3,"Empate"))) -> Corea República | L3: Guadalajara | M3: KOR | N3: CZE | O3: A3 | P3: A4 | Q3: FIFA/CBS
A4: 3 | B4: 46185 | C4: 0.58333333 | D4: =HOUR(tblPartidos[[#This Row],[Hora ET]])-1 -> 13 | E4: Grupo | F4: B | G4: Canadá | H4: Bosnia y Herzegovina | K4: =IF(OR(I4="",J4=""),"",IF(I4>J4,G4,IF(J4>I4,H4,"Empate"))) | L4: Toronto | M4: CAN | N4: BIH | O4: B1 | P4: B2 | Q4: FIFA/CBS
A5: 4 | B5: 46185 | C5: 0.83333333 | D5: =HOUR(tblPartidos[[#This Row],[Hora ET]])-1 -> 19 | E5: Grupo | F5: D | G5: Estados Unidos | H5: Paraguay | K5: =IF(OR(I5="",J5=""),"",IF(I5>J5,G5,IF(J5>I5,H5,"Empate"))) | L5: Los Angeles | M5: USA | N5: PAR | O5: D1 | P5: D2 | Q5: FIFA/CBS
A6: 5 | B6: 46186 | C6: 0.83333333 | D6: =HOUR(tblPartidos[[#This Row],[Hora ET]])-1 -> 19 | E6: Grupo | F6: C | G6: Haití | H6: Escocia | K6: =IF(OR(I6="",J6=""),"",IF(I6>J6,G6,IF(J6>I6,H6,"Empate"))) | L6: Boston | M6: HAI | N6: SCO | O6: C3 | P6: C4 | Q6: FIFA/CBS
A7: 6 | B7: 46186 | C7: 0.95833333 | D7: =HOUR(tblPartidos[[#This Row],[Hora ET]])-1 -> 22 | E7: Grupo | F7: D | G7: Australia | H7: Türkiye | K7: =IF(OR(I7="",J7=""),"",IF(I7>J7,G7,IF(J7>I7,H7,"Empate"))) | L7: Vancouver | M7: AUS | N7: TUR | O7: D3 | P7: D4 | Q7: FIFA/CBS
A8: 7 | B8: 46186 | C8: 0.70833333 | D8: =HOUR(tblPartidos[[#This Row],[Hora ET]])-1 -> 16 | E8: Grupo | F8: C | G8: Brasil | H8: Marruecos | K8: =IF(OR(I8="",J8=""),"",IF(I8>J8,G8,IF(J8>I8,H8,"Empate"))) | L8: New York New Jersey | M8: BRA | N8: MAR | O8: C1 | P8: C2 | Q8: FIFA/CBS
A9: 8 | B9: 46186 | C9: 0.58333333 | D9: =HOUR(tblPartidos[[#This Row],[Hora ET]])-1 -> 13 | E9: Grupo | F9: B | G9: Qatar | H9: Suiza | K9: =IF(OR(I9="",J9=""),"",IF(I9>J9,G9,IF(J9>I9,H9,"Empate"))) | L9: San Francisco Bay Area | M9: QAT | N9: SUI | O9: B3 | P9: B4 | Q9: FIFA/CBS
A10: 9 | B10: 46187 | C10: 0.75 | D10: =HOUR(tblPartidos[[#This Row],[Hora ET]])-1 -> 17 | E10: Grupo | F10: E | G10: Costa de Marfil | H10: Ecuador | K10: =IF(OR(I10="",J10=""),"",IF(I10>J10,G10,IF(J10>I10,H10,"Empate"))) | L10: Philadelphia | M10: CIV | N10: ECU | O10: E3 | P10: E4 | Q10: FIFA/CBS
A11: 10 | B11: 46187 | C11: 0.95833333 | D11: =HOUR(tblPartidos[[#This Row],[Hora ET]])-1 -> 22 | E11: Grupo | F11: E | G11: Alemania | H11: Curazao | K11: =IF(OR(I11="",J11=""),"",IF(I11>J11,G11,IF(J11>I11,H11,"Empate"))) | L11: Houston | M11: GER | N11: CUW | O11: E1 | P11: E2 | Q11: FIFA/CBS
A12: 11 | B12: 46187 | C12: 0.625 | D12: =HOUR(tblPartidos[[#This Row],[Hora ET]])-1 -> 14 | E12: Grupo | F12: F | G12: Países Bajos | H12: Japón | K12: =IF(OR(I12="",J12=""),"",IF(I12>J12,G12,IF(J12>I12,H12,"Empate"))) | L12: Dallas | M12: NED | N12: JPN | O12: F1 | P12: F2 | Q12: FIFA/CBS
A13: 12 | B13: 46187 | C13: 0.875 | D13: =HOUR(tblPartidos[[#This Row],[Hora ET]])-1 -> 20 | E13: Grupo | F13: F | G13: Suecia | H13: Túnez | K13: =IF(OR(I13="",J13=""),"",IF(I13>J13,G13,IF(J13>I13,H13,"Empate"))) | L13: Monterrey | M13: SWE | N13: TUN | O13: F3 | P13: F4 | Q13: FIFA/CBS
A14: 13 | B14: 46188 | C14: 0.70833333 | D14: =HOUR(tblPartidos[[#This Row],[Hora ET]])-1 -> 16 | E14: Grupo | F14: H | G14: Arabia Saudita | H14: Uruguay | K14: =IF(OR(I14="",J14=""),"",IF(I14>J14,G14,IF(J14>I14,H14,"Empate"))) | L14: Miami | M14: KSA | N14: URU | O14: H3 | P14: H4 | Q14: FIFA/CBS
A15: 14 | B15: 46188 | C15: 0.45833333 | D15: =HOUR(tblPartidos[[#This Row],[Hora ET]])-1 -> 10 | E15: Grupo | F15: H | G15: España | H15: Cabo Verde | K15: =IF(OR(I15="",J15=""),"",IF(I15>J15,G15,IF(J15>I15,H15,"Empate"))) | L15: Atlanta | M15: ESP | N15: CPV | O15: H1 | P15: H2 | Q15: FIFA/CBS
... A73: 72 | B73: 46200 | C73: 0.77083333 | D73: =HOUR(tblPartidos[[#This Row],[Hora ET]])-1 -> 17 | E73: Grupo | F73: K | G73: RD Congo | H73: Uzbekistán | K73: =IF(OR(I73="",J73=""),"",IF(I73>J73,G73,IF(J73>I73,H73,"Empate"))) | L73: Atlanta | M73: COD | N73: UZB | O73: K2 | P73: K3 | Q73: FIFA/CBS
A74: 73 | B74: 46201 | C74: 0.58333333 | D74: =HOUR(tblPartidos[[#This Row],[Hora ET]])-1 -> 13 | E74: Ronda de 32 | G74: =IF(O74="","",IF(LEFT(O74,1)="3",IFERROR(IF(VLOOKUP($A74&"L",Asignacion_3ros!$A$2:$G$9,6,FALSE())="",O74,VLOOKUP($A74&"L",Asignacion_3ros!$A$2:$G$9,6,FALSE())),O74),IF(LEFT(O74,1)="W",IFERROR(IF(INDEX($K$2:$K$73,MATCH(VALUE(MID(O74,2,3)),$A$2:$A$73,0))="",O74,INDEX($K$2:$K$73,MATCH(VALUE(MID(O74,2,3)),$A$2:$A$73,0))),O74),IF(LEFT(O74,1)="L",IFERROR(IF(INDEX($K$2:$K$73,MATCH(VALUE(MID(O74,2,3)),$A$2:$A$73,0))=INDEX($G$2:$G$73,MATCH(VALUE(MID(O74,2,3)),$A$2:$A$73,0)),INDEX($H$2:$H$73,MATCH(VALUE(MID(O74,2,3)),$A$2:$A$73,0)),IF(INDEX($K$2:$K$73,MATCH(VALUE(MID(O74,2,3)),$A$2:$A$73,0))=INDEX($H$2:$H$73,MATCH(VALUE(MID(O74,2,3)),$A$2:$A$73,0)),INDEX($G$2:$G$73,MATCH(VALUE(MID(O74,2,3)),$A$2:$A$73,0)),O74)),O74),IFERROR(IF(VLOOKUP(RIGHT(O74,1)&LEFT(O74,1),Clasificacion!$O$2:$Q$49,2,FALSE())="",O74,VLOOKUP(RIGHT(O74,1)&LEFT(O74,1),Clasificacion!$O$2:$Q$49,2,FALSE())),O74))))) -> Corea República | H74: =IF(P74="","",IF(LEFT(P74,1)="3",IFERROR(IF(VLOOKUP($A74&"V",Asignacion_3ros!$A$2:$G$9,6,FALSE())="",P74,VLOOKUP($A74&"V",Asignacion_3ros!$A$2:$G$9,6,FALSE())),P74),IF(LEFT(P74,1)="W",IFERROR(IF(INDEX($K$2:$K$73,MATCH(VALUE(MID(P74,2,3)),$A$2:$A$73,0))="",P74,INDEX($K$2:$K$73,MATCH(VALUE(MID(P74,2,3)),$A$2:$A$73,0))),P74),IF(LEFT(P74,1)="L",IFERROR(IF(INDEX($K$2:$K$73,MATCH(VALUE(MID(P74,2,3)),$A$2:$A$73,0))=INDEX($G$2:$G$73,MATCH(VALUE(MID(P74,2,3)),$A$2:$A$73,0)),INDEX($H$2:$H$73,MATCH(VALUE(MID(P74,2,3)),$A$2:$A$73,0)),IF(INDEX($K$2:$K$73,MATCH(VALUE(MID(P74,2,3)),$A$2:$A$73,0))=INDEX($H$2:$H$73,MATCH(VALUE(MID(P74,2,3)),$A$2:$A$73,0)),INDEX($G$2:$G$73,MATCH(VALUE(MID(P74,2,3)),$A$2:$A$73,0)),P74)),P74),IFERROR(IF(VLOOKUP(RIGHT(P74,1)&LEFT(P74,1),Clasificacion!$O$2:$Q$49,2,FALSE())="",P74,VLOOKUP(RIGHT(P74,1)&LEFT(P74,1),Clasificacion!$O$2:$Q$49,2,FALSE())),P74))))) -> 2B | K74: =IF(OR(I74="",J74=""),"",IF(I74>J74,G74,IF(J74>I74,H74,"Empate"))) | L74: Los Angeles | M74: =IF(O74="","",IF(LEFT(O74,1)="3",IFERROR(IF(VLOOKUP($A74&"L",Asignacion_3ros!$A$2:$G$9,7,FALSE())="",O74,VLOOKUP($A74&"L",Asignacion_3ros!$A$2:$G$9,7,FALSE())),O74),IF(LEFT(O74,1)="W",IFERROR(IF(INDEX($K$2:$K$73,MATCH(VALUE(MID(O74,2,3)),$A$2:$A$73,0))=INDEX($G$2:$G$73,MATCH(VALUE(MID(O74,2,3)),$A$2:$A$73,0)),INDEX($M$2:$M$73,MATCH(VALUE(MID(O74,2,3)),$A$2:$A$73,0)),IF(INDEX($K$2:$K$73,MATCH(VALUE(MID(O74,2,3)),$A$2:$A$73,0))=INDEX($H$2:$H$73,MATCH(VALUE(MID(O74,2,3)),$A$2:$A$73,0)),INDEX($N$2:$N$73,MATCH(VALUE(MID(O74,2,3)),$A$2:$A$73,0)),O74)),O74),IF(LEFT(O74,1)="L",IFERROR(IF(INDEX($K$2:$K$73,MATCH(VALUE(MID(O74,2,3)),$A$2:$A$73,0))=INDEX($G$2:$G$73,MATCH(VALUE(MID(O74,2,3)),$A$2:$A$73,0)),INDEX($N$2:$N$73,MATCH(VALUE(MID(O74,2,3)),$A$2:$A$73,0)),IF(INDEX($K$2:$K$73,MATCH(VALUE(MID(O74,2,3)),$A$2:$A$73,0))=INDEX($H$2:$H$73,MATCH(VALUE(MID(O74,2,3)),$A$2:$A$73,0)),INDEX($M$2:$M$73,MATCH(VALUE(MID(O74,2,3)),$A$2:$A$73,0)),O74)),O74),IFERROR(IF(VLOOKUP(RIGHT(O74,1)&LEFT(O74,1),Clasificacion!$O$2:$Q$49,3,FALSE())="",O74,VLOOKUP(RIGHT(O74,1)&LEFT(O74,1),Clasificacion!$O$2:$Q$49,3,FALSE())),O74))))) -> KOR | N74: =IF(P74="","",IF(LEFT(P74,1)="3",IFERROR(IF(VLOOKUP($A74&"V",Asignacion_3ros!$A$2:$G$9,7,FALSE())="",P74,VLOOKUP($A74&"V",Asignacion_3ros!$A$2:$G$9,7,FALSE())),P74),IF(LEFT(P74,1)="W",IFERROR(IF(INDEX($K$2:$K$73,MATCH(VALUE(MID(P74,2,3)),$A$2:$A$73,0))=INDEX($G$2:$G$73,MATCH(VALUE(MID(P74,2,3)),$A$2:$A$73,0)),INDEX($M$2:$M$73,MATCH(VALUE(MID(P74,2,3)),$A$2:$A$73,0)),IF(INDEX($K$2:$K$73,MATCH(VALUE(MID(P74,2,3)),$A$2:$A$73,0))=INDEX($H$2:$H$73,MATCH(VALUE(MID(P74,2,3)),$A$2:$A$73,0)),INDEX($N$2:$N$73,MATCH(VALUE(MID(P74,2,3)),$A$2:$A$73,0)),P74)),P74),IF(LEFT(P74,1)="L",IFERROR(IF(INDEX($K$2:$K$73,MATCH(VALUE(MID(P74,2,3)),$A$2:$A$73,0))=INDEX($G$2:$G$73,MATCH(VALUE(MID(P74,2,3)),$A$2:$A$73,0)),INDEX($N$2:$N$73,MATCH(VALUE(MID(P74,2,3)),$A$2:$A$73,0)),IF(INDEX($K$2:$K$73,MATCH(VALUE(MID(P74,2,3)),$A$2:$A$73,0))=INDEX($H$2:$H$73,MATCH(VALUE(MID(P74,2,3)),$A$2:$A$73,0)),INDEX($M$2:$M$73,MATCH(VALUE(MID(P74,2,3)),$A$2:$A$73,0)),P74)),P74),IFERROR(IF(VLOOKUP(RIGHT(P74,1)&LEFT(P74,1),Clasificacion!$O$2:$Q$49,3,FALSE())="",P74,VLOOKUP(RIGHT(P74,1)&LEFT(P74,1),Clasificacion!$O$2:$Q$49,3,FALSE())),P74))))) -> 2B | O74: 2A | P74: 2B | Q74: FIFA/CBS
A75: 74 | B75: 46201 | C75: 0.64583333 | D75: =HOUR(tblPartidos[[#This Row],[Hora ET]])-1 -> 14 | E75: Ronda de 32 | G75: =IF(O75="","",IF(LEFT(O75,1)="3",IFERROR(IF(VLOOKUP($A75&"L",Asignacion_3ros!$A$2:$G$9,6,FALSE())="",O75,VLOOKUP($A75&"L",Asignacion_3ros!$A$2:$G$9,6,FALSE())),O75),IF(LEFT(O75,1)="W",IFERROR(IF(INDEX($K$2:$K$74,MATCH(VALUE(MID(O75,2,3)),$A$2:$A$74,0))="",O75,INDEX($K$2:$K$74,MATCH(VALUE(MID(O75,2,3)),$A$2:$A$74,0))),O75),IF(LEFT(O75,1)="L",IFERROR(IF(INDEX($K$2:$K$74,MATCH(VALUE(MID(O75,2,3)),$A$2:$A$74,0))=INDEX($G$2:$G$74,MATCH(VALUE(MID(O75,2,3)),$A$2:$A$74,0)),INDEX($H$2:$H$74,MATCH(VALUE(MID(O75,2,3)),$A$2:$A$74,0)),IF(INDEX($K$2:$K$74,MATCH(VALUE(MID(O75,2,3)),$A$2:$A$74,0))=INDEX($H$2:$H$74,MATCH(VALUE(MID(O75,2,3)),$A$2:$A$74,0)),INDEX($G$2:$G$74,MATCH(VALUE(MID(O75,2,3)),$A$2:$A$74,0)),O75)),O75),IFERROR(IF(VLOOKUP(RIGHT(O75,1)&LEFT(O75,1),Clasificacion!$O$2:$Q$49,2,FALSE())="",O75,VLOOKUP(RIGHT(O75,1)&LEFT(O75,1),Clasificacion!$O$2:$Q$49,2,FALSE())),O75))))) -> 1E | H75: =IF(P75="","",IF(LEFT(P75,1)="3",IFERROR(IF(VLOOKUP($A75&"V",Asignacion_3ros!$A$2:$G$9,6,FALSE())="",P75,VLOOKUP($A75&"V",Asignacion_3ros!$A$2:$G$9,6,FALSE())),P75),IF(LEFT(P75,1)="W",IFERROR(IF(INDEX($K$2:$K$74,MATCH(VALUE(MID(P75,2,3)),$A$2:$A$74,0))="",P75,INDEX($K$2:$K$74,MATCH(VALUE(MID(P75,2,3)),$A$2:$A$74,0))),P75),IF(LEFT(P75,1)="L",IFERROR(IF(INDEX($K$2:$K$74,MATCH(VALUE(MID(P75,2,3)),$A$2:$A$74,0))=INDEX($G$2:$G$74,MATCH(VALUE(MID(P75,2,3)),$A$2:$A$74,0)),INDEX($H$2:$H$74,MATCH(VALUE(MID(P75,2,3)),$A$2:$A$74,0)),IF(INDEX($K$2:$K$74,MATCH(VALUE(MID(P75,2,3)),$A$2:$A$74,0))=INDEX($H$2:$H$74,MATCH(VALUE(MID(P75,2,3)),$A$2:$A$74,0)),INDEX($G$2:$G$74,MATCH(VALUE(MID(P75,2,3)),$A$2:$A$74,0)),P75)),P75),IFERROR(IF(VLOOKUP(RIGHT(P75,1)&LEFT(P75,1),Clasificacion!$O$2:$Q$49,2,FALSE())="",P75,VLOOKUP(RIGHT(P75,1)&LEFT(P75,1),Clasificacion!$O$2:$Q$49,2,FALSE())),P75))))) -> Corea República | K75: =IF(OR(I75="",J75=""),"",IF(I75>J75,G75,IF(J75>I75,H75,"Empate"))) | L75: Boston | M75: =IF(O75="","",IF(LEFT(O75,1)="3",IFERROR(IF(VLOOKUP($A75&"L",Asignacion_3ros!$A$2:$G$9,7,FALSE())="",O75,VLOOKUP($A75&"L",Asignacion_3ros!$A$2:$G$9,7,FALSE())),O75),IF(LEFT(O75,1)="W",IFERROR(IF(INDEX($K$2:$K$74,MATCH(VALUE(MID(O75,2,3)),$A$2:$A$74,0))=INDEX($G$2:$G$74,MATCH(VALUE(MID(O75,2,3)),$A$2:$A$74,0)),INDEX($M$2:$M$74,MATCH(VALUE(MID(O75,2,3)),$A$2:$A$74,0)),IF(INDEX($K$2:$K$74,MATCH(VALUE(MID(O75,2,3)),$A$2:$A$74,0))=INDEX($H$2:$H$74,MATCH(VALUE(MID(O75,2,3)),$A$2:$A$74,0)),INDEX($N$2:$N$74,MATCH(VALUE(MID(O75,2,3)),$A$2:$A$74,0)),O75)),O75),IF(LEFT(O75,1)="L",IFERROR(IF(INDEX($K$2:$K$74,MATCH(VALUE(MID(O75,2,3)),$A$2:$A$74,0))=INDEX($G$2:$G$74,MATCH(VALUE(MID(O75,2,3)),$A$2:$A$74,0)),INDEX($N$2:$N$74,MATCH(VALUE(MID(O75,2,3)),$A$2:$A$74,0)),IF(INDEX($K$2:$K$74,MATCH(VALUE(MID(O75,2,3)),$A$2:$A$74,0))=INDEX($H$2:$H$74,MATCH(VALUE(MID(O75,2,3)),$A$2:$A$74,0)),INDEX($M$2:$M$74,MATCH(VALUE(MID(O75,2,3)),$A$2:$A$74,0)),O75)),O75),IFERROR(IF(VLOOKUP(RIGHT(O75,1)&LEFT(O75,1),Clasificacion!$O$2:$Q$49,3,FALSE())="",O75,VLOOKUP(RIGHT(O75,1)&LEFT(O75,1),Clasificacion!$O$2:$Q$49,3,FALSE())),O75))))) -> 1E | N75: =IF(P75="","",IF(LEFT(P75,1)="3",IFERROR(IF(VLOOKUP($A75&"V",Asignacion_3ros!$A$2:$G$9,7,FALSE())="",P75,VLOOKUP($A75&"V",Asignacion_3ros!$A$2:$G$9,7,FALSE())),P75),IF(LEFT(P75,1)="W",IFERROR(IF(INDEX($K$2:$K$74,MATCH(VALUE(MID(P75,2,3)),$A$2:$A$74,0))=INDEX($G$2:$G$74,MATCH(VALUE(MID(P75,2,3)),$A$2:$A$74,0)),INDEX($M$2:$M$74,MATCH(VALUE(MID(P75,2,3)),$A$2:$A$74,0)),IF(INDEX($K$2:$K$74,MATCH(VALUE(MID(P75,2,3)),$A$2:$A$74,0))=INDEX($H$2:$H$74,MATCH(VALUE(MID(P75,2,3)),$A$2:$A$74,0)),INDEX($N$2:$N$74,MATCH(VALUE(MID(P75,2,3)),$A$2:$A$74,0)),P75)),P75),IF(LEFT(P75,1)="L",IFERROR(IF(INDEX($K$2:$K$74,MATCH(VALUE(MID(P75,2,3)),$A$2:$A$74,0))=INDEX($G$2:$G$74,MATCH(VALUE(MID(P75,2,3)),$A$2:$A$74,0)),INDEX($N$2:$N$74,MATCH(VALUE(MID(P75,2,3)),$A$2:$A$74,0)),IF(INDEX($K$2:$K$74,MATCH(VALUE(MID(P75,2,3)),$A$2:$A$74,0))=INDEX($H$2:$H$74,MATCH(VALUE(MID(P75,2,3)),$A$2:$A$74,0)),INDEX($M$2:$M$74,MATCH(VALUE(MID(P75,2,3)),$A$2:$A$74,0)),P75)),P75),IFERROR(IF(VLOOKUP(RIGHT(P75,1)&LEFT(P75,1),Clasificacion!$O$2:$Q$49,3,FALSE())="",P75,VLOOKUP(RIGHT(P75,1)&LEFT(P75,1),Clasificacion!$O$2:$Q$49,3,FALSE())),P75))))) -> KOR | O75: 1E | P75: 3A/B/C/D/F | Q75: FIFA/CBS
A76: 75 | B76: 46202 | C76: 0.83333333 | D76: =HOUR(tblPartidos[[#This Row],[Hora ET]])-1 -> 19 | E76: Ronda de 32 | G76: =IF(O76="","",IF(LEFT(O76,1)="3",IFERROR(IF(VLOOKUP($A76&"L",Asignacion_3ros!$A$2:$G$9,6,FALSE())="",O76,VLOOKUP($A76&"L",Asignacion_3ros!$A$2:$G$9,6,FALSE())),O76),IF(LEFT(O76,1)="W",IFERROR(IF(INDEX($K$2:$K$75,MATCH(VALUE(MID(O76,2,3)),$A$2:$A$75,0))="",O76,INDEX($K$2:$K$75,MATCH(VALUE(MID(O76,2,3)),$A$2:$A$75,0))),O76),IF(LEFT(O76,1)="L",IFERROR(IF(INDEX($K$2:$K$75,MATCH(VALUE(MID(O76,2,3)),$A$2:$A$75,0))=INDEX($G$2:$G$75,MATCH(VALUE(MID(O76,2,3)),$A$2:$A$75,0)),INDEX($H$2:$H$75,MATCH(VALUE(MID(O76,2,3)),$A$2:$A$75,0)),IF(INDEX($K$2:$K$75,MATCH(VALUE(MID(O76,2,3)),$A$2:$A$75,0))=INDEX($H$2:$H$75,MATCH(VALUE(MID(O76,2,3)),$A$2:$A$75,0)),INDEX($G$2:$G$75,MATCH(VALUE(MID(O76,2,3)),$A$2:$A$75,0)),O76)),O76),IFERROR(IF(VLOOKUP(RIGHT(O76,1)&LEFT(O76,1),Clasificacion!$O$2:$Q$49,2,FALSE())="",O76,VLOOKUP(RIGHT(O76,1)&LEFT(O76,1),Clasificacion!$O$2:$Q$49,2,FALSE())),O76))))) -> 1F | H76: =IF(P76="","",IF(LEFT(P76,1)="3",IFERROR(IF(VLOOKUP($A76&"V",Asignacion_3ros!$A$2:$G$9,6,FALSE())="",P76,VLOOKUP($A76&"V",Asignacion_3ros!$A$2:$G$9,6,FALSE())),P76),IF(LEFT(P76,1)="W",IFERROR(IF(INDEX($K$2:$K$75,MATCH(VALUE(MID(P76,2,3)),$A$2:$A$75,0))="",P76,INDEX($K$2:$K$75,MATCH(VALUE(MID(P76,2,3)),$A$2:$A$75,0))),P76),IF(LEFT(P76,1)="L",IFERROR(IF(INDEX($K$2:$K$75,MATCH(VALUE(MID(P76,2,3)),$A$2:$A$75,0))=INDEX($G$2:$G$75,MATCH(VALUE(MID(P76,2,3)),$A$2:$A$75,0)),INDEX($H$2:$H$75,MATCH(VALUE(MID(P76,2,3)),$A$2:$A$75,0)),IF(INDEX($K$2:$K$75,MATCH(VALUE(MID(P76,2,3)),$A$2:$A$75,0))=INDEX($H$2:$H$75,MATCH(VALUE(MID(P76,2,3)),$A$2:$A$75,0)),INDEX($G$2:$G$75,MATCH(VALUE(MID(P76,2,3)),$A$2:$A$75,0)),P76)),P76),IFERROR(IF(VLOOKUP(RIGHT(P76,1)&LEFT(P76,1),Clasificacion!$O$2:$Q$49,2,FALSE())="",P76,VLOOKUP(RIGHT(P76,1)&LEFT(P76,1),Clasificacion!$O$2:$Q$49,2,FALSE())),P76))))) -> 2C | K76: =IF(OR(I76="",J76=""),"",IF(I76>J76,G76,IF(J76>I76,H76,"Empate"))) | L76: Monterrey | M76: =IF(O76="","",IF(LEFT(O76,1)="3",IFERROR(IF(VLOOKUP($A76&"L",Asignacion_3ros!$A$2:$G$9,7,FALSE())="",O76,VLOOKUP($A76&"L",Asignacion_3ros!$A$2:$G$9,7,FALSE())),O76),IF(LEFT(O76,1)="W",IFERROR(IF(INDEX($K$2:$K$75,MATCH(VALUE(MID(O76,2,3)),$A$2:$A$75,0))=INDEX($G$2:$G$75,MATCH(VALUE(MID(O76,2,3)),$A$2:$A$75,0)),INDEX($M$2:$M$75,MATCH(VALUE(MID(O76,2,3)),$A$2:$A$75,0)),IF(INDEX($K$2:$K$75,MATCH(VALUE(MID(O76,2,3)),$A$2:$A$75,0))=INDEX($H$2:$H$75,MATCH(VALUE(MID(O76,2,3)),$A$2:$A$75,0)),INDEX($N$2:$N$75,MATCH(VALUE(MID(O76,2,3)),$A$2:$A$75,0)),O76)),O76),IF(LEFT(O76,1)="L",IFERROR(IF(INDEX($K$2:$K$75,MATCH(VALUE(MID(O76,2,3)),$A$2:$A$75,0))=INDEX($G$2:$G$75,MATCH(VALUE(MID(O76,2,3)),$A$2:$A$75,0)),INDEX($N$2:$N$75,MATCH(VALUE(MID(O76,2,3)),$A$2:$A$75,0)),IF(INDEX($K$2:$K$75,MATCH(VALUE(MID(O76,2,3)),$A$2:$A$75,0))=INDEX($H$2:$H$75,MATCH(VALUE(MID(O76,2,3)),$A$2:$A$75,0)),INDEX($M$2:$M$75,MATCH(VALUE(MID(O76,2,3)),$A$2:$A$75,0)),O76)),O76),IFERROR(IF(VLOOKUP(RIGHT(O76,1)&LEFT(O76,1),Clasificacion!$O$2:$Q$49,3,FALSE())="",O76,VLOOKUP(RIGHT(O76,1)&LEFT(O76,1),Clasificacion!$O$2:$Q$49,3,FALSE())),O76))))) -> 1F | N76: =IF(P76="","",IF(LEFT(P76,1)="3",IFERROR(IF(VLOOKUP($A76&"V",Asignacion_3ros!$A$2:$G$9,7,FALSE())="",P76,VLOOKUP($A76&"V",Asignacion_3ros!$A$2:$G$9,7,FALSE())),P76),IF(LEFT(P76,1)="W",IFERROR(IF(INDEX($K$2:$K$75,MATCH(VALUE(MID(P76,2,3)),$A$2:$A$75,0))=INDEX($G$2:$G$75,MATCH(VALUE(MID(P76,2,3)),$A$2:$A$75,0)),INDEX($M$2:$M$75,MATCH(VALUE(MID(P76,2,3)),$A$2:$A$75,0)),IF(INDEX($K$2:$K$75,MATCH(VALUE(MID(P76,2,3)),$A$2:$A$75,0))=INDEX($H$2:$H$75,MATCH(VALUE(MID(P76,2,3)),$A$2:$A$75,0)),INDEX($N$2:$N$75,MATCH(VALUE(MID(P76,2,3)),$A$2:$A$75,0)),P76)),P76),IF(LEFT(P76,1)="L",IFERROR(IF(INDEX($K$2:$K$75,MATCH(VALUE(MID(P76,2,3)),$A$2:$A$75,0))=INDEX($G$2:$G$75,MATCH(VALUE(MID(P76,2,3)),$A$2:$A$75,0)),INDEX($N$2:$N$75,MATCH(VALUE(MID(P76,2,3)),$A$2:$A$75,0)),IF(INDEX($K$2:$K$75,MATCH(VALUE(MID(P76,2,3)),$A$2:$A$75,0))=INDEX($H$2:$H$75,MATCH(VALUE(MID(P76,2,3)),$A$2:$A$75,0)),INDEX($M$2:$M$75,MATCH(VALUE(MID(P76,2,3)),$A$2:$A$75,0)),P76)),P76),IFERROR(IF(VLOOKUP(RIGHT(P76,1)&LEFT(P76,1),Clasificacion!$O$2:$Q$49,3,FALSE())="",P76,VLOOKUP(RIGHT(P76,1)&LEFT(P76,1),Clasificacion!$O$2:$Q$49,3,FALSE())),P76))))) -> 2C | O76: 1F | P76: 2C | Q76: FIFA/CBS
